
nohup: ignoring input
Watching for file changes with StatReloader
[12/Feb/2023 07:09:53] "GET /admin/add/ HTTP/1.1" 200 4408
/www/django_www/app01/utils/form.py changed, reloading.
Performing system checks...

System check identified no issues (0 silenced).
February 12, 2023 - 07:09:53
Django version 3.2, using settings 'django_www.settings'
Starting development server at http://0.0.0.0:80/
Quit the server with CONTROL-C.
Watching for file changes with StatReloader
/www/django_www/app01/utils/form.py changed, reloading.
Performing system checks...

System check identified no issues (0 silenced).
February 12, 2023 - 07:12:58
Django version 3.2, using settings 'django_www.settings'
Starting development server at http://0.0.0.0:80/
Quit the server with CONTROL-C.
Watching for file changes with StatReloader
[12/Feb/2023 07:13:45] "GET /admin/add/ HTTP/1.1" 200 4412
/www/django_www/app01/utils/form.py changed, reloading.
Performing system checks...

System check identified no issues (0 silenced).
February 12, 2023 - 07:13:45
Django version 3.2, using settings 'django_www.settings'
Starting development server at http://0.0.0.0:80/
Quit the server with CONTROL-C.
Watching for file changes with StatReloader
/www/django_www/app01/utils/form.py changed, reloading.
Performing system checks...

System check identified no issues (0 silenced).
February 12, 2023 - 07:13:51
Django version 3.2, using settings 'django_www.settings'
Starting development server at http://0.0.0.0:80/
Quit the server with CONTROL-C.
Watching for file changes with StatReloader
[12/Feb/2023 07:14:12] "GET /admin/add/ HTTP/1.1" 200 4403
/www/django_www/app01/utils/form.py changed, reloading.
Performing system checks...

System check identified no issues (0 silenced).
February 12, 2023 - 07:14:12
Django version 3.2, using settings 'django_www.settings'
Starting development server at http://0.0.0.0:80/
Quit the server with CONTROL-C.
Watching for file changes with StatReloader
[12/Feb/2023 07:14:26] "GET /admin/add/ HTTP/1.1" 200 4401
/www/django_www/app01/utils/form.py changed, reloading.
Performing system checks...

System check identified no issues (0 silenced).
February 12, 2023 - 07:14:25
Django version 3.2, using settings 'django_www.settings'
Starting development server at http://0.0.0.0:80/
Quit the server with CONTROL-C.
Watching for file changes with StatReloader
/www/django_www/app01/utils/form.py changed, reloading.
Performing system checks...

System check identified no issues (0 silenced).
February 12, 2023 - 07:15:45
Django version 3.2, using settings 'django_www.settings'
Starting development server at http://0.0.0.0:80/
Quit the server with CONTROL-C.
Watching for file changes with StatReloader
[12/Feb/2023 07:15:54] "GET /admin/add/ HTTP/1.1" 200 4412
/www/django_www/app01/utils/form.py changed, reloading.
Performing system checks...

System check identified no issues (0 silenced).
February 12, 2023 - 07:15:54
Django version 3.2, using settings 'django_www.settings'
Starting development server at http://0.0.0.0:80/
Quit the server with CONTROL-C.
Watching for file changes with StatReloader
/www/django_www/app01/utils/form.py changed, reloading.
Performing system checks...

System check identified no issues (0 silenced).
February 12, 2023 - 07:15:58
Django version 3.2, using settings 'django_www.settings'
Starting development server at http://0.0.0.0:80/
Quit the server with CONTROL-C.
Watching for file changes with StatReloader
[12/Feb/2023 07:16:02] "GET /admin/add/ HTTP/1.1" 200 4416
/www/django_www/app01/utils/form.py changed, reloading.
Performing system checks...

System check identified no issues (0 silenced).
February 12, 2023 - 07:16:02
Django version 3.2, using settings 'django_www.settings'
Starting development server at http://0.0.0.0:80/
Quit the server with CONTROL-C.
Watching for file changes with StatReloader
Internal Server Error: /admin/add/
Traceback (most recent call last):
  File "/usr/local/lib/python3.8/dist-packages/django/core/handlers/exception.py", line 47, in inner
    response = get_response(request)
  File "/usr/local/lib/python3.8/dist-packages/django/core/handlers/base.py", line 181, in _get_response
    response = wrapped_callback(request, *callback_args, **callback_kwargs)
  File "/www/django_www/app01/views/admin.py", line 33, in admin_add
    if form.is_valid():
  File "/usr/local/lib/python3.8/dist-packages/django/forms/forms.py", line 175, in is_valid
    return self.is_bound and not self.errors
  File "/usr/local/lib/python3.8/dist-packages/django/forms/forms.py", line 170, in errors
    self.full_clean()
  File "/usr/local/lib/python3.8/dist-packages/django/forms/forms.py", line 372, in full_clean
    self._clean_fields()
  File "/usr/local/lib/python3.8/dist-packages/django/forms/forms.py", line 393, in _clean_fields
    value = getattr(self, 'clean_%s' % name)()
  File "/www/django_www/app01/utils/form.py", line 58, in clean_verify_password
    password = self.cleaed_data.get["password"]
AttributeError: 'Admin_add_ModeForm' object has no attribute 'cleaed_data'
[12/Feb/2023 07:45:03] "POST /admin/add/ HTTP/1.1" 500 76493
Internal Server Error: /admin/add/
Traceback (most recent call last):
  File "/usr/local/lib/python3.8/dist-packages/django/core/handlers/exception.py", line 47, in inner
    response = get_response(request)
  File "/usr/local/lib/python3.8/dist-packages/django/core/handlers/base.py", line 181, in _get_response
    response = wrapped_callback(request, *callback_args, **callback_kwargs)
  File "/www/django_www/app01/views/admin.py", line 33, in admin_add
    if form.is_valid():
  File "/usr/local/lib/python3.8/dist-packages/django/forms/forms.py", line 175, in is_valid
    return self.is_bound and not self.errors
  File "/usr/local/lib/python3.8/dist-packages/django/forms/forms.py", line 170, in errors
    self.full_clean()
  File "/usr/local/lib/python3.8/dist-packages/django/forms/forms.py", line 372, in full_clean
    self._clean_fields()
  File "/usr/local/lib/python3.8/dist-packages/django/forms/forms.py", line 393, in _clean_fields
    value = getattr(self, 'clean_%s' % name)()
  File "/www/django_www/app01/utils/form.py", line 58, in clean_verify_password
    password = self.cleaed_data.get["password"]
AttributeError: 'Admin_add_ModeForm' object has no attribute 'cleaed_data'
[12/Feb/2023 07:45:11] "POST /admin/add/ HTTP/1.1" 500 76484
/www/django_www/app01/utils/form.py changed, reloading.
Performing system checks...

System check identified no issues (0 silenced).
February 12, 2023 - 07:44:59
Django version 3.2, using settings 'django_www.settings'
Starting development server at http://0.0.0.0:80/
Quit the server with CONTROL-C.
Watching for file changes with StatReloader
Internal Server Error: /admin/add/
Traceback (most recent call last):
  File "/usr/local/lib/python3.8/dist-packages/django/core/handlers/exception.py", line 47, in inner
    response = get_response(request)
  File "/usr/local/lib/python3.8/dist-packages/django/core/handlers/base.py", line 181, in _get_response
    response = wrapped_callback(request, *callback_args, **callback_kwargs)
  File "/www/django_www/app01/views/admin.py", line 33, in admin_add
    if form.is_valid():
  File "/usr/local/lib/python3.8/dist-packages/django/forms/forms.py", line 175, in is_valid
    return self.is_bound and not self.errors
  File "/usr/local/lib/python3.8/dist-packages/django/forms/forms.py", line 170, in errors
    self.full_clean()
  File "/usr/local/lib/python3.8/dist-packages/django/forms/forms.py", line 372, in full_clean
    self._clean_fields()
  File "/usr/local/lib/python3.8/dist-packages/django/forms/forms.py", line 393, in _clean_fields
    value = getattr(self, 'clean_%s' % name)()
  File "/www/django_www/app01/utils/form.py", line 58, in clean_verify_password
    password = self.clean_data.get["password"]
AttributeError: 'Admin_add_ModeForm' object has no attribute 'clean_data'
[12/Feb/2023 07:46:07] "POST /admin/add/ HTTP/1.1" 500 76478
/www/django_www/app01/utils/form.py changed, reloading.
Performing system checks...

System check identified no issues (0 silenced).
February 12, 2023 - 07:46:02
Django version 3.2, using settings 'django_www.settings'
Starting development server at http://0.0.0.0:80/
Quit the server with CONTROL-C.
Watching for file changes with StatReloader
/www/django_www/app01/utils/form.py changed, reloading.
Performing system checks...

System check identified no issues (0 silenced).
February 12, 2023 - 07:46:35
Django version 3.2, using settings 'django_www.settings'
Starting development server at http://0.0.0.0:80/
Quit the server with CONTROL-C.
Watching for file changes with StatReloader
[12/Feb/2023 07:46:52] "POST /admin/add/ HTTP/1.1" 302 0
[12/Feb/2023 07:46:52] "GET /admin/ HTTP/1.1" 200 9576
[12/Feb/2023 07:46:59] "GET /admin/add/ HTTP/1.1" 200 4416
[12/Feb/2023 07:47:03] "POST /admin/add/ HTTP/1.1" 200 15
[12/Feb/2023 07:47:06] "GET /admin/add/ HTTP/1.1" 200 4416
/www/django_www/app01/utils/form.py changed, reloading.
Performing system checks...

System check identified no issues (0 silenced).
February 12, 2023 - 07:46:49
Django version 3.2, using settings 'django_www.settings'
Starting development server at http://0.0.0.0:80/
Quit the server with CONTROL-C.
Watching for file changes with StatReloader
[12/Feb/2023 07:47:43] "POST /admin/add/ HTTP/1.1" 200 15
[12/Feb/2023 07:47:43] "GET /admin/add/ HTTP/1.1" 200 4416
/www/django_www/app01/views/admin.py changed, reloading.
Performing system checks...

System check identified no issues (0 silenced).
February 12, 2023 - 07:47:40
Django version 3.2, using settings 'django_www.settings'
Starting development server at http://0.0.0.0:80/
Quit the server with CONTROL-C.
Watching for file changes with StatReloader
[12/Feb/2023 07:48:14] "POST /admin/add/ HTTP/1.1" 200 4428
[12/Feb/2023 07:48:18] "POST /admin/add/ HTTP/1.1" 200 4428
[12/Feb/2023 07:56:53] "POST /admin/add/ HTTP/1.1" 200 4428
[12/Feb/2023 07:56:56] "POST /admin/add/ HTTP/1.1" 200 4428
[12/Feb/2023 08:01:11] "POST /admin/add/ HTTP/1.1" 200 4611
[12/Feb/2023 08:01:56] "GET /lifelog/log/ HTTP/1.1" 200 5514
Internal Server Error: /lifelog/log/
Traceback (most recent call last):
  File "/usr/local/lib/python3.8/dist-packages/django/db/backends/mysql/base.py", line 73, in execute
    return self.cursor.execute(query, args)
  File "/usr/local/lib/python3.8/dist-packages/MySQLdb/cursors.py", line 206, in execute
    res = self._query(query)
  File "/usr/local/lib/python3.8/dist-packages/MySQLdb/cursors.py", line 319, in _query
    db.query(q)
  File "/usr/local/lib/python3.8/dist-packages/MySQLdb/connections.py", line 254, in query
    _mysql.connection.query(self, query)
MySQLdb.OperationalError: (1048, "Column 'tag' cannot be null")

During handling of the above exception, another exception occurred:

Traceback (most recent call last):
  File "/usr/local/lib/python3.8/dist-packages/django/core/handlers/exception.py", line 47, in inner
    response = get_response(request)
  File "/usr/local/lib/python3.8/dist-packages/django/core/handlers/base.py", line 181, in _get_response
    response = wrapped_callback(request, *callback_args, **callback_kwargs)
  File "/www/django_www/app01/views/lifelog.py", line 40, in lifelog_log
    form.save()        # 如果数据是有效的，存入之前获取的表中
  File "/usr/local/lib/python3.8/dist-packages/django/forms/models.py", line 468, in save
    self.instance.save()
  File "/usr/local/lib/python3.8/dist-packages/django/db/models/base.py", line 726, in save
    self.save_base(using=using, force_insert=force_insert,
  File "/usr/local/lib/python3.8/dist-packages/django/db/models/base.py", line 763, in save_base
    updated = self._save_table(
  File "/usr/local/lib/python3.8/dist-packages/django/db/models/base.py", line 868, in _save_table
    results = self._do_insert(cls._base_manager, using, fields, returning_fields, raw)
  File "/usr/local/lib/python3.8/dist-packages/django/db/models/base.py", line 906, in _do_insert
    return manager._insert(
  File "/usr/local/lib/python3.8/dist-packages/django/db/models/manager.py", line 85, in manager_method
    return getattr(self.get_queryset(), name)(*args, **kwargs)
  File "/usr/local/lib/python3.8/dist-packages/django/db/models/query.py", line 1270, in _insert
    return query.get_compiler(using=using).execute_sql(returning_fields)
  File "/usr/local/lib/python3.8/dist-packages/django/db/models/sql/compiler.py", line 1410, in execute_sql
    cursor.execute(sql, params)
  File "/usr/local/lib/python3.8/dist-packages/django/db/backends/utils.py", line 98, in execute
    return super().execute(sql, params)
  File "/usr/local/lib/python3.8/dist-packages/django/db/backends/utils.py", line 66, in execute
    return self._execute_with_wrappers(sql, params, many=False, executor=self._execute)
  File "/usr/local/lib/python3.8/dist-packages/django/db/backends/utils.py", line 75, in _execute_with_wrappers
    return executor(sql, params, many, context)
  File "/usr/local/lib/python3.8/dist-packages/django/db/backends/utils.py", line 84, in _execute
    return self.cursor.execute(sql, params)
  File "/usr/local/lib/python3.8/dist-packages/django/db/backends/mysql/base.py", line 78, in execute
    raise IntegrityError(*tuple(e.args))
django.db.utils.IntegrityError: (1048, "Column 'tag' cannot be null")
[12/Feb/2023 08:02:08] "POST /lifelog/log/ HTTP/1.1" 500 143473
/www/django_www/app01/views/lifelog.py changed, reloading.
Performing system checks...

System check identified no issues (0 silenced).
February 12, 2023 - 07:48:08
Django version 3.2, using settings 'django_www.settings'
Starting development server at http://0.0.0.0:80/
Quit the server with CONTROL-C.
Watching for file changes with StatReloader
[12/Feb/2023 08:09:39] "GET /lifelog/log/ HTTP/1.1" 200 5514
Internal Server Error: /lifelog/log/
Traceback (most recent call last):
  File "/usr/local/lib/python3.8/dist-packages/django/db/backends/mysql/base.py", line 73, in execute
    return self.cursor.execute(query, args)
  File "/usr/local/lib/python3.8/dist-packages/MySQLdb/cursors.py", line 206, in execute
    res = self._query(query)
  File "/usr/local/lib/python3.8/dist-packages/MySQLdb/cursors.py", line 319, in _query
    db.query(q)
  File "/usr/local/lib/python3.8/dist-packages/MySQLdb/connections.py", line 254, in query
    _mysql.connection.query(self, query)
MySQLdb.OperationalError: (1048, "Column 'tag' cannot be null")

During handling of the above exception, another exception occurred:

Traceback (most recent call last):
  File "/usr/local/lib/python3.8/dist-packages/django/core/handlers/exception.py", line 47, in inner
    response = get_response(request)
  File "/usr/local/lib/python3.8/dist-packages/django/core/handlers/base.py", line 181, in _get_response
    response = wrapped_callback(request, *callback_args, **callback_kwargs)
  File "/www/django_www/app01/views/lifelog.py", line 40, in lifelog_log
    form.save()        # 如果数据是有效的，存入之前获取的表中
  File "/usr/local/lib/python3.8/dist-packages/django/forms/models.py", line 468, in save
    self.instance.save()
  File "/usr/local/lib/python3.8/dist-packages/django/db/models/base.py", line 726, in save
    self.save_base(using=using, force_insert=force_insert,
  File "/usr/local/lib/python3.8/dist-packages/django/db/models/base.py", line 763, in save_base
    updated = self._save_table(
  File "/usr/local/lib/python3.8/dist-packages/django/db/models/base.py", line 868, in _save_table
    results = self._do_insert(cls._base_manager, using, fields, returning_fields, raw)
  File "/usr/local/lib/python3.8/dist-packages/django/db/models/base.py", line 906, in _do_insert
    return manager._insert(
  File "/usr/local/lib/python3.8/dist-packages/django/db/models/manager.py", line 85, in manager_method
    return getattr(self.get_queryset(), name)(*args, **kwargs)
  File "/usr/local/lib/python3.8/dist-packages/django/db/models/query.py", line 1270, in _insert
    return query.get_compiler(using=using).execute_sql(returning_fields)
  File "/usr/local/lib/python3.8/dist-packages/django/db/models/sql/compiler.py", line 1410, in execute_sql
    cursor.execute(sql, params)
  File "/usr/local/lib/python3.8/dist-packages/django/db/backends/utils.py", line 98, in execute
    return super().execute(sql, params)
  File "/usr/local/lib/python3.8/dist-packages/django/db/backends/utils.py", line 66, in execute
    return self._execute_with_wrappers(sql, params, many=False, executor=self._execute)
  File "/usr/local/lib/python3.8/dist-packages/django/db/backends/utils.py", line 75, in _execute_with_wrappers
    return executor(sql, params, many, context)
  File "/usr/local/lib/python3.8/dist-packages/django/db/backends/utils.py", line 84, in _execute
    return self.cursor.execute(sql, params)
  File "/usr/local/lib/python3.8/dist-packages/django/db/backends/mysql/base.py", line 78, in execute
    raise IntegrityError(*tuple(e.args))
django.db.utils.IntegrityError: (1048, "Column 'tag' cannot be null")
[12/Feb/2023 08:09:41] "POST /lifelog/log/ HTTP/1.1" 500 143738
Internal Server Error: /lifelog/log/
Traceback (most recent call last):
  File "/usr/local/lib/python3.8/dist-packages/django/db/backends/mysql/base.py", line 73, in execute
    return self.cursor.execute(query, args)
  File "/usr/local/lib/python3.8/dist-packages/MySQLdb/cursors.py", line 206, in execute
    res = self._query(query)
  File "/usr/local/lib/python3.8/dist-packages/MySQLdb/cursors.py", line 319, in _query
    db.query(q)
  File "/usr/local/lib/python3.8/dist-packages/MySQLdb/connections.py", line 254, in query
    _mysql.connection.query(self, query)
MySQLdb.OperationalError: (1048, "Column 'tag' cannot be null")

During handling of the above exception, another exception occurred:

Traceback (most recent call last):
  File "/usr/local/lib/python3.8/dist-packages/django/core/handlers/exception.py", line 47, in inner
    response = get_response(request)
  File "/usr/local/lib/python3.8/dist-packages/django/core/handlers/base.py", line 181, in _get_response
    response = wrapped_callback(request, *callback_args, **callback_kwargs)
  File "/www/django_www/app01/views/lifelog.py", line 40, in lifelog_log
    form.save()        # 如果数据是有效的，存入之前获取的表中
  File "/usr/local/lib/python3.8/dist-packages/django/forms/models.py", line 468, in save
    self.instance.save()
  File "/usr/local/lib/python3.8/dist-packages/django/db/models/base.py", line 726, in save
    self.save_base(using=using, force_insert=force_insert,
  File "/usr/local/lib/python3.8/dist-packages/django/db/models/base.py", line 763, in save_base
    updated = self._save_table(
  File "/usr/local/lib/python3.8/dist-packages/django/db/models/base.py", line 868, in _save_table
    results = self._do_insert(cls._base_manager, using, fields, returning_fields, raw)
  File "/usr/local/lib/python3.8/dist-packages/django/db/models/base.py", line 906, in _do_insert
    return manager._insert(
  File "/usr/local/lib/python3.8/dist-packages/django/db/models/manager.py", line 85, in manager_method
    return getattr(self.get_queryset(), name)(*args, **kwargs)
  File "/usr/local/lib/python3.8/dist-packages/django/db/models/query.py", line 1270, in _insert
    return query.get_compiler(using=using).execute_sql(returning_fields)
  File "/usr/local/lib/python3.8/dist-packages/django/db/models/sql/compiler.py", line 1410, in execute_sql
    cursor.execute(sql, params)
  File "/usr/local/lib/python3.8/dist-packages/django/db/backends/utils.py", line 98, in execute
    return super().execute(sql, params)
  File "/usr/local/lib/python3.8/dist-packages/django/db/backends/utils.py", line 66, in execute
    return self._execute_with_wrappers(sql, params, many=False, executor=self._execute)
  File "/usr/local/lib/python3.8/dist-packages/django/db/backends/utils.py", line 75, in _execute_with_wrappers
    return executor(sql, params, many, context)
  File "/usr/local/lib/python3.8/dist-packages/django/db/backends/utils.py", line 84, in _execute
    return self.cursor.execute(sql, params)
  File "/usr/local/lib/python3.8/dist-packages/django/db/backends/mysql/base.py", line 78, in execute
    raise IntegrityError(*tuple(e.args))
django.db.utils.IntegrityError: (1048, "Column 'tag' cannot be null")
[12/Feb/2023 08:10:38] "POST /lifelog/log/ HTTP/1.1" 500 143738
[12/Feb/2023 08:11:27] "GET /static/bootstrap/css/bootstrap.min.css.map HTTP/1.1" 200 522639
[12/Feb/2023 08:11:27] "GET /static/bootstrap/js/bootstrap.min.js.map HTTP/1.1" 200 216913
/www/django_www/app01/models.py changed, reloading.
Performing system checks...

System check identified no issues (0 silenced).
February 12, 2023 - 08:09:39
Django version 3.2, using settings 'django_www.settings'
Starting development server at http://0.0.0.0:80/
Quit the server with CONTROL-C.
Watching for file changes with StatReloader
[12/Feb/2023 08:11:54] "GET /lifelog/log/ HTTP/1.1" 200 5514
[12/Feb/2023 08:11:58] "POST /lifelog/log/ HTTP/1.1" 302 0
[12/Feb/2023 08:11:58] "GET /lifelog/ HTTP/1.1" 200 13008
[12/Feb/2023 08:12:04] "GET /lifelog/del/7030242774414921728/ HTTP/1.1" 302 0
[12/Feb/2023 08:12:04] "GET /lifelog/ HTTP/1.1" 200 13332
/www/django_www/app01/models.py changed, reloading.
Performing system checks...

System check identified no issues (0 silenced).
February 12, 2023 - 08:11:53
Django version 3.2, using settings 'django_www.settings'
Starting development server at http://0.0.0.0:80/
Quit the server with CONTROL-C.
Watching for file changes with StatReloader
[12/Feb/2023 08:12:16] "GET /lifelog/log/ HTTP/1.1" 200 5514
[12/Feb/2023 08:12:18] "POST /lifelog/log/ HTTP/1.1" 302 0
[12/Feb/2023 08:12:18] "GET /lifelog/ HTTP/1.1" 200 13008
[12/Feb/2023 08:12:29] "GET /lifelog/del/7030242867192926208/ HTTP/1.1" 302 0
[12/Feb/2023 08:12:29] "GET /lifelog/ HTTP/1.1" 200 13332
[12/Feb/2023 08:12:30] "GET /lifelog/log/ HTTP/1.1" 200 5514
/www/django_www/app01/models.py changed, reloading.
Performing system checks...

System check identified no issues (0 silenced).
February 12, 2023 - 08:12:15
Django version 3.2, using settings 'django_www.settings'
Starting development server at http://0.0.0.0:80/
Quit the server with CONTROL-C.
Watching for file changes with StatReloader
[12/Feb/2023 08:13:34] "POST /lifelog/log/ HTTP/1.1" 200 5695
[12/Feb/2023 08:13:43] "POST /lifelog/log/ HTTP/1.1" 302 0
[12/Feb/2023 08:13:43] "GET /lifelog/ HTTP/1.1" 200 13012
[12/Feb/2023 08:13:47] "GET /lifelog/del/7030242927439908864/ HTTP/1.1" 302 0
[12/Feb/2023 08:13:47] "GET /lifelog/ HTTP/1.1" 200 13332
