bash: nohub: command not found
nohup: ignoring input
Watching for file changes with StatReloader
Performing system checks...

System check identified no issues (0 silenced).

You have 18 unapplied migration(s). Your project may not work properly until you apply the migrations for app(s): admin, auth, contenttypes, sessions.
Run 'python manage.py migrate' to apply them.
November 05, 2022 - 16:57:26
Django version 3.2, using settings 'django_www.settings'
Starting development server at http://0.0.0.0:80/
Quit the server with CONTROL-C.
nohup: ignoring input
nohup: failed to run command 'python3 manage.py runserver 0.0.0.0:80': No such file or directory
nohup: ignoring input
nohup: failed to run command 'python3 manage.py runserver 0.0.0.0:80': No such file or directory
nohup: ignoring input
nohup: failed to run command 'python3 manage.py runserver 0.0.0.0:80': No such file or directory
nohup: ignoring input
Watching for file changes with StatReloader
Performing system checks...

System check identified no issues (0 silenced).

You have 18 unapplied migration(s). Your project may not work properly until you apply the migrations for app(s): admin, auth, contenttypes, sessions.
Run 'python manage.py migrate' to apply them.
November 05, 2022 - 16:59:29
Django version 3.2, using settings 'django_www.settings'
Starting development server at http://0.0.0.0:80/
Quit the server with CONTROL-C.
bash: uphup: command not found
nohup: ignoring input
Watching for file changes with StatReloader
[05/Nov/2022 19:22:11] "GET / HTTP/1.1" 200 10633
Performing system checks...

System check identified no issues (0 silenced).

You have 18 unapplied migration(s). Your project may not work properly until you apply the migrations for app(s): admin, auth, contenttypes, sessions.
Run 'python manage.py migrate' to apply them.
November 05, 2022 - 19:22:11
Django version 3.2, using settings 'django_www.settings'
Starting development server at http://0.0.0.0:80/
Quit the server with CONTROL-C.
nohup: ignoring input
Watching for file changes with StatReloader
[05/Nov/2022 19:23:40] "GET / HTTP/1.1" 200 10633
[05/Nov/2022 19:23:41] "GET / HTTP/1.1" 200 10633
[05/Nov/2022 19:23:41] "GET / HTTP/1.1" 200 10633
[05/Nov/2022 19:23:42] "GET / HTTP/1.1" 200 10633
Performing system checks...

System check identified no issues (0 silenced).

You have 18 unapplied migration(s). Your project may not work properly until you apply the migrations for app(s): admin, auth, contenttypes, sessions.
Run 'python manage.py migrate' to apply them.
November 05, 2022 - 19:23:38
Django version 3.2, using settings 'django_www.settings'
Starting development server at http://0.0.0.0:80/
Quit the server with CONTROL-C.
nohup: ignoring input
python3: can't open file 'manage.py': [Errno 2] No such file or directory
nohup: ignoring input
Watching for file changes with StatReloader
[05/Nov/2022 19:28:47] "GET / HTTP/1.1" 200 10633
Performing system checks...

System check identified no issues (0 silenced).

You have 18 unapplied migration(s). Your project may not work properly until you apply the migrations for app(s): admin, auth, contenttypes, sessions.
Run 'python manage.py migrate' to apply them.
November 05, 2022 - 19:28:46
Django version 3.2, using settings 'django_www.settings'
Starting development server at http://0.0.0.0:80/
Quit the server with CONTROL-C.
nohup: ignoring input
Watching for file changes with StatReloader
[05/Nov/2022 19:49:09] "GET / HTTP/1.1" 200 10633
[05/Nov/2022 19:49:09] "GET /static/admin/css/fonts.css HTTP/1.1" 304 0
[05/Nov/2022 19:49:11] "GET / HTTP/1.1" 200 10633
Not Found: /favicon.ico
[05/Nov/2022 19:49:11] "GET /favicon.ico HTTP/1.1" 404 2003
Performing system checks...

System check identified no issues (0 silenced).

You have 18 unapplied migration(s). Your project may not work properly until you apply the migrations for app(s): admin, auth, contenttypes, sessions.
Run 'python manage.py migrate' to apply them.
November 05, 2022 - 19:49:04
Django version 3.2, using settings 'django_www.settings'
Starting development server at http://0.0.0.0:80/
Quit the server with CONTROL-C.
nohup: ignoring input
Watching for file changes with StatReloader
[05/Nov/2022 19:49:42] "GET / HTTP/1.1" 200 10633
[05/Nov/2022 19:49:42] "GET / HTTP/1.1" 200 10633
[05/Nov/2022 19:49:43] "GET / HTTP/1.1" 200 10633
[05/Nov/2022 19:49:43] "GET / HTTP/1.1" 200 10633
[05/Nov/2022 19:50:11] "GET / HTTP/1.1" 200 10633
[05/Nov/2022 19:50:12] "GET / HTTP/1.1" 200 10633
[05/Nov/2022 19:50:12] "GET / HTTP/1.1" 200 10633
[05/Nov/2022 19:50:13] "GET / HTTP/1.1" 200 10633
[05/Nov/2022 19:50:14] "GET / HTTP/1.1" 200 10633
[05/Nov/2022 19:50:14] "GET / HTTP/1.1" 200 10633
[05/Nov/2022 19:50:14] "GET / HTTP/1.1" 200 10633
[05/Nov/2022 19:50:15] "GET / HTTP/1.1" 200 10633
[05/Nov/2022 19:50:15] "GET / HTTP/1.1" 200 10633
[05/Nov/2022 19:50:15] "GET / HTTP/1.1" 200 10633
[05/Nov/2022 19:50:15] "GET / HTTP/1.1" 200 10633
[05/Nov/2022 19:50:15] "GET / HTTP/1.1" 200 10633
[05/Nov/2022 19:50:21] "GET / HTTP/1.1" 200 10633
[05/Nov/2022 19:53:02] "GET / HTTP/1.1" 200 10633
[05/Nov/2022 19:53:02] "GET / HTTP/1.1" 200 10633
[05/Nov/2022 19:53:05] "GET / HTTP/1.1" 200 10633
[05/Nov/2022 19:53:07] "GET / HTTP/1.1" 200 10633
[05/Nov/2022 19:53:11] "GET / HTTP/1.1" 200 10633
[06/Nov/2022 04:45:14] "GET / HTTP/1.1" 200 10633
[06/Nov/2022 04:45:14] "GET /static/admin/css/fonts.css HTTP/1.1" 304 0
[06/Nov/2022 06:32:38] "GET / HTTP/1.1" 200 10633
[06/Nov/2022 06:32:38] "GET /static/admin/css/fonts.css HTTP/1.1" 304 0
[06/Nov/2022 06:32:38] "GET /static/admin/fonts/Roboto-Regular-webfont.woff HTTP/1.1" 200 85876
[06/Nov/2022 06:32:38] "GET /static/admin/fonts/Roboto-Bold-webfont.woff HTTP/1.1" 200 86184
[06/Nov/2022 06:32:38] "GET /static/admin/fonts/Roboto-Light-webfont.woff HTTP/1.1" 200 85692
Not Found: /favicon.ico
[06/Nov/2022 06:32:38] "GET /favicon.ico HTTP/1.1" 404 2003
[06/Nov/2022 06:34:24] "GET / HTTP/1.1" 200 10633
/www/django_www/django_www/settings.py changed, reloading.
Performing system checks...

System check identified no issues (0 silenced).

You have 18 unapplied migration(s). Your project may not work properly until you apply the migrations for app(s): admin, auth, contenttypes, sessions.
Run 'python manage.py migrate' to apply them.
November 05, 2022 - 19:49:37
Django version 3.2, using settings 'django_www.settings'
Starting development server at http://0.0.0.0:80/
Quit the server with CONTROL-C.
Watching for file changes with StatReloader
[06/Nov/2022 06:56:55] "GET / HTTP/1.1" 200 10633
[06/Nov/2022 06:56:57] "GET / HTTP/1.1" 200 10633
[06/Nov/2022 06:57:04] "GET / HTTP/1.1" 200 10633
[06/Nov/2022 06:58:02] "GET /admin HTTP/1.1" 301 0
[06/Nov/2022 06:58:02] "GET /admin/ HTTP/1.1" 302 0
[06/Nov/2022 06:58:02] "GET /admin/login/?next=/admin/ HTTP/1.1" 200 2216
[06/Nov/2022 06:58:03] "GET /static/admin/css/nav_sidebar.css HTTP/1.1" 200 2271
[06/Nov/2022 06:58:03] "GET /static/admin/css/login.css HTTP/1.1" 200 939
[06/Nov/2022 06:58:03] "GET /static/admin/js/nav_sidebar.js HTTP/1.1" 200 1360
[06/Nov/2022 06:58:03] "GET /static/admin/css/responsive.css HTTP/1.1" 200 18545
[06/Nov/2022 06:58:03] "GET /static/admin/css/base.css HTTP/1.1" 200 19513
Internal Server Error: /admin/login/
Traceback (most recent call last):
  File "/usr/local/lib/python3.8/dist-packages/django/db/backends/utils.py", line 84, in _execute
    return self.cursor.execute(sql, params)
  File "/usr/local/lib/python3.8/dist-packages/django/db/backends/sqlite3/base.py", line 423, in execute
    return Database.Cursor.execute(self, query, params)
sqlite3.OperationalError: no such table: auth_user

The above exception was the direct cause of the following exception:

Traceback (most recent call last):
  File "/usr/local/lib/python3.8/dist-packages/django/core/handlers/exception.py", line 47, in inner
    response = get_response(request)
  File "/usr/local/lib/python3.8/dist-packages/django/core/handlers/base.py", line 181, in _get_response
    response = wrapped_callback(request, *callback_args, **callback_kwargs)
  File "/usr/local/lib/python3.8/dist-packages/django/views/decorators/cache.py", line 44, in _wrapped_view_func
    response = view_func(request, *args, **kwargs)
  File "/usr/local/lib/python3.8/dist-packages/django/contrib/admin/sites.py", line 414, in login
    return LoginView.as_view(**defaults)(request)
  File "/usr/local/lib/python3.8/dist-packages/django/views/generic/base.py", line 70, in view
    return self.dispatch(request, *args, **kwargs)
  File "/usr/local/lib/python3.8/dist-packages/django/utils/decorators.py", line 43, in _wrapper
    return bound_method(*args, **kwargs)
  File "/usr/local/lib/python3.8/dist-packages/django/views/decorators/debug.py", line 89, in sensitive_post_parameters_wrapper
    return view(request, *args, **kwargs)
  File "/usr/local/lib/python3.8/dist-packages/django/utils/decorators.py", line 43, in _wrapper
    return bound_method(*args, **kwargs)
  File "/usr/local/lib/python3.8/dist-packages/django/utils/decorators.py", line 130, in _wrapped_view
    response = view_func(request, *args, **kwargs)
  File "/usr/local/lib/python3.8/dist-packages/django/utils/decorators.py", line 43, in _wrapper
    return bound_method(*args, **kwargs)
  File "/usr/local/lib/python3.8/dist-packages/django/views/decorators/cache.py", line 44, in _wrapped_view_func
    response = view_func(request, *args, **kwargs)
  File "/usr/local/lib/python3.8/dist-packages/django/contrib/auth/views.py", line 63, in dispatch
    return super().dispatch(request, *args, **kwargs)
  File "/usr/local/lib/python3.8/dist-packages/django/views/generic/base.py", line 98, in dispatch
    return handler(request, *args, **kwargs)
  File "/usr/local/lib/python3.8/dist-packages/django/views/generic/edit.py", line 141, in post
    if form.is_valid():
  File "/usr/local/lib/python3.8/dist-packages/django/forms/forms.py", line 175, in is_valid
    return self.is_bound and not self.errors
  File "/usr/local/lib/python3.8/dist-packages/django/forms/forms.py", line 170, in errors
    self.full_clean()
  File "/usr/local/lib/python3.8/dist-packages/django/forms/forms.py", line 373, in full_clean
    self._clean_form()
  File "/usr/local/lib/python3.8/dist-packages/django/forms/forms.py", line 400, in _clean_form
    cleaned_data = self.clean()
  File "/usr/local/lib/python3.8/dist-packages/django/contrib/auth/forms.py", line 202, in clean
    self.user_cache = authenticate(self.request, username=username, password=password)
  File "/usr/local/lib/python3.8/dist-packages/django/views/decorators/debug.py", line 42, in sensitive_variables_wrapper
    return func(*func_args, **func_kwargs)
  File "/usr/local/lib/python3.8/dist-packages/django/contrib/auth/__init__.py", line 76, in authenticate
    user = backend.authenticate(request, **credentials)
  File "/usr/local/lib/python3.8/dist-packages/django/contrib/auth/backends.py", line 42, in authenticate
    user = UserModel._default_manager.get_by_natural_key(username)
  File "/usr/local/lib/python3.8/dist-packages/django/contrib/auth/base_user.py", line 45, in get_by_natural_key
    return self.get(**{self.model.USERNAME_FIELD: username})
  File "/usr/local/lib/python3.8/dist-packages/django/db/models/manager.py", line 85, in manager_method
    return getattr(self.get_queryset(), name)(*args, **kwargs)
  File "/usr/local/lib/python3.8/dist-packages/django/db/models/query.py", line 431, in get
    num = len(clone)
  File "/usr/local/lib/python3.8/dist-packages/django/db/models/query.py", line 262, in __len__
    self._fetch_all()
  File "/usr/local/lib/python3.8/dist-packages/django/db/models/query.py", line 1324, in _fetch_all
    self._result_cache = list(self._iterable_class(self))
  File "/usr/local/lib/python3.8/dist-packages/django/db/models/query.py", line 51, in __iter__
    results = compiler.execute_sql(chunked_fetch=self.chunked_fetch, chunk_size=self.chunk_size)
  File "/usr/local/lib/python3.8/dist-packages/django/db/models/sql/compiler.py", line 1169, in execute_sql
    cursor.execute(sql, params)
  File "/usr/local/lib/python3.8/dist-packages/django/db/backends/utils.py", line 98, in execute
    return super().execute(sql, params)
  File "/usr/local/lib/python3.8/dist-packages/django/db/backends/utils.py", line 66, in execute
    return self._execute_with_wrappers(sql, params, many=False, executor=self._execute)
  File "/usr/local/lib/python3.8/dist-packages/django/db/backends/utils.py", line 75, in _execute_with_wrappers
    return executor(sql, params, many, context)
  File "/usr/local/lib/python3.8/dist-packages/django/db/backends/utils.py", line 84, in _execute
    return self.cursor.execute(sql, params)
  File "/usr/local/lib/python3.8/dist-packages/django/db/utils.py", line 90, in __exit__
    raise dj_exc_value.with_traceback(traceback) from exc_value
  File "/usr/local/lib/python3.8/dist-packages/django/db/backends/utils.py", line 84, in _execute
    return self.cursor.execute(sql, params)
  File "/usr/local/lib/python3.8/dist-packages/django/db/backends/sqlite3/base.py", line 423, in execute
    return Database.Cursor.execute(self, query, params)
django.db.utils.OperationalError: no such table: auth_user
[06/Nov/2022 06:58:09] "POST /admin/login/?next=/admin/ HTTP/1.1" 500 221735
[06/Nov/2022 06:58:11] "GET /admin/login/?next=/admin/ HTTP/1.1" 200 2216
/www/django_www/django_www/urls.py changed, reloading.
Performing system checks...

System check identified no issues (0 silenced).

You have 18 unapplied migration(s). Your project may not work properly until you apply the migrations for app(s): admin, auth, contenttypes, sessions.
Run 'python manage.py migrate' to apply them.
November 06, 2022 - 06:56:55
Django version 3.2, using settings 'django_www.settings'
Starting development server at http://0.0.0.0:80/
Quit the server with CONTROL-C.
Watching for file changes with StatReloader
Exception in thread django-main-thread:
Traceback (most recent call last):
  File "/usr/lib/python3.8/threading.py", line 932, in _bootstrap_inner
    self.run()
  File "/usr/lib/python3.8/threading.py", line 870, in run
    self._target(*self._args, **self._kwargs)
  File "/usr/local/lib/python3.8/dist-packages/django/utils/autoreload.py", line 64, in wrapper
    fn(*args, **kwargs)
  File "/usr/local/lib/python3.8/dist-packages/django/core/management/commands/runserver.py", line 118, in inner_run
    self.check(display_num_errors=True)
  File "/usr/local/lib/python3.8/dist-packages/django/core/management/base.py", line 419, in check
    all_issues = checks.run_checks(
  File "/usr/local/lib/python3.8/dist-packages/django/core/checks/registry.py", line 76, in run_checks
    new_errors = check(app_configs=app_configs, databases=databases)
  File "/usr/local/lib/python3.8/dist-packages/django/core/checks/urls.py", line 13, in check_url_config
    return check_resolver(resolver)
  File "/usr/local/lib/python3.8/dist-packages/django/core/checks/urls.py", line 23, in check_resolver
    return check_method()
  File "/usr/local/lib/python3.8/dist-packages/django/urls/resolvers.py", line 412, in check
    for pattern in self.url_patterns:
  File "/usr/local/lib/python3.8/dist-packages/django/utils/functional.py", line 48, in __get__
    res = instance.__dict__[self.name] = self.func(instance)
  File "/usr/local/lib/python3.8/dist-packages/django/urls/resolvers.py", line 598, in url_patterns
    patterns = getattr(self.urlconf_module, "urlpatterns", self.urlconf_module)
  File "/usr/local/lib/python3.8/dist-packages/django/utils/functional.py", line 48, in __get__
    res = instance.__dict__[self.name] = self.func(instance)
  File "/usr/local/lib/python3.8/dist-packages/django/urls/resolvers.py", line 591, in urlconf_module
    return import_module(self.urlconf_name)
  File "/usr/lib/python3.8/importlib/__init__.py", line 127, in import_module
    return _bootstrap._gcd_import(name[level:], package, level)
  File "<frozen importlib._bootstrap>", line 1014, in _gcd_import
  File "<frozen importlib._bootstrap>", line 991, in _find_and_load
  File "<frozen importlib._bootstrap>", line 975, in _find_and_load_unlocked
  File "<frozen importlib._bootstrap>", line 671, in _load_unlocked
  File "<frozen importlib._bootstrap_external>", line 848, in exec_module
  File "<frozen importlib._bootstrap>", line 219, in _call_with_frames_removed
  File "/www/django_www/django_www/urls.py", line 21, in <module>
    path('demo/text/', views),
  File "/usr/local/lib/python3.8/dist-packages/django/urls/conf.py", line 73, in _path
    raise TypeError('view must be a callable or a list/tuple in the case of include().')
TypeError: view must be a callable or a list/tuple in the case of include().
/www/django_www/app01/views.py changed, reloading.
Performing system checks...

Watching for file changes with StatReloader
Exception in thread django-main-thread:
Traceback (most recent call last):
  File "/usr/lib/python3.8/threading.py", line 932, in _bootstrap_inner
    self.run()
  File "/usr/lib/python3.8/threading.py", line 870, in run
    self._target(*self._args, **self._kwargs)
  File "/usr/local/lib/python3.8/dist-packages/django/utils/autoreload.py", line 64, in wrapper
    fn(*args, **kwargs)
  File "/usr/local/lib/python3.8/dist-packages/django/core/management/commands/runserver.py", line 118, in inner_run
    self.check(display_num_errors=True)
  File "/usr/local/lib/python3.8/dist-packages/django/core/management/base.py", line 419, in check
    all_issues = checks.run_checks(
  File "/usr/local/lib/python3.8/dist-packages/django/core/checks/registry.py", line 76, in run_checks
    new_errors = check(app_configs=app_configs, databases=databases)
  File "/usr/local/lib/python3.8/dist-packages/django/core/checks/urls.py", line 13, in check_url_config
    return check_resolver(resolver)
  File "/usr/local/lib/python3.8/dist-packages/django/core/checks/urls.py", line 23, in check_resolver
    return check_method()
  File "/usr/local/lib/python3.8/dist-packages/django/urls/resolvers.py", line 412, in check
    for pattern in self.url_patterns:
  File "/usr/local/lib/python3.8/dist-packages/django/utils/functional.py", line 48, in __get__
    res = instance.__dict__[self.name] = self.func(instance)
  File "/usr/local/lib/python3.8/dist-packages/django/urls/resolvers.py", line 598, in url_patterns
    patterns = getattr(self.urlconf_module, "urlpatterns", self.urlconf_module)
  File "/usr/local/lib/python3.8/dist-packages/django/utils/functional.py", line 48, in __get__
    res = instance.__dict__[self.name] = self.func(instance)
  File "/usr/local/lib/python3.8/dist-packages/django/urls/resolvers.py", line 591, in urlconf_module
    return import_module(self.urlconf_name)
  File "/usr/lib/python3.8/importlib/__init__.py", line 127, in import_module
    return _bootstrap._gcd_import(name[level:], package, level)
  File "<frozen importlib._bootstrap>", line 1014, in _gcd_import
  File "<frozen importlib._bootstrap>", line 991, in _find_and_load
  File "<frozen importlib._bootstrap>", line 975, in _find_and_load_unlocked
  File "<frozen importlib._bootstrap>", line 671, in _load_unlocked
  File "<frozen importlib._bootstrap_external>", line 848, in exec_module
  File "<frozen importlib._bootstrap>", line 219, in _call_with_frames_removed
  File "/www/django_www/django_www/urls.py", line 21, in <module>
    path('demo/text/', views),
  File "/usr/local/lib/python3.8/dist-packages/django/urls/conf.py", line 73, in _path
    raise TypeError('view must be a callable or a list/tuple in the case of include().')
TypeError: view must be a callable or a list/tuple in the case of include().
/www/django_www/app01/views.py changed, reloading.
Performing system checks...

Watching for file changes with StatReloader
Exception in thread django-main-thread:
Traceback (most recent call last):
  File "/usr/lib/python3.8/threading.py", line 932, in _bootstrap_inner
    self.run()
  File "/usr/lib/python3.8/threading.py", line 870, in run
    self._target(*self._args, **self._kwargs)
  File "/usr/local/lib/python3.8/dist-packages/django/utils/autoreload.py", line 64, in wrapper
    fn(*args, **kwargs)
  File "/usr/local/lib/python3.8/dist-packages/django/core/management/commands/runserver.py", line 118, in inner_run
    self.check(display_num_errors=True)
  File "/usr/local/lib/python3.8/dist-packages/django/core/management/base.py", line 419, in check
    all_issues = checks.run_checks(
  File "/usr/local/lib/python3.8/dist-packages/django/core/checks/registry.py", line 76, in run_checks
    new_errors = check(app_configs=app_configs, databases=databases)
  File "/usr/local/lib/python3.8/dist-packages/django/core/checks/urls.py", line 13, in check_url_config
    return check_resolver(resolver)
  File "/usr/local/lib/python3.8/dist-packages/django/core/checks/urls.py", line 23, in check_resolver
    return check_method()
  File "/usr/local/lib/python3.8/dist-packages/django/urls/resolvers.py", line 412, in check
    for pattern in self.url_patterns:
  File "/usr/local/lib/python3.8/dist-packages/django/utils/functional.py", line 48, in __get__
    res = instance.__dict__[self.name] = self.func(instance)
  File "/usr/local/lib/python3.8/dist-packages/django/urls/resolvers.py", line 598, in url_patterns
    patterns = getattr(self.urlconf_module, "urlpatterns", self.urlconf_module)
  File "/usr/local/lib/python3.8/dist-packages/django/utils/functional.py", line 48, in __get__
    res = instance.__dict__[self.name] = self.func(instance)
  File "/usr/local/lib/python3.8/dist-packages/django/urls/resolvers.py", line 591, in urlconf_module
    return import_module(self.urlconf_name)
  File "/usr/lib/python3.8/importlib/__init__.py", line 127, in import_module
    return _bootstrap._gcd_import(name[level:], package, level)
  File "<frozen importlib._bootstrap>", line 1014, in _gcd_import
  File "<frozen importlib._bootstrap>", line 991, in _find_and_load
  File "<frozen importlib._bootstrap>", line 975, in _find_and_load_unlocked
  File "<frozen importlib._bootstrap>", line 671, in _load_unlocked
  File "<frozen importlib._bootstrap_external>", line 848, in exec_module
  File "<frozen importlib._bootstrap>", line 219, in _call_with_frames_removed
  File "/www/django_www/django_www/urls.py", line 21, in <module>
    path('demo/text/', views),
  File "/usr/local/lib/python3.8/dist-packages/django/urls/conf.py", line 73, in _path
    raise TypeError('view must be a callable or a list/tuple in the case of include().')
TypeError: view must be a callable or a list/tuple in the case of include().
nohup: ignoring input
Watching for file changes with StatReloader
Not Found: /
[06/Nov/2022 07:03:31] "GET / HTTP/1.1" 404 2062
Not Found: /
[06/Nov/2022 07:03:31] "GET / HTTP/1.1" 404 2062
Not Found: /
[06/Nov/2022 07:03:32] "GET / HTTP/1.1" 404 2062
Not Found: /
[06/Nov/2022 07:03:32] "GET / HTTP/1.1" 404 2062
Not Found: /
[06/Nov/2022 07:03:32] "GET / HTTP/1.1" 404 2062
Not Found: /
[06/Nov/2022 07:03:33] "GET / HTTP/1.1" 404 2062
Not Found: /
[06/Nov/2022 07:03:33] "GET / HTTP/1.1" 404 2062
Not Found: /
[06/Nov/2022 07:03:34] "GET / HTTP/1.1" 404 2062
Not Found: /
[06/Nov/2022 07:03:34] "GET / HTTP/1.1" 404 2062
Not Found: /
[06/Nov/2022 07:03:34] "GET / HTTP/1.1" 404 2062
Not Found: /
[06/Nov/2022 07:03:35] "GET / HTTP/1.1" 404 2062
Not Found: /
[06/Nov/2022 07:03:40] "GET / HTTP/1.1" 404 2062
Internal Server Error: /demo/text/
Traceback (most recent call last):
  File "/usr/local/lib/python3.8/dist-packages/django/core/handlers/exception.py", line 47, in inner
    response = get_response(request)
  File "/usr/local/lib/python3.8/dist-packages/django/core/handlers/base.py", line 188, in _get_response
    self.check_response(response, callback)
  File "/usr/local/lib/python3.8/dist-packages/django/core/handlers/base.py", line 309, in check_response
    raise ValueError(
ValueError: The view app01.views.demo_text didn't return an HttpResponse object. It returned None instead.
[06/Nov/2022 07:03:52] "GET /demo/text/ HTTP/1.1" 500 57051
/www/django_www/app01/views.py changed, reloading.
Performing system checks...

System check identified no issues (0 silenced).

You have 18 unapplied migration(s). Your project may not work properly until you apply the migrations for app(s): admin, auth, contenttypes, sessions.
Run 'python manage.py migrate' to apply them.
November 06, 2022 - 07:03:31
Django version 3.2, using settings 'django_www.settings'
Starting development server at http://0.0.0.0:80/
Quit the server with CONTROL-C.
Watching for file changes with StatReloader
[06/Nov/2022 07:05:00] "GET /demo/text/ HTTP/1.1" 200 4
[06/Nov/2022 07:05:07] "GET /demo/text/ HTTP/1.1" 200 4
Not Found: /favicon.ico
[06/Nov/2022 07:16:09] "GET /favicon.ico HTTP/1.1" 404 2113
Not Found: /
[06/Nov/2022 07:16:32] "GET / HTTP/1.1" 404 2062
[06/Nov/2022 07:16:42] "GET /demo/text HTTP/1.1" 301 0
[06/Nov/2022 07:16:42] "GET /demo/text/ HTTP/1.1" 200 4
Not Found: /
[06/Nov/2022 15:02:37] "GET / HTTP/1.1" 404 2062
Not Found: /favicon.ico
[06/Nov/2022 15:02:38] "GET /favicon.ico HTTP/1.1" 404 2113
Not Found: /text
[06/Nov/2022 15:02:41] "GET /text HTTP/1.1" 404 2092
Not Found: /test
[06/Nov/2022 15:02:48] "GET /test HTTP/1.1" 404 2092
Not Found: /test/
[06/Nov/2022 15:02:52] "GET /test/ HTTP/1.1" 404 2095
[06/Nov/2022 15:03:03] "GET /demo/text/ HTTP/1.1" 200 4
/www/django_www/django_www/settings.py changed, reloading.
Performing system checks...

System check identified no issues (0 silenced).

You have 18 unapplied migration(s). Your project may not work properly until you apply the migrations for app(s): admin, auth, contenttypes, sessions.
Run 'python manage.py migrate' to apply them.
November 06, 2022 - 07:04:59
Django version 3.2, using settings 'django_www.settings'
Starting development server at http://0.0.0.0:80/
Quit the server with CONTROL-C.
Watching for file changes with StatReloader
Exception in thread django-main-thread:
Traceback (most recent call last):
  File "/usr/local/lib/python3.8/dist-packages/django/db/backends/base/base.py", line 219, in ensure_connection
    self.connect()
  File "/usr/local/lib/python3.8/dist-packages/django/utils/asyncio.py", line 26, in inner
    return func(*args, **kwargs)
  File "/usr/local/lib/python3.8/dist-packages/django/db/backends/base/base.py", line 200, in connect
    self.connection = self.get_new_connection(conn_params)
  File "/usr/local/lib/python3.8/dist-packages/django/utils/asyncio.py", line 26, in inner
    return func(*args, **kwargs)
  File "/usr/local/lib/python3.8/dist-packages/django/db/backends/mysql/base.py", line 234, in get_new_connection
    connection = Database.connect(**conn_params)
  File "/usr/local/lib/python3.8/dist-packages/MySQLdb/__init__.py", line 123, in Connect
    return Connection(*args, **kwargs)
  File "/usr/local/lib/python3.8/dist-packages/MySQLdb/connections.py", line 185, in __init__
    super().__init__(*args, **kwargs2)
MySQLdb.OperationalError: (2003, "Can't connect to MySQL server on 'mysql5.7.39:50001' (111)")

The above exception was the direct cause of the following exception:

Traceback (most recent call last):
  File "/usr/lib/python3.8/threading.py", line 932, in _bootstrap_inner
    self.run()
  File "/usr/lib/python3.8/threading.py", line 870, in run
    self._target(*self._args, **self._kwargs)
  File "/usr/local/lib/python3.8/dist-packages/django/utils/autoreload.py", line 64, in wrapper
    fn(*args, **kwargs)
  File "/usr/local/lib/python3.8/dist-packages/django/core/management/commands/runserver.py", line 121, in inner_run
    self.check_migrations()
  File "/usr/local/lib/python3.8/dist-packages/django/core/management/base.py", line 486, in check_migrations
    executor = MigrationExecutor(connections[DEFAULT_DB_ALIAS])
  File "/usr/local/lib/python3.8/dist-packages/django/db/migrations/executor.py", line 18, in __init__
    self.loader = MigrationLoader(self.connection)
  File "/usr/local/lib/python3.8/dist-packages/django/db/migrations/loader.py", line 53, in __init__
    self.build_graph()
  File "/usr/local/lib/python3.8/dist-packages/django/db/migrations/loader.py", line 220, in build_graph
    self.applied_migrations = recorder.applied_migrations()
  File "/usr/local/lib/python3.8/dist-packages/django/db/migrations/recorder.py", line 77, in applied_migrations
    if self.has_table():
  File "/usr/local/lib/python3.8/dist-packages/django/db/migrations/recorder.py", line 55, in has_table
    with self.connection.cursor() as cursor:
  File "/usr/local/lib/python3.8/dist-packages/django/utils/asyncio.py", line 26, in inner
    return func(*args, **kwargs)
  File "/usr/local/lib/python3.8/dist-packages/django/db/backends/base/base.py", line 259, in cursor
    return self._cursor()
  File "/usr/local/lib/python3.8/dist-packages/django/db/backends/base/base.py", line 235, in _cursor
    self.ensure_connection()
  File "/usr/local/lib/python3.8/dist-packages/django/utils/asyncio.py", line 26, in inner
    return func(*args, **kwargs)
  File "/usr/local/lib/python3.8/dist-packages/django/db/backends/base/base.py", line 219, in ensure_connection
    self.connect()
  File "/usr/local/lib/python3.8/dist-packages/django/db/utils.py", line 90, in __exit__
    raise dj_exc_value.with_traceback(traceback) from exc_value
  File "/usr/local/lib/python3.8/dist-packages/django/db/backends/base/base.py", line 219, in ensure_connection
    self.connect()
  File "/usr/local/lib/python3.8/dist-packages/django/utils/asyncio.py", line 26, in inner
    return func(*args, **kwargs)
  File "/usr/local/lib/python3.8/dist-packages/django/db/backends/base/base.py", line 200, in connect
    self.connection = self.get_new_connection(conn_params)
  File "/usr/local/lib/python3.8/dist-packages/django/utils/asyncio.py", line 26, in inner
    return func(*args, **kwargs)
  File "/usr/local/lib/python3.8/dist-packages/django/db/backends/mysql/base.py", line 234, in get_new_connection
    connection = Database.connect(**conn_params)
  File "/usr/local/lib/python3.8/dist-packages/MySQLdb/__init__.py", line 123, in Connect
    return Connection(*args, **kwargs)
  File "/usr/local/lib/python3.8/dist-packages/MySQLdb/connections.py", line 185, in __init__
    super().__init__(*args, **kwargs2)
django.db.utils.OperationalError: (2003, "Can't connect to MySQL server on 'mysql5.7.39:50001' (111)")
/www/django_www/django_www/settings.py changed, reloading.
Performing system checks...

System check identified no issues (0 silenced).
Watching for file changes with StatReloader
[06/Nov/2022 15:06:58] "GET /demo/text/ HTTP/1.1" 200 4
