[01/Feb/2023 09:41:44] "GET /lifelog/ HTTP/1.1" 200 36812
[01/Feb/2023 09:41:49] "GET /lifelog/log/ HTTP/1.1" 200 4127
Internal Server Error: /lifelog/log/
Traceback (most recent call last):
  File "/usr/local/lib/python3.8/dist-packages/django/db/backends/utils.py", line 84, in _execute
    return self.cursor.execute(sql, params)
  File "/usr/local/lib/python3.8/dist-packages/django/db/backends/mysql/base.py", line 73, in execute
    return self.cursor.execute(query, args)
  File "/usr/local/lib/python3.8/dist-packages/MySQLdb/cursors.py", line 206, in execute
    res = self._query(query)
  File "/usr/local/lib/python3.8/dist-packages/MySQLdb/cursors.py", line 319, in _query
    db.query(q)
  File "/usr/local/lib/python3.8/dist-packages/MySQLdb/connections.py", line 254, in query
    _mysql.connection.query(self, query)
MySQLdb.ProgrammingError: (1146, "Table 'blog_django.lifelog' doesn't exist")

The above exception was the direct cause of the following exception:

Traceback (most recent call last):
  File "/usr/local/lib/python3.8/dist-packages/django/core/handlers/exception.py", line 47, in inner
    response = get_response(request)
  File "/usr/local/lib/python3.8/dist-packages/django/core/handlers/base.py", line 181, in _get_response
    response = wrapped_callback(request, *callback_args, **callback_kwargs)
  File "/www/django_www/app01/views.py", line 57, in lifelog_log
    if form.is_valid():
  File "/usr/local/lib/python3.8/dist-packages/django/forms/forms.py", line 175, in is_valid
    return self.is_bound and not self.errors
  File "/usr/local/lib/python3.8/dist-packages/django/forms/forms.py", line 170, in errors
    self.full_clean()
  File "/usr/local/lib/python3.8/dist-packages/django/forms/forms.py", line 374, in full_clean
    self._post_clean()
  File "/usr/local/lib/python3.8/dist-packages/django/forms/models.py", line 419, in _post_clean
    self.validate_unique()
  File "/usr/local/lib/python3.8/dist-packages/django/forms/models.py", line 428, in validate_unique
    self.instance.validate_unique(exclude=exclude)
  File "/usr/local/lib/python3.8/dist-packages/django/db/models/base.py", line 1016, in validate_unique
    errors = self._perform_unique_checks(unique_checks)
  File "/usr/local/lib/python3.8/dist-packages/django/db/models/base.py", line 1119, in _perform_unique_checks
    if qs.exists():
  File "/usr/local/lib/python3.8/dist-packages/django/db/models/query.py", line 808, in exists
    return self.query.has_results(using=self.db)
  File "/usr/local/lib/python3.8/dist-packages/django/db/models/sql/query.py", line 559, in has_results
    return compiler.has_results()
  File "/usr/local/lib/python3.8/dist-packages/django/db/models/sql/compiler.py", line 1139, in has_results
    return bool(self.execute_sql(SINGLE))
  File "/usr/local/lib/python3.8/dist-packages/django/db/models/sql/compiler.py", line 1169, in execute_sql
    cursor.execute(sql, params)
  File "/usr/local/lib/python3.8/dist-packages/django/db/backends/utils.py", line 98, in execute
    return super().execute(sql, params)
  File "/usr/local/lib/python3.8/dist-packages/django/db/backends/utils.py", line 66, in execute
    return self._execute_with_wrappers(sql, params, many=False, executor=self._execute)
  File "/usr/local/lib/python3.8/dist-packages/django/db/backends/utils.py", line 75, in _execute_with_wrappers
    return executor(sql, params, many, context)
  File "/usr/local/lib/python3.8/dist-packages/django/db/backends/utils.py", line 84, in _execute
    return self.cursor.execute(sql, params)
  File "/usr/local/lib/python3.8/dist-packages/django/db/utils.py", line 90, in __exit__
    raise dj_exc_value.with_traceback(traceback) from exc_value
  File "/usr/local/lib/python3.8/dist-packages/django/db/backends/utils.py", line 84, in _execute
    return self.cursor.execute(sql, params)
  File "/usr/local/lib/python3.8/dist-packages/django/db/backends/mysql/base.py", line 73, in execute
    return self.cursor.execute(query, args)
  File "/usr/local/lib/python3.8/dist-packages/MySQLdb/cursors.py", line 206, in execute
    res = self._query(query)
  File "/usr/local/lib/python3.8/dist-packages/MySQLdb/cursors.py", line 319, in _query
    db.query(q)
  File "/usr/local/lib/python3.8/dist-packages/MySQLdb/connections.py", line 254, in query
    _mysql.connection.query(self, query)
django.db.utils.ProgrammingError: (1146, "Table 'blog_django.lifelog' doesn't exist")
[01/Feb/2023 09:45:17] "POST /lifelog/log/ HTTP/1.1" 500 170203
/www/django_www/app01/views.py changed, reloading.
Performing system checks...

System check identified no issues (0 silenced).

You have 1 unapplied migration(s). Your project may not work properly until you apply the migrations for app(s): app01.
Run 'python manage.py migrate' to apply them.
January 26, 2023 - 06:09:29
Django version 3.2, using settings 'django_www.settings'
Starting development server at http://0.0.0.0:80/
Quit the server with CONTROL-C.
Watching for file changes with StatReloader
Internal Server Error: /lifelog/log/
Traceback (most recent call last):
  File "/usr/local/lib/python3.8/dist-packages/django/db/backends/utils.py", line 84, in _execute
    return self.cursor.execute(sql, params)
  File "/usr/local/lib/python3.8/dist-packages/django/db/backends/mysql/base.py", line 73, in execute
    return self.cursor.execute(query, args)
  File "/usr/local/lib/python3.8/dist-packages/MySQLdb/cursors.py", line 206, in execute
    res = self._query(query)
  File "/usr/local/lib/python3.8/dist-packages/MySQLdb/cursors.py", line 319, in _query
    db.query(q)
  File "/usr/local/lib/python3.8/dist-packages/MySQLdb/connections.py", line 254, in query
    _mysql.connection.query(self, query)
MySQLdb.ProgrammingError: (1146, "Table 'blog_django.lifelog' doesn't exist")

The above exception was the direct cause of the following exception:

Traceback (most recent call last):
  File "/usr/local/lib/python3.8/dist-packages/django/core/handlers/exception.py", line 47, in inner
    response = get_response(request)
  File "/usr/local/lib/python3.8/dist-packages/django/core/handlers/base.py", line 181, in _get_response
    response = wrapped_callback(request, *callback_args, **callback_kwargs)
  File "/www/django_www/app01/views.py", line 57, in lifelog_log
    if form.is_valid():
  File "/usr/local/lib/python3.8/dist-packages/django/forms/forms.py", line 175, in is_valid
    return self.is_bound and not self.errors
  File "/usr/local/lib/python3.8/dist-packages/django/forms/forms.py", line 170, in errors
    self.full_clean()
  File "/usr/local/lib/python3.8/dist-packages/django/forms/forms.py", line 374, in full_clean
    self._post_clean()
  File "/usr/local/lib/python3.8/dist-packages/django/forms/models.py", line 419, in _post_clean
    self.validate_unique()
  File "/usr/local/lib/python3.8/dist-packages/django/forms/models.py", line 428, in validate_unique
    self.instance.validate_unique(exclude=exclude)
  File "/usr/local/lib/python3.8/dist-packages/django/db/models/base.py", line 1016, in validate_unique
    errors = self._perform_unique_checks(unique_checks)
  File "/usr/local/lib/python3.8/dist-packages/django/db/models/base.py", line 1119, in _perform_unique_checks
    if qs.exists():
  File "/usr/local/lib/python3.8/dist-packages/django/db/models/query.py", line 808, in exists
    return self.query.has_results(using=self.db)
  File "/usr/local/lib/python3.8/dist-packages/django/db/models/sql/query.py", line 559, in has_results
    return compiler.has_results()
  File "/usr/local/lib/python3.8/dist-packages/django/db/models/sql/compiler.py", line 1139, in has_results
    return bool(self.execute_sql(SINGLE))
  File "/usr/local/lib/python3.8/dist-packages/django/db/models/sql/compiler.py", line 1169, in execute_sql
    cursor.execute(sql, params)
  File "/usr/local/lib/python3.8/dist-packages/django/db/backends/utils.py", line 98, in execute
    return super().execute(sql, params)
  File "/usr/local/lib/python3.8/dist-packages/django/db/backends/utils.py", line 66, in execute
    return self._execute_with_wrappers(sql, params, many=False, executor=self._execute)
  File "/usr/local/lib/python3.8/dist-packages/django/db/backends/utils.py", line 75, in _execute_with_wrappers
    return executor(sql, params, many, context)
  File "/usr/local/lib/python3.8/dist-packages/django/db/backends/utils.py", line 84, in _execute
    return self.cursor.execute(sql, params)
  File "/usr/local/lib/python3.8/dist-packages/django/db/utils.py", line 90, in __exit__
    raise dj_exc_value.with_traceback(traceback) from exc_value
  File "/usr/local/lib/python3.8/dist-packages/django/db/backends/utils.py", line 84, in _execute
    return self.cursor.execute(sql, params)
  File "/usr/local/lib/python3.8/dist-packages/django/db/backends/mysql/base.py", line 73, in execute
    return self.cursor.execute(query, args)
  File "/usr/local/lib/python3.8/dist-packages/MySQLdb/cursors.py", line 206, in execute
    res = self._query(query)
  File "/usr/local/lib/python3.8/dist-packages/MySQLdb/cursors.py", line 319, in _query
    db.query(q)
  File "/usr/local/lib/python3.8/dist-packages/MySQLdb/connections.py", line 254, in query
    _mysql.connection.query(self, query)
django.db.utils.ProgrammingError: (1146, "Table 'blog_django.lifelog' doesn't exist")
[01/Feb/2023 11:26:58] "POST /lifelog/log/ HTTP/1.1" 500 170221
Internal Server Error: /lifelog/log/
Traceback (most recent call last):
  File "/usr/local/lib/python3.8/dist-packages/django/db/backends/utils.py", line 84, in _execute
    return self.cursor.execute(sql, params)
  File "/usr/local/lib/python3.8/dist-packages/django/db/backends/mysql/base.py", line 73, in execute
    return self.cursor.execute(query, args)
  File "/usr/local/lib/python3.8/dist-packages/MySQLdb/cursors.py", line 206, in execute
    res = self._query(query)
  File "/usr/local/lib/python3.8/dist-packages/MySQLdb/cursors.py", line 319, in _query
    db.query(q)
  File "/usr/local/lib/python3.8/dist-packages/MySQLdb/connections.py", line 254, in query
    _mysql.connection.query(self, query)
MySQLdb.ProgrammingError: (1146, "Table 'blog_django.lifelog' doesn't exist")

The above exception was the direct cause of the following exception:

Traceback (most recent call last):
  File "/usr/local/lib/python3.8/dist-packages/django/core/handlers/exception.py", line 47, in inner
    response = get_response(request)
  File "/usr/local/lib/python3.8/dist-packages/django/core/handlers/base.py", line 181, in _get_response
    response = wrapped_callback(request, *callback_args, **callback_kwargs)
  File "/www/django_www/app01/views.py", line 57, in lifelog_log
    if form.is_valid():
  File "/usr/local/lib/python3.8/dist-packages/django/forms/forms.py", line 175, in is_valid
    return self.is_bound and not self.errors
  File "/usr/local/lib/python3.8/dist-packages/django/forms/forms.py", line 170, in errors
    self.full_clean()
  File "/usr/local/lib/python3.8/dist-packages/django/forms/forms.py", line 374, in full_clean
    self._post_clean()
  File "/usr/local/lib/python3.8/dist-packages/django/forms/models.py", line 419, in _post_clean
    self.validate_unique()
  File "/usr/local/lib/python3.8/dist-packages/django/forms/models.py", line 428, in validate_unique
    self.instance.validate_unique(exclude=exclude)
  File "/usr/local/lib/python3.8/dist-packages/django/db/models/base.py", line 1016, in validate_unique
    errors = self._perform_unique_checks(unique_checks)
  File "/usr/local/lib/python3.8/dist-packages/django/db/models/base.py", line 1119, in _perform_unique_checks
    if qs.exists():
  File "/usr/local/lib/python3.8/dist-packages/django/db/models/query.py", line 808, in exists
    return self.query.has_results(using=self.db)
  File "/usr/local/lib/python3.8/dist-packages/django/db/models/sql/query.py", line 559, in has_results
    return compiler.has_results()
  File "/usr/local/lib/python3.8/dist-packages/django/db/models/sql/compiler.py", line 1139, in has_results
    return bool(self.execute_sql(SINGLE))
  File "/usr/local/lib/python3.8/dist-packages/django/db/models/sql/compiler.py", line 1169, in execute_sql
    cursor.execute(sql, params)
  File "/usr/local/lib/python3.8/dist-packages/django/db/backends/utils.py", line 98, in execute
    return super().execute(sql, params)
  File "/usr/local/lib/python3.8/dist-packages/django/db/backends/utils.py", line 66, in execute
    return self._execute_with_wrappers(sql, params, many=False, executor=self._execute)
  File "/usr/local/lib/python3.8/dist-packages/django/db/backends/utils.py", line 75, in _execute_with_wrappers
    return executor(sql, params, many, context)
  File "/usr/local/lib/python3.8/dist-packages/django/db/backends/utils.py", line 84, in _execute
    return self.cursor.execute(sql, params)
  File "/usr/local/lib/python3.8/dist-packages/django/db/utils.py", line 90, in __exit__
    raise dj_exc_value.with_traceback(traceback) from exc_value
  File "/usr/local/lib/python3.8/dist-packages/django/db/backends/utils.py", line 84, in _execute
    return self.cursor.execute(sql, params)
  File "/usr/local/lib/python3.8/dist-packages/django/db/backends/mysql/base.py", line 73, in execute
    return self.cursor.execute(query, args)
  File "/usr/local/lib/python3.8/dist-packages/MySQLdb/cursors.py", line 206, in execute
    res = self._query(query)
  File "/usr/local/lib/python3.8/dist-packages/MySQLdb/cursors.py", line 319, in _query
    db.query(q)
  File "/usr/local/lib/python3.8/dist-packages/MySQLdb/connections.py", line 254, in query
    _mysql.connection.query(self, query)
django.db.utils.ProgrammingError: (1146, "Table 'blog_django.lifelog' doesn't exist")
[01/Feb/2023 11:35:42] "POST /lifelog/log/ HTTP/1.1" 500 170221
/www/django_www/app01/views.py changed, reloading.
Performing system checks...

System check identified no issues (0 silenced).

You have 1 unapplied migration(s). Your project may not work properly until you apply the migrations for app(s): app01.
Run 'python manage.py migrate' to apply them.
February 01, 2023 - 11:26:51
Django version 3.2, using settings 'django_www.settings'
Starting development server at http://0.0.0.0:80/
Quit the server with CONTROL-C.
Watching for file changes with StatReloader
Internal Server Error: /lifelog/log/
Traceback (most recent call last):
  File "/usr/local/lib/python3.8/dist-packages/django/db/backends/utils.py", line 84, in _execute
    return self.cursor.execute(sql, params)
  File "/usr/local/lib/python3.8/dist-packages/django/db/backends/mysql/base.py", line 73, in execute
    return self.cursor.execute(query, args)
  File "/usr/local/lib/python3.8/dist-packages/MySQLdb/cursors.py", line 206, in execute
    res = self._query(query)
  File "/usr/local/lib/python3.8/dist-packages/MySQLdb/cursors.py", line 319, in _query
    db.query(q)
  File "/usr/local/lib/python3.8/dist-packages/MySQLdb/connections.py", line 254, in query
    _mysql.connection.query(self, query)
MySQLdb.ProgrammingError: (1146, "Table 'blog_django.lifelog' doesn't exist")

The above exception was the direct cause of the following exception:

Traceback (most recent call last):
  File "/usr/local/lib/python3.8/dist-packages/django/core/handlers/exception.py", line 47, in inner
    response = get_response(request)
  File "/usr/local/lib/python3.8/dist-packages/django/core/handlers/base.py", line 181, in _get_response
    response = wrapped_callback(request, *callback_args, **callback_kwargs)
  File "/www/django_www/app01/views.py", line 57, in lifelog_log
    if form.is_valid():
  File "/usr/local/lib/python3.8/dist-packages/django/forms/forms.py", line 175, in is_valid
    return self.is_bound and not self.errors
  File "/usr/local/lib/python3.8/dist-packages/django/forms/forms.py", line 170, in errors
    self.full_clean()
  File "/usr/local/lib/python3.8/dist-packages/django/forms/forms.py", line 374, in full_clean
    self._post_clean()
  File "/usr/local/lib/python3.8/dist-packages/django/forms/models.py", line 419, in _post_clean
    self.validate_unique()
  File "/usr/local/lib/python3.8/dist-packages/django/forms/models.py", line 428, in validate_unique
    self.instance.validate_unique(exclude=exclude)
  File "/usr/local/lib/python3.8/dist-packages/django/db/models/base.py", line 1016, in validate_unique
    errors = self._perform_unique_checks(unique_checks)
  File "/usr/local/lib/python3.8/dist-packages/django/db/models/base.py", line 1119, in _perform_unique_checks
    if qs.exists():
  File "/usr/local/lib/python3.8/dist-packages/django/db/models/query.py", line 808, in exists
    return self.query.has_results(using=self.db)
  File "/usr/local/lib/python3.8/dist-packages/django/db/models/sql/query.py", line 559, in has_results
    return compiler.has_results()
  File "/usr/local/lib/python3.8/dist-packages/django/db/models/sql/compiler.py", line 1139, in has_results
    return bool(self.execute_sql(SINGLE))
  File "/usr/local/lib/python3.8/dist-packages/django/db/models/sql/compiler.py", line 1169, in execute_sql
    cursor.execute(sql, params)
  File "/usr/local/lib/python3.8/dist-packages/django/db/backends/utils.py", line 98, in execute
    return super().execute(sql, params)
  File "/usr/local/lib/python3.8/dist-packages/django/db/backends/utils.py", line 66, in execute
    return self._execute_with_wrappers(sql, params, many=False, executor=self._execute)
  File "/usr/local/lib/python3.8/dist-packages/django/db/backends/utils.py", line 75, in _execute_with_wrappers
    return executor(sql, params, many, context)
  File "/usr/local/lib/python3.8/dist-packages/django/db/backends/utils.py", line 84, in _execute
    return self.cursor.execute(sql, params)
  File "/usr/local/lib/python3.8/dist-packages/django/db/utils.py", line 90, in __exit__
    raise dj_exc_value.with_traceback(traceback) from exc_value
  File "/usr/local/lib/python3.8/dist-packages/django/db/backends/utils.py", line 84, in _execute
    return self.cursor.execute(sql, params)
  File "/usr/local/lib/python3.8/dist-packages/django/db/backends/mysql/base.py", line 73, in execute
    return self.cursor.execute(query, args)
  File "/usr/local/lib/python3.8/dist-packages/MySQLdb/cursors.py", line 206, in execute
    res = self._query(query)
  File "/usr/local/lib/python3.8/dist-packages/MySQLdb/cursors.py", line 319, in _query
    db.query(q)
  File "/usr/local/lib/python3.8/dist-packages/MySQLdb/connections.py", line 254, in query
    _mysql.connection.query(self, query)
django.db.utils.ProgrammingError: (1146, "Table 'blog_django.lifelog' doesn't exist")
[01/Feb/2023 11:44:20] "POST /lifelog/log/ HTTP/1.1" 500 170203
/www/django_www/app01/models.py changed, reloading.
Performing system checks...

System check identified no issues (0 silenced).
February 01, 2023 - 11:36:40
Django version 3.2, using settings 'django_www.settings'
Starting development server at http://0.0.0.0:80/
Quit the server with CONTROL-C.
Watching for file changes with StatReloader
Internal Server Error: /lifelog/log/
Traceback (most recent call last):
  File "/usr/local/lib/python3.8/dist-packages/django/db/backends/utils.py", line 84, in _execute
    return self.cursor.execute(sql, params)
  File "/usr/local/lib/python3.8/dist-packages/django/db/backends/mysql/base.py", line 73, in execute
    return self.cursor.execute(query, args)
  File "/usr/local/lib/python3.8/dist-packages/MySQLdb/cursors.py", line 206, in execute
    res = self._query(query)
  File "/usr/local/lib/python3.8/dist-packages/MySQLdb/cursors.py", line 319, in _query
    db.query(q)
  File "/usr/local/lib/python3.8/dist-packages/MySQLdb/connections.py", line 254, in query
    _mysql.connection.query(self, query)
MySQLdb.ProgrammingError: (1146, "Table 'blog_django.lifelog' doesn't exist")

The above exception was the direct cause of the following exception:

Traceback (most recent call last):
  File "/usr/local/lib/python3.8/dist-packages/django/core/handlers/exception.py", line 47, in inner
    response = get_response(request)
  File "/usr/local/lib/python3.8/dist-packages/django/core/handlers/base.py", line 181, in _get_response
    response = wrapped_callback(request, *callback_args, **callback_kwargs)
  File "/www/django_www/app01/views.py", line 57, in lifelog_log
    if form.is_valid():
  File "/usr/local/lib/python3.8/dist-packages/django/forms/forms.py", line 175, in is_valid
    return self.is_bound and not self.errors
  File "/usr/local/lib/python3.8/dist-packages/django/forms/forms.py", line 170, in errors
    self.full_clean()
  File "/usr/local/lib/python3.8/dist-packages/django/forms/forms.py", line 374, in full_clean
    self._post_clean()
  File "/usr/local/lib/python3.8/dist-packages/django/forms/models.py", line 419, in _post_clean
    self.validate_unique()
  File "/usr/local/lib/python3.8/dist-packages/django/forms/models.py", line 428, in validate_unique
    self.instance.validate_unique(exclude=exclude)
  File "/usr/local/lib/python3.8/dist-packages/django/db/models/base.py", line 1016, in validate_unique
    errors = self._perform_unique_checks(unique_checks)
  File "/usr/local/lib/python3.8/dist-packages/django/db/models/base.py", line 1119, in _perform_unique_checks
    if qs.exists():
  File "/usr/local/lib/python3.8/dist-packages/django/db/models/query.py", line 808, in exists
    return self.query.has_results(using=self.db)
  File "/usr/local/lib/python3.8/dist-packages/django/db/models/sql/query.py", line 559, in has_results
    return compiler.has_results()
  File "/usr/local/lib/python3.8/dist-packages/django/db/models/sql/compiler.py", line 1139, in has_results
    return bool(self.execute_sql(SINGLE))
  File "/usr/local/lib/python3.8/dist-packages/django/db/models/sql/compiler.py", line 1169, in execute_sql
    cursor.execute(sql, params)
  File "/usr/local/lib/python3.8/dist-packages/django/db/backends/utils.py", line 98, in execute
    return super().execute(sql, params)
  File "/usr/local/lib/python3.8/dist-packages/django/db/backends/utils.py", line 66, in execute
    return self._execute_with_wrappers(sql, params, many=False, executor=self._execute)
  File "/usr/local/lib/python3.8/dist-packages/django/db/backends/utils.py", line 75, in _execute_with_wrappers
    return executor(sql, params, many, context)
  File "/usr/local/lib/python3.8/dist-packages/django/db/backends/utils.py", line 84, in _execute
    return self.cursor.execute(sql, params)
  File "/usr/local/lib/python3.8/dist-packages/django/db/utils.py", line 90, in __exit__
    raise dj_exc_value.with_traceback(traceback) from exc_value
  File "/usr/local/lib/python3.8/dist-packages/django/db/backends/utils.py", line 84, in _execute
    return self.cursor.execute(sql, params)
  File "/usr/local/lib/python3.8/dist-packages/django/db/backends/mysql/base.py", line 73, in execute
    return self.cursor.execute(query, args)
  File "/usr/local/lib/python3.8/dist-packages/MySQLdb/cursors.py", line 206, in execute
    res = self._query(query)
  File "/usr/local/lib/python3.8/dist-packages/MySQLdb/cursors.py", line 319, in _query
    db.query(q)
  File "/usr/local/lib/python3.8/dist-packages/MySQLdb/connections.py", line 254, in query
    _mysql.connection.query(self, query)
django.db.utils.ProgrammingError: (1146, "Table 'blog_django.lifelog' doesn't exist")
[01/Feb/2023 11:47:08] "POST /lifelog/log/ HTTP/1.1" 500 170203
Internal Server Error: /lifelog/log/
Traceback (most recent call last):
  File "/usr/local/lib/python3.8/dist-packages/django/db/backends/utils.py", line 84, in _execute
    return self.cursor.execute(sql, params)
  File "/usr/local/lib/python3.8/dist-packages/django/db/backends/mysql/base.py", line 73, in execute
    return self.cursor.execute(query, args)
  File "/usr/local/lib/python3.8/dist-packages/MySQLdb/cursors.py", line 206, in execute
    res = self._query(query)
  File "/usr/local/lib/python3.8/dist-packages/MySQLdb/cursors.py", line 319, in _query
    db.query(q)
  File "/usr/local/lib/python3.8/dist-packages/MySQLdb/connections.py", line 254, in query
    _mysql.connection.query(self, query)
MySQLdb.ProgrammingError: (1146, "Table 'blog_django.lifelog' doesn't exist")

The above exception was the direct cause of the following exception:

Traceback (most recent call last):
  File "/usr/local/lib/python3.8/dist-packages/django/core/handlers/exception.py", line 47, in inner
    response = get_response(request)
  File "/usr/local/lib/python3.8/dist-packages/django/core/handlers/base.py", line 181, in _get_response
    response = wrapped_callback(request, *callback_args, **callback_kwargs)
  File "/www/django_www/app01/views.py", line 57, in lifelog_log
    if form.is_valid():
  File "/usr/local/lib/python3.8/dist-packages/django/forms/forms.py", line 175, in is_valid
    return self.is_bound and not self.errors
  File "/usr/local/lib/python3.8/dist-packages/django/forms/forms.py", line 170, in errors
    self.full_clean()
  File "/usr/local/lib/python3.8/dist-packages/django/forms/forms.py", line 374, in full_clean
    self._post_clean()
  File "/usr/local/lib/python3.8/dist-packages/django/forms/models.py", line 419, in _post_clean
    self.validate_unique()
  File "/usr/local/lib/python3.8/dist-packages/django/forms/models.py", line 428, in validate_unique
    self.instance.validate_unique(exclude=exclude)
  File "/usr/local/lib/python3.8/dist-packages/django/db/models/base.py", line 1016, in validate_unique
    errors = self._perform_unique_checks(unique_checks)
  File "/usr/local/lib/python3.8/dist-packages/django/db/models/base.py", line 1119, in _perform_unique_checks
    if qs.exists():
  File "/usr/local/lib/python3.8/dist-packages/django/db/models/query.py", line 808, in exists
    return self.query.has_results(using=self.db)
  File "/usr/local/lib/python3.8/dist-packages/django/db/models/sql/query.py", line 559, in has_results
    return compiler.has_results()
  File "/usr/local/lib/python3.8/dist-packages/django/db/models/sql/compiler.py", line 1139, in has_results
    return bool(self.execute_sql(SINGLE))
  File "/usr/local/lib/python3.8/dist-packages/django/db/models/sql/compiler.py", line 1169, in execute_sql
    cursor.execute(sql, params)
  File "/usr/local/lib/python3.8/dist-packages/django/db/backends/utils.py", line 98, in execute
    return super().execute(sql, params)
  File "/usr/local/lib/python3.8/dist-packages/django/db/backends/utils.py", line 66, in execute
    return self._execute_with_wrappers(sql, params, many=False, executor=self._execute)
  File "/usr/local/lib/python3.8/dist-packages/django/db/backends/utils.py", line 75, in _execute_with_wrappers
    return executor(sql, params, many, context)
  File "/usr/local/lib/python3.8/dist-packages/django/db/backends/utils.py", line 84, in _execute
    return self.cursor.execute(sql, params)
  File "/usr/local/lib/python3.8/dist-packages/django/db/utils.py", line 90, in __exit__
    raise dj_exc_value.with_traceback(traceback) from exc_value
  File "/usr/local/lib/python3.8/dist-packages/django/db/backends/utils.py", line 84, in _execute
    return self.cursor.execute(sql, params)
  File "/usr/local/lib/python3.8/dist-packages/django/db/backends/mysql/base.py", line 73, in execute
    return self.cursor.execute(query, args)
  File "/usr/local/lib/python3.8/dist-packages/MySQLdb/cursors.py", line 206, in execute
    res = self._query(query)
  File "/usr/local/lib/python3.8/dist-packages/MySQLdb/cursors.py", line 319, in _query
    db.query(q)
  File "/usr/local/lib/python3.8/dist-packages/MySQLdb/connections.py", line 254, in query
    _mysql.connection.query(self, query)
django.db.utils.ProgrammingError: (1146, "Table 'blog_django.lifelog' doesn't exist")
[01/Feb/2023 11:47:49] "POST /lifelog/log/ HTTP/1.1" 500 170203
[01/Feb/2023 11:47:51] "GET /lifelog/log/ HTTP/1.1" 200 4127
Internal Server Error: /lifelog/log/
Traceback (most recent call last):
  File "/usr/local/lib/python3.8/dist-packages/django/db/backends/utils.py", line 84, in _execute
    return self.cursor.execute(sql, params)
  File "/usr/local/lib/python3.8/dist-packages/django/db/backends/mysql/base.py", line 73, in execute
    return self.cursor.execute(query, args)
  File "/usr/local/lib/python3.8/dist-packages/MySQLdb/cursors.py", line 206, in execute
    res = self._query(query)
  File "/usr/local/lib/python3.8/dist-packages/MySQLdb/cursors.py", line 319, in _query
    db.query(q)
  File "/usr/local/lib/python3.8/dist-packages/MySQLdb/connections.py", line 254, in query
    _mysql.connection.query(self, query)
MySQLdb.ProgrammingError: (1146, "Table 'blog_django.lifelog' doesn't exist")

The above exception was the direct cause of the following exception:

Traceback (most recent call last):
  File "/usr/local/lib/python3.8/dist-packages/django/core/handlers/exception.py", line 47, in inner
    response = get_response(request)
  File "/usr/local/lib/python3.8/dist-packages/django/core/handlers/base.py", line 181, in _get_response
    response = wrapped_callback(request, *callback_args, **callback_kwargs)
  File "/www/django_www/app01/views.py", line 57, in lifelog_log
    if form.is_valid():
  File "/usr/local/lib/python3.8/dist-packages/django/forms/forms.py", line 175, in is_valid
    return self.is_bound and not self.errors
  File "/usr/local/lib/python3.8/dist-packages/django/forms/forms.py", line 170, in errors
    self.full_clean()
  File "/usr/local/lib/python3.8/dist-packages/django/forms/forms.py", line 374, in full_clean
    self._post_clean()
  File "/usr/local/lib/python3.8/dist-packages/django/forms/models.py", line 419, in _post_clean
    self.validate_unique()
  File "/usr/local/lib/python3.8/dist-packages/django/forms/models.py", line 428, in validate_unique
    self.instance.validate_unique(exclude=exclude)
  File "/usr/local/lib/python3.8/dist-packages/django/db/models/base.py", line 1016, in validate_unique
    errors = self._perform_unique_checks(unique_checks)
  File "/usr/local/lib/python3.8/dist-packages/django/db/models/base.py", line 1119, in _perform_unique_checks
    if qs.exists():
  File "/usr/local/lib/python3.8/dist-packages/django/db/models/query.py", line 808, in exists
    return self.query.has_results(using=self.db)
  File "/usr/local/lib/python3.8/dist-packages/django/db/models/sql/query.py", line 559, in has_results
    return compiler.has_results()
  File "/usr/local/lib/python3.8/dist-packages/django/db/models/sql/compiler.py", line 1139, in has_results
    return bool(self.execute_sql(SINGLE))
  File "/usr/local/lib/python3.8/dist-packages/django/db/models/sql/compiler.py", line 1169, in execute_sql
    cursor.execute(sql, params)
  File "/usr/local/lib/python3.8/dist-packages/django/db/backends/utils.py", line 98, in execute
    return super().execute(sql, params)
  File "/usr/local/lib/python3.8/dist-packages/django/db/backends/utils.py", line 66, in execute
    return self._execute_with_wrappers(sql, params, many=False, executor=self._execute)
  File "/usr/local/lib/python3.8/dist-packages/django/db/backends/utils.py", line 75, in _execute_with_wrappers
    return executor(sql, params, many, context)
  File "/usr/local/lib/python3.8/dist-packages/django/db/backends/utils.py", line 84, in _execute
    return self.cursor.execute(sql, params)
  File "/usr/local/lib/python3.8/dist-packages/django/db/utils.py", line 90, in __exit__
    raise dj_exc_value.with_traceback(traceback) from exc_value
  File "/usr/local/lib/python3.8/dist-packages/django/db/backends/utils.py", line 84, in _execute
    return self.cursor.execute(sql, params)
  File "/usr/local/lib/python3.8/dist-packages/django/db/backends/mysql/base.py", line 73, in execute
    return self.cursor.execute(query, args)
  File "/usr/local/lib/python3.8/dist-packages/MySQLdb/cursors.py", line 206, in execute
    res = self._query(query)
  File "/usr/local/lib/python3.8/dist-packages/MySQLdb/cursors.py", line 319, in _query
    db.query(q)
  File "/usr/local/lib/python3.8/dist-packages/MySQLdb/connections.py", line 254, in query
    _mysql.connection.query(self, query)
django.db.utils.ProgrammingError: (1146, "Table 'blog_django.lifelog' doesn't exist")
[01/Feb/2023 11:47:58] "POST /lifelog/log/ HTTP/1.1" 500 170222
[01/Feb/2023 11:51:48] "GET /lifelog/log/ HTTP/1.1" 200 4127
Internal Server Error: /lifelog/log/
Traceback (most recent call last):
  File "/usr/local/lib/python3.8/dist-packages/django/db/backends/utils.py", line 84, in _execute
    return self.cursor.execute(sql, params)
  File "/usr/local/lib/python3.8/dist-packages/django/db/backends/mysql/base.py", line 73, in execute
    return self.cursor.execute(query, args)
  File "/usr/local/lib/python3.8/dist-packages/MySQLdb/cursors.py", line 206, in execute
    res = self._query(query)
  File "/usr/local/lib/python3.8/dist-packages/MySQLdb/cursors.py", line 319, in _query
    db.query(q)
  File "/usr/local/lib/python3.8/dist-packages/MySQLdb/connections.py", line 254, in query
    _mysql.connection.query(self, query)
MySQLdb.ProgrammingError: (1146, "Table 'blog_django.lifelog' doesn't exist")

The above exception was the direct cause of the following exception:

Traceback (most recent call last):
  File "/usr/local/lib/python3.8/dist-packages/django/core/handlers/exception.py", line 47, in inner
    response = get_response(request)
  File "/usr/local/lib/python3.8/dist-packages/django/core/handlers/base.py", line 181, in _get_response
    response = wrapped_callback(request, *callback_args, **callback_kwargs)
  File "/www/django_www/app01/views.py", line 57, in lifelog_log
    if form.is_valid():
  File "/usr/local/lib/python3.8/dist-packages/django/forms/forms.py", line 175, in is_valid
    return self.is_bound and not self.errors
  File "/usr/local/lib/python3.8/dist-packages/django/forms/forms.py", line 170, in errors
    self.full_clean()
  File "/usr/local/lib/python3.8/dist-packages/django/forms/forms.py", line 374, in full_clean
    self._post_clean()
  File "/usr/local/lib/python3.8/dist-packages/django/forms/models.py", line 419, in _post_clean
    self.validate_unique()
  File "/usr/local/lib/python3.8/dist-packages/django/forms/models.py", line 428, in validate_unique
    self.instance.validate_unique(exclude=exclude)
  File "/usr/local/lib/python3.8/dist-packages/django/db/models/base.py", line 1016, in validate_unique
    errors = self._perform_unique_checks(unique_checks)
  File "/usr/local/lib/python3.8/dist-packages/django/db/models/base.py", line 1119, in _perform_unique_checks
    if qs.exists():
  File "/usr/local/lib/python3.8/dist-packages/django/db/models/query.py", line 808, in exists
    return self.query.has_results(using=self.db)
  File "/usr/local/lib/python3.8/dist-packages/django/db/models/sql/query.py", line 559, in has_results
    return compiler.has_results()
  File "/usr/local/lib/python3.8/dist-packages/django/db/models/sql/compiler.py", line 1139, in has_results
    return bool(self.execute_sql(SINGLE))
  File "/usr/local/lib/python3.8/dist-packages/django/db/models/sql/compiler.py", line 1169, in execute_sql
    cursor.execute(sql, params)
  File "/usr/local/lib/python3.8/dist-packages/django/db/backends/utils.py", line 98, in execute
    return super().execute(sql, params)
  File "/usr/local/lib/python3.8/dist-packages/django/db/backends/utils.py", line 66, in execute
    return self._execute_with_wrappers(sql, params, many=False, executor=self._execute)
  File "/usr/local/lib/python3.8/dist-packages/django/db/backends/utils.py", line 75, in _execute_with_wrappers
    return executor(sql, params, many, context)
  File "/usr/local/lib/python3.8/dist-packages/django/db/backends/utils.py", line 84, in _execute
    return self.cursor.execute(sql, params)
  File "/usr/local/lib/python3.8/dist-packages/django/db/utils.py", line 90, in __exit__
    raise dj_exc_value.with_traceback(traceback) from exc_value
  File "/usr/local/lib/python3.8/dist-packages/django/db/backends/utils.py", line 84, in _execute
    return self.cursor.execute(sql, params)
  File "/usr/local/lib/python3.8/dist-packages/django/db/backends/mysql/base.py", line 73, in execute
    return self.cursor.execute(query, args)
  File "/usr/local/lib/python3.8/dist-packages/MySQLdb/cursors.py", line 206, in execute
    res = self._query(query)
  File "/usr/local/lib/python3.8/dist-packages/MySQLdb/cursors.py", line 319, in _query
    db.query(q)
  File "/usr/local/lib/python3.8/dist-packages/MySQLdb/connections.py", line 254, in query
    _mysql.connection.query(self, query)
django.db.utils.ProgrammingError: (1146, "Table 'blog_django.lifelog' doesn't exist")
[01/Feb/2023 11:52:04] "POST /lifelog/log/ HTTP/1.1" 500 170245
[01/Feb/2023 11:53:15] "GET /lifelog/ HTTP/1.1" 200 36798
/www/django_www/app01/views.py changed, reloading.
Performing system checks...

System check identified no issues (0 silenced).
February 01, 2023 - 11:47:01
Django version 3.2, using settings 'django_www.settings'
Starting development server at http://0.0.0.0:80/
Quit the server with CONTROL-C.
Watching for file changes with StatReloader
/www/django_www/app01/views.py changed, reloading.
Performing system checks...

System check identified no issues (0 silenced).
February 01, 2023 - 17:21:50
Django version 3.2, using settings 'django_www.settings'
Starting development server at http://0.0.0.0:80/
Quit the server with CONTROL-C.
Watching for file changes with StatReloader
Exception in thread django-main-thread:
Traceback (most recent call last):
  File "/usr/lib/python3.8/threading.py", line 932, in _bootstrap_inner
    self.run()
  File "/usr/lib/python3.8/threading.py", line 870, in run
    self._target(*self._args, **self._kwargs)
  File "/usr/local/lib/python3.8/dist-packages/django/utils/autoreload.py", line 64, in wrapper
    fn(*args, **kwargs)
  File "/usr/local/lib/python3.8/dist-packages/django/core/management/commands/runserver.py", line 118, in inner_run
    self.check(display_num_errors=True)
  File "/usr/local/lib/python3.8/dist-packages/django/core/management/base.py", line 419, in check
    all_issues = checks.run_checks(
  File "/usr/local/lib/python3.8/dist-packages/django/core/checks/registry.py", line 76, in run_checks
    new_errors = check(app_configs=app_configs, databases=databases)
  File "/usr/local/lib/python3.8/dist-packages/django/core/checks/urls.py", line 13, in check_url_config
    return check_resolver(resolver)
  File "/usr/local/lib/python3.8/dist-packages/django/core/checks/urls.py", line 23, in check_resolver
    return check_method()
  File "/usr/local/lib/python3.8/dist-packages/django/urls/resolvers.py", line 412, in check
    for pattern in self.url_patterns:
  File "/usr/local/lib/python3.8/dist-packages/django/utils/functional.py", line 48, in __get__
    res = instance.__dict__[self.name] = self.func(instance)
  File "/usr/local/lib/python3.8/dist-packages/django/urls/resolvers.py", line 598, in url_patterns
    patterns = getattr(self.urlconf_module, "urlpatterns", self.urlconf_module)
  File "/usr/local/lib/python3.8/dist-packages/django/utils/functional.py", line 48, in __get__
    res = instance.__dict__[self.name] = self.func(instance)
  File "/usr/local/lib/python3.8/dist-packages/django/urls/resolvers.py", line 591, in urlconf_module
    return import_module(self.urlconf_name)
  File "/usr/lib/python3.8/importlib/__init__.py", line 127, in import_module
    return _bootstrap._gcd_import(name[level:], package, level)
  File "<frozen importlib._bootstrap>", line 1014, in _gcd_import
  File "<frozen importlib._bootstrap>", line 991, in _find_and_load
  File "<frozen importlib._bootstrap>", line 975, in _find_and_load_unlocked
  File "<frozen importlib._bootstrap>", line 671, in _load_unlocked
  File "<frozen importlib._bootstrap_external>", line 848, in exec_module
  File "<frozen importlib._bootstrap>", line 219, in _call_with_frames_removed
  File "/www/django_www/django_www/urls.py", line 3, in <module>
    from app01 import views
  File "/www/django_www/app01/views.py", line 34, in <module>
    class LogModeForm(forms.ModelForm):
  File "/www/django_www/app01/views.py", line 35, in LogModeForm
    class Meta:
  File "/www/django_www/app01/views.py", line 36, in Meta
    model = models.app01_lifelog # 获取表 
AttributeError: module 'app01.models' has no attribute 'app01_lifelog'
/www/django_www/app01/views.py changed, reloading.
Performing system checks...

Watching for file changes with StatReloader
Exception in thread django-main-thread:
Traceback (most recent call last):
  File "/usr/lib/python3.8/threading.py", line 932, in _bootstrap_inner
    self.run()
  File "/usr/lib/python3.8/threading.py", line 870, in run
    self._target(*self._args, **self._kwargs)
  File "/usr/local/lib/python3.8/dist-packages/django/utils/autoreload.py", line 64, in wrapper
    fn(*args, **kwargs)
  File "/usr/local/lib/python3.8/dist-packages/django/core/management/commands/runserver.py", line 118, in inner_run
    self.check(display_num_errors=True)
  File "/usr/local/lib/python3.8/dist-packages/django/core/management/base.py", line 419, in check
    all_issues = checks.run_checks(
  File "/usr/local/lib/python3.8/dist-packages/django/core/checks/registry.py", line 76, in run_checks
    new_errors = check(app_configs=app_configs, databases=databases)
  File "/usr/local/lib/python3.8/dist-packages/django/core/checks/urls.py", line 13, in check_url_config
    return check_resolver(resolver)
  File "/usr/local/lib/python3.8/dist-packages/django/core/checks/urls.py", line 23, in check_resolver
    return check_method()
  File "/usr/local/lib/python3.8/dist-packages/django/urls/resolvers.py", line 412, in check
    for pattern in self.url_patterns:
  File "/usr/local/lib/python3.8/dist-packages/django/utils/functional.py", line 48, in __get__
    res = instance.__dict__[self.name] = self.func(instance)
  File "/usr/local/lib/python3.8/dist-packages/django/urls/resolvers.py", line 598, in url_patterns
    patterns = getattr(self.urlconf_module, "urlpatterns", self.urlconf_module)
  File "/usr/local/lib/python3.8/dist-packages/django/utils/functional.py", line 48, in __get__
    res = instance.__dict__[self.name] = self.func(instance)
  File "/usr/local/lib/python3.8/dist-packages/django/urls/resolvers.py", line 591, in urlconf_module
    return import_module(self.urlconf_name)
  File "/usr/lib/python3.8/importlib/__init__.py", line 127, in import_module
    return _bootstrap._gcd_import(name[level:], package, level)
  File "<frozen importlib._bootstrap>", line 1014, in _gcd_import
  File "<frozen importlib._bootstrap>", line 991, in _find_and_load
  File "<frozen importlib._bootstrap>", line 975, in _find_and_load_unlocked
  File "<frozen importlib._bootstrap>", line 671, in _load_unlocked
  File "<frozen importlib._bootstrap_external>", line 848, in exec_module
  File "<frozen importlib._bootstrap>", line 219, in _call_with_frames_removed
  File "/www/django_www/django_www/urls.py", line 3, in <module>
    from app01 import views
  File "/www/django_www/app01/views.py", line 34, in <module>
    class LogModeForm(forms.ModelForm):
  File "/www/django_www/app01/views.py", line 35, in LogModeForm
    class Meta:
  File "/www/django_www/app01/views.py", line 36, in Meta
    model = app01_lifelog # 获取表 
NameError: name 'app01_lifelog' is not defined
/www/django_www/app01/views.py changed, reloading.
Performing system checks...

Watching for file changes with StatReloader
/www/django_www/app01/views.py changed, reloading.
Performing system checks...

System check identified no issues (0 silenced).
February 01, 2023 - 17:45:49
Django version 3.2, using settings 'django_www.settings'
Starting development server at http://0.0.0.0:80/
Quit the server with CONTROL-C.
Watching for file changes with StatReloader
[01/Feb/2023 17:46:02] "GET /lifelog/ HTTP/1.1" 200 36798
[01/Feb/2023 17:46:11] "GET /lifelog/log/ HTTP/1.1" 200 4139
[01/Feb/2023 17:46:23] "POST /lifelog/log/ HTTP/1.1" 200 4
[01/Feb/2023 17:46:27] "GET /lifelog/log/ HTTP/1.1" 200 4139
[01/Feb/2023 17:46:29] "GET /lifelog/ HTTP/1.1" 200 36798
/www/django_www/app01/views.py changed, reloading.
Performing system checks...

System check identified no issues (0 silenced).
February 01, 2023 - 17:45:52
Django version 3.2, using settings 'django_www.settings'
Starting development server at http://0.0.0.0:80/
Quit the server with CONTROL-C.
Watching for file changes with StatReloader
[01/Feb/2023 17:46:59] "GET /lifelog/log/ HTTP/1.1" 200 4139
Internal Server Error: /lifelog/log/
Traceback (most recent call last):
  File "/usr/local/lib/python3.8/dist-packages/django/db/backends/utils.py", line 84, in _execute
    return self.cursor.execute(sql, params)
  File "/usr/local/lib/python3.8/dist-packages/django/db/backends/mysql/base.py", line 73, in execute
    return self.cursor.execute(query, args)
  File "/usr/local/lib/python3.8/dist-packages/MySQLdb/cursors.py", line 206, in execute
    res = self._query(query)
  File "/usr/local/lib/python3.8/dist-packages/MySQLdb/cursors.py", line 319, in _query
    db.query(q)
  File "/usr/local/lib/python3.8/dist-packages/MySQLdb/connections.py", line 254, in query
    _mysql.connection.query(self, query)
MySQLdb.OperationalError: (1054, "Unknown column 'app01_lifelog.id' in 'where clause'")

The above exception was the direct cause of the following exception:

Traceback (most recent call last):
  File "/usr/local/lib/python3.8/dist-packages/django/core/handlers/exception.py", line 47, in inner
    response = get_response(request)
  File "/usr/local/lib/python3.8/dist-packages/django/core/handlers/base.py", line 181, in _get_response
    response = wrapped_callback(request, *callback_args, **callback_kwargs)
  File "/www/django_www/app01/views.py", line 61, in lifelog_log
    form.save().using('second_db')
  File "/usr/local/lib/python3.8/dist-packages/django/forms/models.py", line 468, in save
    self.instance.save()
  File "/usr/local/lib/python3.8/dist-packages/django/db/models/base.py", line 726, in save
    self.save_base(using=using, force_insert=force_insert,
  File "/usr/local/lib/python3.8/dist-packages/django/db/models/base.py", line 763, in save_base
    updated = self._save_table(
  File "/usr/local/lib/python3.8/dist-packages/django/db/models/base.py", line 845, in _save_table
    updated = self._do_update(base_qs, using, pk_val, values, update_fields,
  File "/usr/local/lib/python3.8/dist-packages/django/db/models/base.py", line 899, in _do_update
    return filtered._update(values) > 0
  File "/usr/local/lib/python3.8/dist-packages/django/db/models/query.py", line 802, in _update
    return query.get_compiler(self.db).execute_sql(CURSOR)
  File "/usr/local/lib/python3.8/dist-packages/django/db/models/sql/compiler.py", line 1535, in execute_sql
    cursor = super().execute_sql(result_type)
  File "/usr/local/lib/python3.8/dist-packages/django/db/models/sql/compiler.py", line 1169, in execute_sql
    cursor.execute(sql, params)
  File "/usr/local/lib/python3.8/dist-packages/django/db/backends/utils.py", line 98, in execute
    return super().execute(sql, params)
  File "/usr/local/lib/python3.8/dist-packages/django/db/backends/utils.py", line 66, in execute
    return self._execute_with_wrappers(sql, params, many=False, executor=self._execute)
  File "/usr/local/lib/python3.8/dist-packages/django/db/backends/utils.py", line 75, in _execute_with_wrappers
    return executor(sql, params, many, context)
  File "/usr/local/lib/python3.8/dist-packages/django/db/backends/utils.py", line 84, in _execute
    return self.cursor.execute(sql, params)
  File "/usr/local/lib/python3.8/dist-packages/django/db/utils.py", line 90, in __exit__
    raise dj_exc_value.with_traceback(traceback) from exc_value
  File "/usr/local/lib/python3.8/dist-packages/django/db/backends/utils.py", line 84, in _execute
    return self.cursor.execute(sql, params)
  File "/usr/local/lib/python3.8/dist-packages/django/db/backends/mysql/base.py", line 73, in execute
    return self.cursor.execute(query, args)
  File "/usr/local/lib/python3.8/dist-packages/MySQLdb/cursors.py", line 206, in execute
    res = self._query(query)
  File "/usr/local/lib/python3.8/dist-packages/MySQLdb/cursors.py", line 319, in _query
    db.query(q)
  File "/usr/local/lib/python3.8/dist-packages/MySQLdb/connections.py", line 254, in query
    _mysql.connection.query(self, query)
django.db.utils.OperationalError: (1054, "Unknown column 'app01_lifelog.id' in 'where clause'")
[01/Feb/2023 17:47:05] "POST /lifelog/log/ HTTP/1.1" 500 168293
/www/django_www/app01/models.py changed, reloading.
Performing system checks...

System check identified no issues (0 silenced).
February 01, 2023 - 17:46:58
Django version 3.2, using settings 'django_www.settings'
Starting development server at http://0.0.0.0:80/
Quit the server with CONTROL-C.
Watching for file changes with StatReloader
[01/Feb/2023 17:47:51] "POST /lifelog/log/ HTTP/1.1" 200 9
[01/Feb/2023 17:47:53] "GET /lifelog/log/ HTTP/1.1" 200 4139
[01/Feb/2023 17:47:55] "POST /lifelog/log/ HTTP/1.1" 200 9
[01/Feb/2023 17:48:01] "GET /lifelog/log/ HTTP/1.1" 200 4139
[01/Feb/2023 17:48:13] "POST /lifelog/log/ HTTP/1.1" 200 9
[01/Feb/2023 17:48:15] "GET /lifelog/log/ HTTP/1.1" 200 4139
Internal Server Error: /lifelog/log/
Traceback (most recent call last):
  File "/usr/local/lib/python3.8/dist-packages/django/core/handlers/exception.py", line 47, in inner
    response = get_response(request)
  File "/usr/local/lib/python3.8/dist-packages/django/core/handlers/base.py", line 181, in _get_response
    response = wrapped_callback(request, *callback_args, **callback_kwargs)
  File "/www/django_www/app01/views.py", line 61, in lifelog_log
    form.save().using('second_db')
AttributeError: 'App01Lifelog' object has no attribute 'using'
[01/Feb/2023 17:49:08] "POST /lifelog/log/ HTTP/1.1" 500 57656
/www/django_www/app01/views.py changed, reloading.
Performing system checks...

System check identified no issues (0 silenced).
February 01, 2023 - 17:47:50
Django version 3.2, using settings 'django_www.settings'
Starting development server at http://0.0.0.0:80/
Quit the server with CONTROL-C.
form.errors +++++form.errors的错误+++++
form.errors +++++form.errors的错误+++++
form.errors +++++form.errors的错误+++++
Watching for file changes with StatReloader
[01/Feb/2023 17:49:45] "POST /lifelog/log/ HTTP/1.1" 200 9
[01/Feb/2023 17:49:46] "GET /lifelog/log/ HTTP/1.1" 200 4139
[01/Feb/2023 17:49:47] "POST /lifelog/log/ HTTP/1.1" 200 9
[01/Feb/2023 17:49:48] "GET /lifelog/log/ HTTP/1.1" 200 4139
[01/Feb/2023 17:49:54] "POST /lifelog/log/ HTTP/1.1" 200 9
[01/Feb/2023 17:49:54] "GET /lifelog/log/ HTTP/1.1" 200 4139
[01/Feb/2023 17:50:00] "POST /lifelog/log/ HTTP/1.1" 200 9
[01/Feb/2023 17:50:01] "GET /lifelog/log/ HTTP/1.1" 200 4139
[01/Feb/2023 19:54:05] "POST /lifelog/log/ HTTP/1.1" 200 9
[01/Feb/2023 19:54:06] "GET /lifelog/log/ HTTP/1.1" 200 4139
[01/Feb/2023 19:58:28] "POST /lifelog/log/ HTTP/1.1" 200 9
[01/Feb/2023 19:58:28] "GET /lifelog/log/ HTTP/1.1" 200 4139
[01/Feb/2023 20:09:02] "POST /lifelog/log/ HTTP/1.1" 200 9
[01/Feb/2023 20:09:02] "GET /lifelog/log/ HTTP/1.1" 200 4139
[01/Feb/2023 20:09:07] "POST /lifelog/log/ HTTP/1.1" 200 9
[01/Feb/2023 20:09:08] "GET /lifelog/log/ HTTP/1.1" 200 4139
[01/Feb/2023 20:09:20] "POST /lifelog/log/ HTTP/1.1" 200 9
[01/Feb/2023 20:09:21] "GET /lifelog/log/ HTTP/1.1" 200 4139
/www/django_www/app01/models.py changed, reloading.
Performing system checks...

System check identified no issues (0 silenced).
February 01, 2023 - 17:49:44
Django version 3.2, using settings 'django_www.settings'
Starting development server at http://0.0.0.0:80/
Quit the server with CONTROL-C.
form.errors +++++form.errors的错误+++++
form.errors +++++form.errors的错误+++++
form.errors +++++form.errors的错误+++++
form.errors +++++form.errors的错误+++++
form.errors +++++form.errors的错误+++++
form.errors +++++form.errors的错误+++++
form.errors +++++form.errors的错误+++++
form.errors +++++form.errors的错误+++++
form.errors +++++form.errors的错误+++++
Watching for file changes with StatReloader
[01/Feb/2023 20:10:46] "POST /lifelog/log/ HTTP/1.1" 200 9
[01/Feb/2023 20:10:47] "GET /lifelog/log/ HTTP/1.1" 200 4139
[01/Feb/2023 20:10:48] "GET /lifelog/log/ HTTP/1.1" 200 4139
[01/Feb/2023 20:10:59] "POST /lifelog/log/ HTTP/1.1" 200 9
[01/Feb/2023 20:11:00] "GET /lifelog/log/ HTTP/1.1" 200 4139
/www/django_www/app01/views.py changed, reloading.
Performing system checks...

System check identified no issues (0 silenced).
February 01, 2023 - 20:10:46
Django version 3.2, using settings 'django_www.settings'
Starting development server at http://0.0.0.0:80/
Quit the server with CONTROL-C.
form.errors +++++form.errors的错误+++++
form.errors +++++form.errors的错误+++++
Watching for file changes with StatReloader
[01/Feb/2023 20:13:29] "POST /lifelog/log/ HTTP/1.1" 200 9
[01/Feb/2023 20:13:31] "GET /lifelog/log/ HTTP/1.1" 200 4139
/www/django_www/app01/views.py changed, reloading.
Performing system checks...

System check identified no issues (0 silenced).
February 01, 2023 - 20:13:25
Django version 3.2, using settings 'django_www.settings'
Starting development server at http://0.0.0.0:80/
Quit the server with CONTROL-C.
form.errors +++++form.errors的错误+++++
Watching for file changes with StatReloader
nohup: ignoring input
Watching for file changes with StatReloader
[02/Feb/2023 10:40:20] "GET /index/ HTTP/1.1" 200 4146
Not Found: /favicon.ico
[02/Feb/2023 10:40:20] "GET /favicon.ico HTTP/1.1" 404 5827
[02/Feb/2023 10:40:23] "GET /lifelog/ HTTP/1.1" 200 36858
[02/Feb/2023 10:40:26] "GET /lifelog/log/ HTTP/1.1" 200 4139
[02/Feb/2023 10:40:33] "POST /lifelog/log/ HTTP/1.1" 200 9
/www/django_www/app01/views.py changed, reloading.
Performing system checks...

System check identified no issues (0 silenced).
February 02, 2023 - 06:10:10
Django version 3.2, using settings 'django_www.settings'
Starting development server at http://0.0.0.0:80/
Quit the server with CONTROL-C.
form.errors +++++form.errors的错误+++++
Watching for file changes with StatReloader
[02/Feb/2023 10:41:17] "POST /lifelog/log/ HTTP/1.1" 200 9
[02/Feb/2023 10:41:18] "GET /lifelog/log/ HTTP/1.1" 200 4139
[02/Feb/2023 10:41:19] "POST /lifelog/log/ HTTP/1.1" 200 9
[02/Feb/2023 10:41:20] "GET /lifelog/log/ HTTP/1.1" 200 4139
/www/django_www/app01/models.py changed, reloading.
Performing system checks...

System check identified no issues (0 silenced).
February 02, 2023 - 10:41:06
Django version 3.2, using settings 'django_www.settings'
Starting development server at http://0.0.0.0:80/
Quit the server with CONTROL-C.
form.errors +++++form.errors的错误+++++
form.errors +++++form.errors的错误+++++
Watching for file changes with StatReloader
[02/Feb/2023 10:49:53] "POST /lifelog/log/ HTTP/1.1" 200 9
[02/Feb/2023 10:49:54] "GET /lifelog/log/ HTTP/1.1" 200 4139
[02/Feb/2023 10:49:54] "POST /lifelog/log/ HTTP/1.1" 200 9
[02/Feb/2023 10:49:55] "GET /lifelog/log/ HTTP/1.1" 200 4139
[02/Feb/2023 10:50:13] "POST /lifelog/log/ HTTP/1.1" 200 9
[02/Feb/2023 10:50:14] "GET /lifelog/log/ HTTP/1.1" 200 4139
/www/django_www/app01/models.py changed, reloading.
Performing system checks...

System check identified no issues (0 silenced).
February 02, 2023 - 10:49:50
Django version 3.2, using settings 'django_www.settings'
Starting development server at http://0.0.0.0:80/
Quit the server with CONTROL-C.
form.errors +++++form.errors的错误+++++
form.errors +++++form.errors的错误+++++
form.errors +++++form.errors的错误+++++
Watching for file changes with StatReloader
[02/Feb/2023 10:58:57] "GET /lifelog/log/ HTTP/1.1" 200 4127
[02/Feb/2023 10:59:07] "POST /lifelog/log/ HTTP/1.1" 200 9
[02/Feb/2023 10:59:07] "GET /lifelog/log/ HTTP/1.1" 200 4127
/www/django_www/app01/views.py changed, reloading.
Performing system checks...

System check identified no issues (0 silenced).
February 02, 2023 - 10:58:56
Django version 3.2, using settings 'django_www.settings'
Starting development server at http://0.0.0.0:80/
Quit the server with CONTROL-C.
form.errors +++++form.errors的错误+++++
Watching for file changes with StatReloader
[02/Feb/2023 11:02:21] "POST /lifelog/log/ HTTP/1.1" 200 9
[02/Feb/2023 11:02:24] "GET /lifelog/log/ HTTP/1.1" 200 4127
[02/Feb/2023 11:02:25] "POST /lifelog/log/ HTTP/1.1" 200 9
[02/Feb/2023 11:02:26] "GET /lifelog/log/ HTTP/1.1" 200 4127
[02/Feb/2023 11:03:41] "POST /lifelog/log/ HTTP/1.1" 200 4
[02/Feb/2023 11:03:42] "GET /lifelog/log/ HTTP/1.1" 200 4127
[02/Feb/2023 11:04:41] "POST /lifelog/log/ HTTP/1.1" 200 9
[02/Feb/2023 11:04:42] "GET /lifelog/log/ HTTP/1.1" 200 4127
[02/Feb/2023 11:04:46] "POST /lifelog/log/ HTTP/1.1" 200 4
[02/Feb/2023 11:04:47] "GET /lifelog/log/ HTTP/1.1" 200 4127
[02/Feb/2023 11:06:44] "GET /lifelog/ HTTP/1.1" 200 36858
[02/Feb/2023 11:06:45] "GET /lifelog/ HTTP/1.1" 200 36858
[02/Feb/2023 11:06:45] "GET /lifelog/ HTTP/1.1" 200 36858
[02/Feb/2023 11:06:48] "GET /lifelog/ HTTP/1.1" 200 36858
/www/django_www/app01/views.py changed, reloading.
Performing system checks...

System check identified no issues (0 silenced).
February 02, 2023 - 11:02:20
Django version 3.2, using settings 'django_www.settings'
Starting development server at http://0.0.0.0:80/
Quit the server with CONTROL-C.
form.errors +++++form.errors的错误+++++
form.errors +++++form.errors的错误+++++
form.errors +++++form.errors的错误+++++
Watching for file changes with StatReloader
Internal Server Error: /lifelog/
Traceback (most recent call last):
  File "/usr/local/lib/python3.8/dist-packages/django/utils/connection.py", line 58, in __getitem__
    return getattr(self._connections, alias)
  File "/usr/local/lib/python3.8/dist-packages/asgiref/local.py", line 105, in __getattr__
    raise AttributeError(f"{self!r} object has no attribute {key!r}")
AttributeError: <asgiref.local.Local object at 0x7fc55794a4f0> object has no attribute 'app01_lifelog'

During handling of the above exception, another exception occurred:

Traceback (most recent call last):
  File "/usr/local/lib/python3.8/dist-packages/django/core/handlers/exception.py", line 47, in inner
    response = get_response(request)
  File "/usr/local/lib/python3.8/dist-packages/django/core/handlers/base.py", line 181, in _get_response
    response = wrapped_callback(request, *callback_args, **callback_kwargs)
  File "/www/django_www/app01/views.py", line 22, in lifelog
    return render(request, 'lifelog.html', {'lifelog':lifelog})
  File "/usr/local/lib/python3.8/dist-packages/django/shortcuts.py", line 19, in render
    content = loader.render_to_string(template_name, context, request, using=using)
  File "/usr/local/lib/python3.8/dist-packages/django/template/loader.py", line 62, in render_to_string
    return template.render(context, request)
  File "/usr/local/lib/python3.8/dist-packages/django/template/backends/django.py", line 61, in render
    return self.template.render(context)
  File "/usr/local/lib/python3.8/dist-packages/django/template/base.py", line 170, in render
    return self._render(context)
  File "/usr/local/lib/python3.8/dist-packages/django/template/base.py", line 162, in _render
    return self.nodelist.render(context)
  File "/usr/local/lib/python3.8/dist-packages/django/template/base.py", line 938, in render
    bit = node.render_annotated(context)
  File "/usr/local/lib/python3.8/dist-packages/django/template/base.py", line 905, in render_annotated
    return self.render(context)
  File "/usr/local/lib/python3.8/dist-packages/django/template/loader_tags.py", line 150, in render
    return compiled_parent._render(context)
  File "/usr/local/lib/python3.8/dist-packages/django/template/base.py", line 162, in _render
    return self.nodelist.render(context)
  File "/usr/local/lib/python3.8/dist-packages/django/template/base.py", line 938, in render
    bit = node.render_annotated(context)
  File "/usr/local/lib/python3.8/dist-packages/django/template/base.py", line 905, in render_annotated
    return self.render(context)
  File "/usr/local/lib/python3.8/dist-packages/django/template/loader_tags.py", line 62, in render
    result = block.nodelist.render(context)
  File "/usr/local/lib/python3.8/dist-packages/django/template/base.py", line 938, in render
    bit = node.render_annotated(context)
  File "/usr/local/lib/python3.8/dist-packages/django/template/base.py", line 905, in render_annotated
    return self.render(context)
  File "/usr/local/lib/python3.8/dist-packages/django/template/defaulttags.py", line 168, in render
    len_values = len(values)
  File "/usr/local/lib/python3.8/dist-packages/django/db/models/query.py", line 262, in __len__
    self._fetch_all()
  File "/usr/local/lib/python3.8/dist-packages/django/db/models/query.py", line 1324, in _fetch_all
    self._result_cache = list(self._iterable_class(self))
  File "/usr/local/lib/python3.8/dist-packages/django/db/models/query.py", line 48, in __iter__
    compiler = queryset.query.get_compiler(using=db)
  File "/usr/local/lib/python3.8/dist-packages/django/db/models/sql/query.py", line 292, in get_compiler
    connection = connections[using]
  File "/usr/local/lib/python3.8/dist-packages/django/utils/connection.py", line 61, in __getitem__
    raise self.exception_class(f"The connection '{alias}' doesn't exist.")
django.utils.connection.ConnectionDoesNotExist: The connection 'app01_lifelog' doesn't exist.
[02/Feb/2023 11:07:58] "GET /lifelog/ HTTP/1.1" 500 155493
/www/django_www/app01/views.py changed, reloading.
Performing system checks...

System check identified no issues (0 silenced).
February 02, 2023 - 11:07:58
Django version 3.2, using settings 'django_www.settings'
Starting development server at http://0.0.0.0:80/
Quit the server with CONTROL-C.
Watching for file changes with StatReloader
Internal Server Error: /lifelog/
Traceback (most recent call last):
  File "/usr/local/lib/python3.8/dist-packages/django/utils/connection.py", line 58, in __getitem__
    return getattr(self._connections, alias)
  File "/usr/local/lib/python3.8/dist-packages/asgiref/local.py", line 105, in __getattr__
    raise AttributeError(f"{self!r} object has no attribute {key!r}")
AttributeError: <asgiref.local.Local object at 0x7fe1ea18f4f0> object has no attribute 'App01Lifelog'

During handling of the above exception, another exception occurred:

Traceback (most recent call last):
  File "/usr/local/lib/python3.8/dist-packages/django/core/handlers/exception.py", line 47, in inner
    response = get_response(request)
  File "/usr/local/lib/python3.8/dist-packages/django/core/handlers/base.py", line 181, in _get_response
    response = wrapped_callback(request, *callback_args, **callback_kwargs)
  File "/www/django_www/app01/views.py", line 22, in lifelog
    return render(request, 'lifelog.html', {'lifelog':lifelog})
  File "/usr/local/lib/python3.8/dist-packages/django/shortcuts.py", line 19, in render
    content = loader.render_to_string(template_name, context, request, using=using)
  File "/usr/local/lib/python3.8/dist-packages/django/template/loader.py", line 62, in render_to_string
    return template.render(context, request)
  File "/usr/local/lib/python3.8/dist-packages/django/template/backends/django.py", line 61, in render
    return self.template.render(context)
  File "/usr/local/lib/python3.8/dist-packages/django/template/base.py", line 170, in render
    return self._render(context)
  File "/usr/local/lib/python3.8/dist-packages/django/template/base.py", line 162, in _render
    return self.nodelist.render(context)
  File "/usr/local/lib/python3.8/dist-packages/django/template/base.py", line 938, in render
    bit = node.render_annotated(context)
  File "/usr/local/lib/python3.8/dist-packages/django/template/base.py", line 905, in render_annotated
    return self.render(context)
  File "/usr/local/lib/python3.8/dist-packages/django/template/loader_tags.py", line 150, in render
    return compiled_parent._render(context)
  File "/usr/local/lib/python3.8/dist-packages/django/template/base.py", line 162, in _render
    return self.nodelist.render(context)
  File "/usr/local/lib/python3.8/dist-packages/django/template/base.py", line 938, in render
    bit = node.render_annotated(context)
  File "/usr/local/lib/python3.8/dist-packages/django/template/base.py", line 905, in render_annotated
    return self.render(context)
  File "/usr/local/lib/python3.8/dist-packages/django/template/loader_tags.py", line 62, in render
    result = block.nodelist.render(context)
  File "/usr/local/lib/python3.8/dist-packages/django/template/base.py", line 938, in render
    bit = node.render_annotated(context)
  File "/usr/local/lib/python3.8/dist-packages/django/template/base.py", line 905, in render_annotated
    return self.render(context)
  File "/usr/local/lib/python3.8/dist-packages/django/template/defaulttags.py", line 168, in render
    len_values = len(values)
  File "/usr/local/lib/python3.8/dist-packages/django/db/models/query.py", line 262, in __len__
    self._fetch_all()
  File "/usr/local/lib/python3.8/dist-packages/django/db/models/query.py", line 1324, in _fetch_all
    self._result_cache = list(self._iterable_class(self))
  File "/usr/local/lib/python3.8/dist-packages/django/db/models/query.py", line 48, in __iter__
    compiler = queryset.query.get_compiler(using=db)
  File "/usr/local/lib/python3.8/dist-packages/django/db/models/sql/query.py", line 292, in get_compiler
    connection = connections[using]
  File "/usr/local/lib/python3.8/dist-packages/django/utils/connection.py", line 61, in __getitem__
    raise self.exception_class(f"The connection '{alias}' doesn't exist.")
django.utils.connection.ConnectionDoesNotExist: The connection 'App01Lifelog' doesn't exist.
[02/Feb/2023 11:08:21] "GET /lifelog/ HTTP/1.1" 500 155459
/www/django_www/app01/views.py changed, reloading.
Performing system checks...

System check identified no issues (0 silenced).
February 02, 2023 - 11:08:20
Django version 3.2, using settings 'django_www.settings'
Starting development server at http://0.0.0.0:80/
Quit the server with CONTROL-C.
Watching for file changes with StatReloader
Internal Server Error: /lifelog/
Traceback (most recent call last):
  File "/usr/local/lib/python3.8/dist-packages/django/utils/connection.py", line 58, in __getitem__
    return getattr(self._connections, alias)
  File "/usr/local/lib/python3.8/dist-packages/asgiref/local.py", line 105, in __getattr__
    raise AttributeError(f"{self!r} object has no attribute {key!r}")
AttributeError: <asgiref.local.Local object at 0x7f7a369134f0> object has no attribute 'app01_lifelog'

During handling of the above exception, another exception occurred:

Traceback (most recent call last):
  File "/usr/local/lib/python3.8/dist-packages/django/core/handlers/exception.py", line 47, in inner
    response = get_response(request)
  File "/usr/local/lib/python3.8/dist-packages/django/core/handlers/base.py", line 181, in _get_response
    response = wrapped_callback(request, *callback_args, **callback_kwargs)
  File "/www/django_www/app01/views.py", line 22, in lifelog
    return render(request, 'lifelog.html', {'lifelog':lifelog})
  File "/usr/local/lib/python3.8/dist-packages/django/shortcuts.py", line 19, in render
    content = loader.render_to_string(template_name, context, request, using=using)
  File "/usr/local/lib/python3.8/dist-packages/django/template/loader.py", line 62, in render_to_string
    return template.render(context, request)
  File "/usr/local/lib/python3.8/dist-packages/django/template/backends/django.py", line 61, in render
    return self.template.render(context)
  File "/usr/local/lib/python3.8/dist-packages/django/template/base.py", line 170, in render
    return self._render(context)
  File "/usr/local/lib/python3.8/dist-packages/django/template/base.py", line 162, in _render
    return self.nodelist.render(context)
  File "/usr/local/lib/python3.8/dist-packages/django/template/base.py", line 938, in render
    bit = node.render_annotated(context)
  File "/usr/local/lib/python3.8/dist-packages/django/template/base.py", line 905, in render_annotated
    return self.render(context)
  File "/usr/local/lib/python3.8/dist-packages/django/template/loader_tags.py", line 150, in render
    return compiled_parent._render(context)
  File "/usr/local/lib/python3.8/dist-packages/django/template/base.py", line 162, in _render
    return self.nodelist.render(context)
  File "/usr/local/lib/python3.8/dist-packages/django/template/base.py", line 938, in render
    bit = node.render_annotated(context)
  File "/usr/local/lib/python3.8/dist-packages/django/template/base.py", line 905, in render_annotated
    return self.render(context)
  File "/usr/local/lib/python3.8/dist-packages/django/template/loader_tags.py", line 62, in render
    result = block.nodelist.render(context)
  File "/usr/local/lib/python3.8/dist-packages/django/template/base.py", line 938, in render
    bit = node.render_annotated(context)
  File "/usr/local/lib/python3.8/dist-packages/django/template/base.py", line 905, in render_annotated
    return self.render(context)
  File "/usr/local/lib/python3.8/dist-packages/django/template/defaulttags.py", line 168, in render
    len_values = len(values)
  File "/usr/local/lib/python3.8/dist-packages/django/db/models/query.py", line 262, in __len__
    self._fetch_all()
  File "/usr/local/lib/python3.8/dist-packages/django/db/models/query.py", line 1324, in _fetch_all
    self._result_cache = list(self._iterable_class(self))
  File "/usr/local/lib/python3.8/dist-packages/django/db/models/query.py", line 48, in __iter__
    compiler = queryset.query.get_compiler(using=db)
  File "/usr/local/lib/python3.8/dist-packages/django/db/models/sql/query.py", line 292, in get_compiler
    connection = connections[using]
  File "/usr/local/lib/python3.8/dist-packages/django/utils/connection.py", line 61, in __getitem__
    raise self.exception_class(f"The connection '{alias}' doesn't exist.")
django.utils.connection.ConnectionDoesNotExist: The connection 'app01_lifelog' doesn't exist.
[02/Feb/2023 11:09:43] "GET /lifelog/ HTTP/1.1" 500 155510
/www/django_www/app01/models.py changed, reloading.
Performing system checks...

System check identified no issues (0 silenced).
February 02, 2023 - 11:09:42
Django version 3.2, using settings 'django_www.settings'
Starting development server at http://0.0.0.0:80/
Quit the server with CONTROL-C.
Watching for file changes with StatReloader
Internal Server Error: /lifelog/
Traceback (most recent call last):
  File "/usr/local/lib/python3.8/dist-packages/django/utils/connection.py", line 58, in __getitem__
    return getattr(self._connections, alias)
  File "/usr/local/lib/python3.8/dist-packages/asgiref/local.py", line 105, in __getattr__
    raise AttributeError(f"{self!r} object has no attribute {key!r}")
AttributeError: <asgiref.local.Local object at 0x7f0a8bddb4f0> object has no attribute 'app01_lifelog'

During handling of the above exception, another exception occurred:

Traceback (most recent call last):
  File "/usr/local/lib/python3.8/dist-packages/django/core/handlers/exception.py", line 47, in inner
    response = get_response(request)
  File "/usr/local/lib/python3.8/dist-packages/django/core/handlers/base.py", line 181, in _get_response
    response = wrapped_callback(request, *callback_args, **callback_kwargs)
  File "/www/django_www/app01/views.py", line 22, in lifelog
    return render(request, 'lifelog.html', {'lifelog':lifelog})
  File "/usr/local/lib/python3.8/dist-packages/django/shortcuts.py", line 19, in render
    content = loader.render_to_string(template_name, context, request, using=using)
  File "/usr/local/lib/python3.8/dist-packages/django/template/loader.py", line 62, in render_to_string
    return template.render(context, request)
  File "/usr/local/lib/python3.8/dist-packages/django/template/backends/django.py", line 61, in render
    return self.template.render(context)
  File "/usr/local/lib/python3.8/dist-packages/django/template/base.py", line 170, in render
    return self._render(context)
  File "/usr/local/lib/python3.8/dist-packages/django/template/base.py", line 162, in _render
    return self.nodelist.render(context)
  File "/usr/local/lib/python3.8/dist-packages/django/template/base.py", line 938, in render
    bit = node.render_annotated(context)
  File "/usr/local/lib/python3.8/dist-packages/django/template/base.py", line 905, in render_annotated
    return self.render(context)
  File "/usr/local/lib/python3.8/dist-packages/django/template/loader_tags.py", line 150, in render
    return compiled_parent._render(context)
  File "/usr/local/lib/python3.8/dist-packages/django/template/base.py", line 162, in _render
    return self.nodelist.render(context)
  File "/usr/local/lib/python3.8/dist-packages/django/template/base.py", line 938, in render
    bit = node.render_annotated(context)
  File "/usr/local/lib/python3.8/dist-packages/django/template/base.py", line 905, in render_annotated
    return self.render(context)
  File "/usr/local/lib/python3.8/dist-packages/django/template/loader_tags.py", line 62, in render
    result = block.nodelist.render(context)
  File "/usr/local/lib/python3.8/dist-packages/django/template/base.py", line 938, in render
    bit = node.render_annotated(context)
  File "/usr/local/lib/python3.8/dist-packages/django/template/base.py", line 905, in render_annotated
    return self.render(context)
  File "/usr/local/lib/python3.8/dist-packages/django/template/defaulttags.py", line 168, in render
    len_values = len(values)
  File "/usr/local/lib/python3.8/dist-packages/django/db/models/query.py", line 262, in __len__
    self._fetch_all()
  File "/usr/local/lib/python3.8/dist-packages/django/db/models/query.py", line 1324, in _fetch_all
    self._result_cache = list(self._iterable_class(self))
  File "/usr/local/lib/python3.8/dist-packages/django/db/models/query.py", line 48, in __iter__
    compiler = queryset.query.get_compiler(using=db)
  File "/usr/local/lib/python3.8/dist-packages/django/db/models/sql/query.py", line 292, in get_compiler
    connection = connections[using]
  File "/usr/local/lib/python3.8/dist-packages/django/utils/connection.py", line 61, in __getitem__
    raise self.exception_class(f"The connection '{alias}' doesn't exist.")
django.utils.connection.ConnectionDoesNotExist: The connection 'app01_lifelog' doesn't exist.
[02/Feb/2023 11:10:56] "GET /lifelog/ HTTP/1.1" 500 155647
/www/django_www/app01/models.py changed, reloading.
Performing system checks...

System check identified no issues (0 silenced).
February 02, 2023 - 11:10:55
Django version 3.2, using settings 'django_www.settings'
Starting development server at http://0.0.0.0:80/
Quit the server with CONTROL-C.
Watching for file changes with StatReloader
Internal Server Error: /lifelog/
Traceback (most recent call last):
  File "/usr/local/lib/python3.8/dist-packages/django/utils/connection.py", line 58, in __getitem__
    return getattr(self._connections, alias)
  File "/usr/local/lib/python3.8/dist-packages/asgiref/local.py", line 105, in __getattr__
    raise AttributeError(f"{self!r} object has no attribute {key!r}")
AttributeError: <asgiref.local.Local object at 0x7fa04bd274f0> object has no attribute 'app01_lifelog'

During handling of the above exception, another exception occurred:

Traceback (most recent call last):
  File "/usr/local/lib/python3.8/dist-packages/django/core/handlers/exception.py", line 47, in inner
    response = get_response(request)
  File "/usr/local/lib/python3.8/dist-packages/django/core/handlers/base.py", line 181, in _get_response
    response = wrapped_callback(request, *callback_args, **callback_kwargs)
  File "/www/django_www/app01/views.py", line 22, in lifelog
    return render(request, 'lifelog.html', {'lifelog':lifelog})
  File "/usr/local/lib/python3.8/dist-packages/django/shortcuts.py", line 19, in render
    content = loader.render_to_string(template_name, context, request, using=using)
  File "/usr/local/lib/python3.8/dist-packages/django/template/loader.py", line 62, in render_to_string
    return template.render(context, request)
  File "/usr/local/lib/python3.8/dist-packages/django/template/backends/django.py", line 61, in render
    return self.template.render(context)
  File "/usr/local/lib/python3.8/dist-packages/django/template/base.py", line 170, in render
    return self._render(context)
  File "/usr/local/lib/python3.8/dist-packages/django/template/base.py", line 162, in _render
    return self.nodelist.render(context)
  File "/usr/local/lib/python3.8/dist-packages/django/template/base.py", line 938, in render
    bit = node.render_annotated(context)
  File "/usr/local/lib/python3.8/dist-packages/django/template/base.py", line 905, in render_annotated
    return self.render(context)
  File "/usr/local/lib/python3.8/dist-packages/django/template/loader_tags.py", line 150, in render
    return compiled_parent._render(context)
  File "/usr/local/lib/python3.8/dist-packages/django/template/base.py", line 162, in _render
    return self.nodelist.render(context)
  File "/usr/local/lib/python3.8/dist-packages/django/template/base.py", line 938, in render
    bit = node.render_annotated(context)
  File "/usr/local/lib/python3.8/dist-packages/django/template/base.py", line 905, in render_annotated
    return self.render(context)
  File "/usr/local/lib/python3.8/dist-packages/django/template/loader_tags.py", line 62, in render
    result = block.nodelist.render(context)
  File "/usr/local/lib/python3.8/dist-packages/django/template/base.py", line 938, in render
    bit = node.render_annotated(context)
  File "/usr/local/lib/python3.8/dist-packages/django/template/base.py", line 905, in render_annotated
    return self.render(context)
  File "/usr/local/lib/python3.8/dist-packages/django/template/defaulttags.py", line 168, in render
    len_values = len(values)
  File "/usr/local/lib/python3.8/dist-packages/django/db/models/query.py", line 262, in __len__
    self._fetch_all()
  File "/usr/local/lib/python3.8/dist-packages/django/db/models/query.py", line 1324, in _fetch_all
    self._result_cache = list(self._iterable_class(self))
  File "/usr/local/lib/python3.8/dist-packages/django/db/models/query.py", line 48, in __iter__
    compiler = queryset.query.get_compiler(using=db)
  File "/usr/local/lib/python3.8/dist-packages/django/db/models/sql/query.py", line 292, in get_compiler
    connection = connections[using]
  File "/usr/local/lib/python3.8/dist-packages/django/utils/connection.py", line 61, in __getitem__
    raise self.exception_class(f"The connection '{alias}' doesn't exist.")
django.utils.connection.ConnectionDoesNotExist: The connection 'app01_lifelog' doesn't exist.
[02/Feb/2023 11:11:25] "GET /lifelog/ HTTP/1.1" 500 155647
Internal Server Error: /lifelog/
Traceback (most recent call last):
  File "/usr/local/lib/python3.8/dist-packages/django/utils/connection.py", line 58, in __getitem__
    return getattr(self._connections, alias)
  File "/usr/local/lib/python3.8/dist-packages/asgiref/local.py", line 105, in __getattr__
    raise AttributeError(f"{self!r} object has no attribute {key!r}")
AttributeError: <asgiref.local.Local object at 0x7fa04bd274f0> object has no attribute 'app01_lifelog'

During handling of the above exception, another exception occurred:

Traceback (most recent call last):
  File "/usr/local/lib/python3.8/dist-packages/django/core/handlers/exception.py", line 47, in inner
    response = get_response(request)
  File "/usr/local/lib/python3.8/dist-packages/django/core/handlers/base.py", line 181, in _get_response
    response = wrapped_callback(request, *callback_args, **callback_kwargs)
  File "/www/django_www/app01/views.py", line 22, in lifelog
    return render(request, 'lifelog.html', {'lifelog':lifelog})
  File "/usr/local/lib/python3.8/dist-packages/django/shortcuts.py", line 19, in render
    content = loader.render_to_string(template_name, context, request, using=using)
  File "/usr/local/lib/python3.8/dist-packages/django/template/loader.py", line 62, in render_to_string
    return template.render(context, request)
  File "/usr/local/lib/python3.8/dist-packages/django/template/backends/django.py", line 61, in render
    return self.template.render(context)
  File "/usr/local/lib/python3.8/dist-packages/django/template/base.py", line 170, in render
    return self._render(context)
  File "/usr/local/lib/python3.8/dist-packages/django/template/base.py", line 162, in _render
    return self.nodelist.render(context)
  File "/usr/local/lib/python3.8/dist-packages/django/template/base.py", line 938, in render
    bit = node.render_annotated(context)
  File "/usr/local/lib/python3.8/dist-packages/django/template/base.py", line 905, in render_annotated
    return self.render(context)
  File "/usr/local/lib/python3.8/dist-packages/django/template/loader_tags.py", line 150, in render
    return compiled_parent._render(context)
  File "/usr/local/lib/python3.8/dist-packages/django/template/base.py", line 162, in _render
    return self.nodelist.render(context)
  File "/usr/local/lib/python3.8/dist-packages/django/template/base.py", line 938, in render
    bit = node.render_annotated(context)
  File "/usr/local/lib/python3.8/dist-packages/django/template/base.py", line 905, in render_annotated
    return self.render(context)
  File "/usr/local/lib/python3.8/dist-packages/django/template/loader_tags.py", line 62, in render
    result = block.nodelist.render(context)
  File "/usr/local/lib/python3.8/dist-packages/django/template/base.py", line 938, in render
    bit = node.render_annotated(context)
  File "/usr/local/lib/python3.8/dist-packages/django/template/base.py", line 905, in render_annotated
    return self.render(context)
  File "/usr/local/lib/python3.8/dist-packages/django/template/defaulttags.py", line 168, in render
    len_values = len(values)
  File "/usr/local/lib/python3.8/dist-packages/django/db/models/query.py", line 262, in __len__
    self._fetch_all()
  File "/usr/local/lib/python3.8/dist-packages/django/db/models/query.py", line 1324, in _fetch_all
    self._result_cache = list(self._iterable_class(self))
  File "/usr/local/lib/python3.8/dist-packages/django/db/models/query.py", line 48, in __iter__
    compiler = queryset.query.get_compiler(using=db)
  File "/usr/local/lib/python3.8/dist-packages/django/db/models/sql/query.py", line 292, in get_compiler
    connection = connections[using]
  File "/usr/local/lib/python3.8/dist-packages/django/utils/connection.py", line 61, in __getitem__
    raise self.exception_class(f"The connection '{alias}' doesn't exist.")
django.utils.connection.ConnectionDoesNotExist: The connection 'app01_lifelog' doesn't exist.
[02/Feb/2023 11:11:28] "GET /lifelog/ HTTP/1.1" 500 155510
/www/django_www/app01/models.py changed, reloading.
Performing system checks...

System check identified no issues (0 silenced).
February 02, 2023 - 11:11:25
Django version 3.2, using settings 'django_www.settings'
Starting development server at http://0.0.0.0:80/
Quit the server with CONTROL-C.
Watching for file changes with StatReloader
Internal Server Error: /lifelog/
Traceback (most recent call last):
  File "/usr/local/lib/python3.8/dist-packages/django/utils/connection.py", line 58, in __getitem__
    return getattr(self._connections, alias)
  File "/usr/local/lib/python3.8/dist-packages/asgiref/local.py", line 105, in __getattr__
    raise AttributeError(f"{self!r} object has no attribute {key!r}")
AttributeError: <asgiref.local.Local object at 0x7f869a0a04f0> object has no attribute 'app01_lifelog'

During handling of the above exception, another exception occurred:

Traceback (most recent call last):
  File "/usr/local/lib/python3.8/dist-packages/django/core/handlers/exception.py", line 47, in inner
    response = get_response(request)
  File "/usr/local/lib/python3.8/dist-packages/django/core/handlers/base.py", line 181, in _get_response
    response = wrapped_callback(request, *callback_args, **callback_kwargs)
  File "/www/django_www/app01/views.py", line 22, in lifelog
    return render(request, 'lifelog.html', {'lifelog':lifelog})
  File "/usr/local/lib/python3.8/dist-packages/django/shortcuts.py", line 19, in render
    content = loader.render_to_string(template_name, context, request, using=using)
  File "/usr/local/lib/python3.8/dist-packages/django/template/loader.py", line 62, in render_to_string
    return template.render(context, request)
  File "/usr/local/lib/python3.8/dist-packages/django/template/backends/django.py", line 61, in render
    return self.template.render(context)
  File "/usr/local/lib/python3.8/dist-packages/django/template/base.py", line 170, in render
    return self._render(context)
  File "/usr/local/lib/python3.8/dist-packages/django/template/base.py", line 162, in _render
    return self.nodelist.render(context)
  File "/usr/local/lib/python3.8/dist-packages/django/template/base.py", line 938, in render
    bit = node.render_annotated(context)
  File "/usr/local/lib/python3.8/dist-packages/django/template/base.py", line 905, in render_annotated
    return self.render(context)
  File "/usr/local/lib/python3.8/dist-packages/django/template/loader_tags.py", line 150, in render
    return compiled_parent._render(context)
  File "/usr/local/lib/python3.8/dist-packages/django/template/base.py", line 162, in _render
    return self.nodelist.render(context)
  File "/usr/local/lib/python3.8/dist-packages/django/template/base.py", line 938, in render
    bit = node.render_annotated(context)
  File "/usr/local/lib/python3.8/dist-packages/django/template/base.py", line 905, in render_annotated
    return self.render(context)
  File "/usr/local/lib/python3.8/dist-packages/django/template/loader_tags.py", line 62, in render
    result = block.nodelist.render(context)
  File "/usr/local/lib/python3.8/dist-packages/django/template/base.py", line 938, in render
    bit = node.render_annotated(context)
  File "/usr/local/lib/python3.8/dist-packages/django/template/base.py", line 905, in render_annotated
    return self.render(context)
  File "/usr/local/lib/python3.8/dist-packages/django/template/defaulttags.py", line 168, in render
    len_values = len(values)
  File "/usr/local/lib/python3.8/dist-packages/django/db/models/query.py", line 262, in __len__
    self._fetch_all()
  File "/usr/local/lib/python3.8/dist-packages/django/db/models/query.py", line 1324, in _fetch_all
    self._result_cache = list(self._iterable_class(self))
  File "/usr/local/lib/python3.8/dist-packages/django/db/models/query.py", line 48, in __iter__
    compiler = queryset.query.get_compiler(using=db)
  File "/usr/local/lib/python3.8/dist-packages/django/db/models/sql/query.py", line 292, in get_compiler
    connection = connections[using]
  File "/usr/local/lib/python3.8/dist-packages/django/utils/connection.py", line 61, in __getitem__
    raise self.exception_class(f"The connection '{alias}' doesn't exist.")
django.utils.connection.ConnectionDoesNotExist: The connection 'app01_lifelog' doesn't exist.
[02/Feb/2023 11:11:33] "GET /lifelog/ HTTP/1.1" 500 155647
/www/django_www/app01/models.py changed, reloading.
Performing system checks...

System check identified no issues (0 silenced).
February 02, 2023 - 11:11:32
Django version 3.2, using settings 'django_www.settings'
Starting development server at http://0.0.0.0:80/
Quit the server with CONTROL-C.
Watching for file changes with StatReloader
/www/django_www/app01/views.py changed, reloading.
Performing system checks...

System check identified no issues (0 silenced).
February 02, 2023 - 11:11:44
Django version 3.2, using settings 'django_www.settings'
Starting development server at http://0.0.0.0:80/
Quit the server with CONTROL-C.
Watching for file changes with StatReloader
Internal Server Error: /lifelog/
Traceback (most recent call last):
  File "/usr/local/lib/python3.8/dist-packages/django/db/backends/utils.py", line 84, in _execute
    return self.cursor.execute(sql, params)
  File "/usr/local/lib/python3.8/dist-packages/django/db/backends/mysql/base.py", line 73, in execute
    return self.cursor.execute(query, args)
  File "/usr/local/lib/python3.8/dist-packages/MySQLdb/cursors.py", line 206, in execute
    res = self._query(query)
  File "/usr/local/lib/python3.8/dist-packages/MySQLdb/cursors.py", line 319, in _query
    db.query(q)
  File "/usr/local/lib/python3.8/dist-packages/MySQLdb/connections.py", line 254, in query
    _mysql.connection.query(self, query)
MySQLdb.ProgrammingError: (1146, "Table 'blog_django.lifelog' doesn't exist")

The above exception was the direct cause of the following exception:

Traceback (most recent call last):
  File "/usr/local/lib/python3.8/dist-packages/django/core/handlers/exception.py", line 47, in inner
    response = get_response(request)
  File "/usr/local/lib/python3.8/dist-packages/django/core/handlers/base.py", line 181, in _get_response
    response = wrapped_callback(request, *callback_args, **callback_kwargs)
  File "/www/django_www/app01/views.py", line 22, in lifelog
    return render(request, 'lifelog.html', {'lifelog':lifelog})
  File "/usr/local/lib/python3.8/dist-packages/django/shortcuts.py", line 19, in render
    content = loader.render_to_string(template_name, context, request, using=using)
  File "/usr/local/lib/python3.8/dist-packages/django/template/loader.py", line 62, in render_to_string
    return template.render(context, request)
  File "/usr/local/lib/python3.8/dist-packages/django/template/backends/django.py", line 61, in render
    return self.template.render(context)
  File "/usr/local/lib/python3.8/dist-packages/django/template/base.py", line 170, in render
    return self._render(context)
  File "/usr/local/lib/python3.8/dist-packages/django/template/base.py", line 162, in _render
    return self.nodelist.render(context)
  File "/usr/local/lib/python3.8/dist-packages/django/template/base.py", line 938, in render
    bit = node.render_annotated(context)
  File "/usr/local/lib/python3.8/dist-packages/django/template/base.py", line 905, in render_annotated
    return self.render(context)
  File "/usr/local/lib/python3.8/dist-packages/django/template/loader_tags.py", line 150, in render
    return compiled_parent._render(context)
  File "/usr/local/lib/python3.8/dist-packages/django/template/base.py", line 162, in _render
    return self.nodelist.render(context)
  File "/usr/local/lib/python3.8/dist-packages/django/template/base.py", line 938, in render
    bit = node.render_annotated(context)
  File "/usr/local/lib/python3.8/dist-packages/django/template/base.py", line 905, in render_annotated
    return self.render(context)
  File "/usr/local/lib/python3.8/dist-packages/django/template/loader_tags.py", line 62, in render
    result = block.nodelist.render(context)
  File "/usr/local/lib/python3.8/dist-packages/django/template/base.py", line 938, in render
    bit = node.render_annotated(context)
  File "/usr/local/lib/python3.8/dist-packages/django/template/base.py", line 905, in render_annotated
    return self.render(context)
  File "/usr/local/lib/python3.8/dist-packages/django/template/defaulttags.py", line 168, in render
    len_values = len(values)
  File "/usr/local/lib/python3.8/dist-packages/django/db/models/query.py", line 262, in __len__
    self._fetch_all()
  File "/usr/local/lib/python3.8/dist-packages/django/db/models/query.py", line 1324, in _fetch_all
    self._result_cache = list(self._iterable_class(self))
  File "/usr/local/lib/python3.8/dist-packages/django/db/models/query.py", line 51, in __iter__
    results = compiler.execute_sql(chunked_fetch=self.chunked_fetch, chunk_size=self.chunk_size)
  File "/usr/local/lib/python3.8/dist-packages/django/db/models/sql/compiler.py", line 1169, in execute_sql
    cursor.execute(sql, params)
  File "/usr/local/lib/python3.8/dist-packages/django/db/backends/utils.py", line 98, in execute
    return super().execute(sql, params)
  File "/usr/local/lib/python3.8/dist-packages/django/db/backends/utils.py", line 66, in execute
    return self._execute_with_wrappers(sql, params, many=False, executor=self._execute)
  File "/usr/local/lib/python3.8/dist-packages/django/db/backends/utils.py", line 75, in _execute_with_wrappers
    return executor(sql, params, many, context)
  File "/usr/local/lib/python3.8/dist-packages/django/db/backends/utils.py", line 84, in _execute
    return self.cursor.execute(sql, params)
  File "/usr/local/lib/python3.8/dist-packages/django/db/utils.py", line 90, in __exit__
    raise dj_exc_value.with_traceback(traceback) from exc_value
  File "/usr/local/lib/python3.8/dist-packages/django/db/backends/utils.py", line 84, in _execute
    return self.cursor.execute(sql, params)
  File "/usr/local/lib/python3.8/dist-packages/django/db/backends/mysql/base.py", line 73, in execute
    return self.cursor.execute(query, args)
  File "/usr/local/lib/python3.8/dist-packages/MySQLdb/cursors.py", line 206, in execute
    res = self._query(query)
  File "/usr/local/lib/python3.8/dist-packages/MySQLdb/cursors.py", line 319, in _query
    db.query(q)
  File "/usr/local/lib/python3.8/dist-packages/MySQLdb/connections.py", line 254, in query
    _mysql.connection.query(self, query)
django.db.utils.ProgrammingError: (1146, "Table 'blog_django.lifelog' doesn't exist")
[02/Feb/2023 11:11:51] "GET /lifelog/ HTTP/1.1" 500 211848
/www/django_www/app01/views.py changed, reloading.
Performing system checks...

System check identified no issues (0 silenced).
February 02, 2023 - 11:11:50
Django version 3.2, using settings 'django_www.settings'
Starting development server at http://0.0.0.0:80/
Quit the server with CONTROL-C.
Watching for file changes with StatReloader
/www/django_www/app01/views.py changed, reloading.
Performing system checks...

System check identified no issues (0 silenced).
February 02, 2023 - 11:12:23
Django version 3.2, using settings 'django_www.settings'
Starting development server at http://0.0.0.0:80/
Quit the server with CONTROL-C.
Watching for file changes with StatReloader
Exception in thread django-main-thread:
Traceback (most recent call last):
  File "/usr/lib/python3.8/threading.py", line 932, in _bootstrap_inner
    self.run()
  File "/usr/lib/python3.8/threading.py", line 870, in run
    self._target(*self._args, **self._kwargs)
  File "/usr/local/lib/python3.8/dist-packages/django/utils/autoreload.py", line 64, in wrapper
    fn(*args, **kwargs)
  File "/usr/local/lib/python3.8/dist-packages/django/core/management/commands/runserver.py", line 118, in inner_run
    self.check(display_num_errors=True)
  File "/usr/local/lib/python3.8/dist-packages/django/core/management/base.py", line 419, in check
    all_issues = checks.run_checks(
  File "/usr/local/lib/python3.8/dist-packages/django/core/checks/registry.py", line 76, in run_checks
    new_errors = check(app_configs=app_configs, databases=databases)
  File "/usr/local/lib/python3.8/dist-packages/django/core/checks/urls.py", line 13, in check_url_config
    return check_resolver(resolver)
  File "/usr/local/lib/python3.8/dist-packages/django/core/checks/urls.py", line 23, in check_resolver
    return check_method()
  File "/usr/local/lib/python3.8/dist-packages/django/urls/resolvers.py", line 412, in check
    for pattern in self.url_patterns:
  File "/usr/local/lib/python3.8/dist-packages/django/utils/functional.py", line 48, in __get__
    res = instance.__dict__[self.name] = self.func(instance)
  File "/usr/local/lib/python3.8/dist-packages/django/urls/resolvers.py", line 598, in url_patterns
    patterns = getattr(self.urlconf_module, "urlpatterns", self.urlconf_module)
  File "/usr/local/lib/python3.8/dist-packages/django/utils/functional.py", line 48, in __get__
    res = instance.__dict__[self.name] = self.func(instance)
  File "/usr/local/lib/python3.8/dist-packages/django/urls/resolvers.py", line 591, in urlconf_module
    return import_module(self.urlconf_name)
  File "/usr/lib/python3.8/importlib/__init__.py", line 127, in import_module
    return _bootstrap._gcd_import(name[level:], package, level)
  File "<frozen importlib._bootstrap>", line 1014, in _gcd_import
  File "<frozen importlib._bootstrap>", line 991, in _find_and_load
  File "<frozen importlib._bootstrap>", line 975, in _find_and_load_unlocked
  File "<frozen importlib._bootstrap>", line 671, in _load_unlocked
  File "<frozen importlib._bootstrap_external>", line 848, in exec_module
  File "<frozen importlib._bootstrap>", line 219, in _call_with_frames_removed
  File "/www/django_www/django_www/urls.py", line 3, in <module>
    from app01 import views
  File "/www/django_www/app01/views.py", line 5
    form app01.models import App01Lifelog
         ^
SyntaxError: invalid syntax
/www/django_www/app01/views.py changed, reloading.
Performing system checks...

Watching for file changes with StatReloader
Internal Server Error: /lifelog/
Traceback (most recent call last):
  File "/usr/local/lib/python3.8/dist-packages/django/utils/connection.py", line 58, in __getitem__
    return getattr(self._connections, alias)
  File "/usr/local/lib/python3.8/dist-packages/asgiref/local.py", line 105, in __getattr__
    raise AttributeError(f"{self!r} object has no attribute {key!r}")
AttributeError: <asgiref.local.Local object at 0x7f785b4474f0> object has no attribute 'app01_lifelog'

During handling of the above exception, another exception occurred:

Traceback (most recent call last):
  File "/usr/local/lib/python3.8/dist-packages/django/core/handlers/exception.py", line 47, in inner
    response = get_response(request)
  File "/usr/local/lib/python3.8/dist-packages/django/core/handlers/base.py", line 181, in _get_response
    response = wrapped_callback(request, *callback_args, **callback_kwargs)
  File "/www/django_www/app01/views.py", line 23, in lifelog
    return render(request, 'lifelog.html', {'lifelog':lifelog})
  File "/usr/local/lib/python3.8/dist-packages/django/shortcuts.py", line 19, in render
    content = loader.render_to_string(template_name, context, request, using=using)
  File "/usr/local/lib/python3.8/dist-packages/django/template/loader.py", line 62, in render_to_string
    return template.render(context, request)
  File "/usr/local/lib/python3.8/dist-packages/django/template/backends/django.py", line 61, in render
    return self.template.render(context)
  File "/usr/local/lib/python3.8/dist-packages/django/template/base.py", line 170, in render
    return self._render(context)
  File "/usr/local/lib/python3.8/dist-packages/django/template/base.py", line 162, in _render
    return self.nodelist.render(context)
  File "/usr/local/lib/python3.8/dist-packages/django/template/base.py", line 938, in render
    bit = node.render_annotated(context)
  File "/usr/local/lib/python3.8/dist-packages/django/template/base.py", line 905, in render_annotated
    return self.render(context)
  File "/usr/local/lib/python3.8/dist-packages/django/template/loader_tags.py", line 150, in render
    return compiled_parent._render(context)
  File "/usr/local/lib/python3.8/dist-packages/django/template/base.py", line 162, in _render
    return self.nodelist.render(context)
  File "/usr/local/lib/python3.8/dist-packages/django/template/base.py", line 938, in render
    bit = node.render_annotated(context)
  File "/usr/local/lib/python3.8/dist-packages/django/template/base.py", line 905, in render_annotated
    return self.render(context)
  File "/usr/local/lib/python3.8/dist-packages/django/template/loader_tags.py", line 62, in render
    result = block.nodelist.render(context)
  File "/usr/local/lib/python3.8/dist-packages/django/template/base.py", line 938, in render
    bit = node.render_annotated(context)
  File "/usr/local/lib/python3.8/dist-packages/django/template/base.py", line 905, in render_annotated
    return self.render(context)
  File "/usr/local/lib/python3.8/dist-packages/django/template/defaulttags.py", line 168, in render
    len_values = len(values)
  File "/usr/local/lib/python3.8/dist-packages/django/db/models/query.py", line 262, in __len__
    self._fetch_all()
  File "/usr/local/lib/python3.8/dist-packages/django/db/models/query.py", line 1324, in _fetch_all
    self._result_cache = list(self._iterable_class(self))
  File "/usr/local/lib/python3.8/dist-packages/django/db/models/query.py", line 48, in __iter__
    compiler = queryset.query.get_compiler(using=db)
  File "/usr/local/lib/python3.8/dist-packages/django/db/models/sql/query.py", line 292, in get_compiler
    connection = connections[using]
  File "/usr/local/lib/python3.8/dist-packages/django/utils/connection.py", line 61, in __getitem__
    raise self.exception_class(f"The connection '{alias}' doesn't exist.")
django.utils.connection.ConnectionDoesNotExist: The connection 'app01_lifelog' doesn't exist.
[02/Feb/2023 11:13:37] "GET /lifelog/ HTTP/1.1" 500 155652
/www/django_www/app01/views.py changed, reloading.
Performing system checks...

System check identified no issues (0 silenced).
February 02, 2023 - 11:13:36
Django version 3.2, using settings 'django_www.settings'
Starting development server at http://0.0.0.0:80/
Quit the server with CONTROL-C.
Watching for file changes with StatReloader
Internal Server Error: /lifelog/
Traceback (most recent call last):
  File "/usr/local/lib/python3.8/dist-packages/django/utils/connection.py", line 58, in __getitem__
    return getattr(self._connections, alias)
  File "/usr/local/lib/python3.8/dist-packages/asgiref/local.py", line 105, in __getattr__
    raise AttributeError(f"{self!r} object has no attribute {key!r}")
AttributeError: <asgiref.local.Local object at 0x7f22f6e034f0> object has no attribute 'app01_lifelog'

During handling of the above exception, another exception occurred:

Traceback (most recent call last):
  File "/usr/local/lib/python3.8/dist-packages/django/core/handlers/exception.py", line 47, in inner
    response = get_response(request)
  File "/usr/local/lib/python3.8/dist-packages/django/core/handlers/base.py", line 181, in _get_response
    response = wrapped_callback(request, *callback_args, **callback_kwargs)
  File "/www/django_www/app01/views.py", line 23, in lifelog
    return render(request, 'lifelog.html', {'lifelog':lifelog})
  File "/usr/local/lib/python3.8/dist-packages/django/shortcuts.py", line 19, in render
    content = loader.render_to_string(template_name, context, request, using=using)
  File "/usr/local/lib/python3.8/dist-packages/django/template/loader.py", line 62, in render_to_string
    return template.render(context, request)
  File "/usr/local/lib/python3.8/dist-packages/django/template/backends/django.py", line 61, in render
    return self.template.render(context)
  File "/usr/local/lib/python3.8/dist-packages/django/template/base.py", line 170, in render
    return self._render(context)
  File "/usr/local/lib/python3.8/dist-packages/django/template/base.py", line 162, in _render
    return self.nodelist.render(context)
  File "/usr/local/lib/python3.8/dist-packages/django/template/base.py", line 938, in render
    bit = node.render_annotated(context)
  File "/usr/local/lib/python3.8/dist-packages/django/template/base.py", line 905, in render_annotated
    return self.render(context)
  File "/usr/local/lib/python3.8/dist-packages/django/template/loader_tags.py", line 150, in render
    return compiled_parent._render(context)
  File "/usr/local/lib/python3.8/dist-packages/django/template/base.py", line 162, in _render
    return self.nodelist.render(context)
  File "/usr/local/lib/python3.8/dist-packages/django/template/base.py", line 938, in render
    bit = node.render_annotated(context)
  File "/usr/local/lib/python3.8/dist-packages/django/template/base.py", line 905, in render_annotated
    return self.render(context)
  File "/usr/local/lib/python3.8/dist-packages/django/template/loader_tags.py", line 62, in render
    result = block.nodelist.render(context)
  File "/usr/local/lib/python3.8/dist-packages/django/template/base.py", line 938, in render
    bit = node.render_annotated(context)
  File "/usr/local/lib/python3.8/dist-packages/django/template/base.py", line 905, in render_annotated
    return self.render(context)
  File "/usr/local/lib/python3.8/dist-packages/django/template/defaulttags.py", line 168, in render
    len_values = len(values)
  File "/usr/local/lib/python3.8/dist-packages/django/db/models/query.py", line 262, in __len__
    self._fetch_all()
  File "/usr/local/lib/python3.8/dist-packages/django/db/models/query.py", line 1324, in _fetch_all
    self._result_cache = list(self._iterable_class(self))
  File "/usr/local/lib/python3.8/dist-packages/django/db/models/query.py", line 48, in __iter__
    compiler = queryset.query.get_compiler(using=db)
  File "/usr/local/lib/python3.8/dist-packages/django/db/models/sql/query.py", line 292, in get_compiler
    connection = connections[using]
  File "/usr/local/lib/python3.8/dist-packages/django/utils/connection.py", line 61, in __getitem__
    raise self.exception_class(f"The connection '{alias}' doesn't exist.")
django.utils.connection.ConnectionDoesNotExist: The connection 'app01_lifelog' doesn't exist.
[02/Feb/2023 11:14:00] "GET /lifelog/ HTTP/1.1" 500 155661
[02/Feb/2023 11:15:00] "GET /music/list/ HTTP/1.1" 200 29040
/www/django_www/app01/views.py changed, reloading.
Performing system checks...

System check identified no issues (0 silenced).
February 02, 2023 - 11:14:00
Django version 3.2, using settings 'django_www.settings'
Starting development server at http://0.0.0.0:80/
Quit the server with CONTROL-C.
Watching for file changes with StatReloader
[02/Feb/2023 11:15:20] "GET /lifelog/ HTTP/1.1" 200 36798
[02/Feb/2023 11:16:58] "GET /lifelog/log/ HTTP/1.1" 200 4127
[02/Feb/2023 11:17:15] "POST /lifelog/log/ HTTP/1.1" 200 9
[02/Feb/2023 11:17:16] "GET /lifelog/log/ HTTP/1.1" 200 4127
Internal Server Error: /lifelog/log/
Traceback (most recent call last):
  File "/usr/local/lib/python3.8/dist-packages/django/core/handlers/exception.py", line 47, in inner
    response = get_response(request)
  File "/usr/local/lib/python3.8/dist-packages/django/core/handlers/base.py", line 181, in _get_response
    response = wrapped_callback(request, *callback_args, **callback_kwargs)
  File "/www/django_www/app01/views.py", line 62, in lifelog_log
    return redirect()
TypeError: redirect() missing 1 required positional argument: 'to'
[02/Feb/2023 11:17:20] "POST /lifelog/log/ HTTP/1.1" 500 57559
/www/django_www/app01/views.py changed, reloading.
Performing system checks...

System check identified no issues (0 silenced).
February 02, 2023 - 11:15:19
Django version 3.2, using settings 'django_www.settings'
Starting development server at http://0.0.0.0:80/
Quit the server with CONTROL-C.
form.errors +++++form.errors的错误+++++
Watching for file changes with StatReloader
[02/Feb/2023 11:18:05] "POST /lifelog/log/ HTTP/1.1" 200 9
[02/Feb/2023 11:18:06] "GET /lifelog/log/ HTTP/1.1" 200 4127
[02/Feb/2023 11:18:11] "POST /lifelog/log/ HTTP/1.1" 302 0
[02/Feb/2023 11:18:11] "GET /lifelog/ HTTP/1.1" 200 36773
[02/Feb/2023 11:18:15] "GET /lifelog/log/ HTTP/1.1" 200 4127
[02/Feb/2023 11:18:26] "POST /lifelog/log/ HTTP/1.1" 302 0
[02/Feb/2023 11:18:26] "GET /lifelog/ HTTP/1.1" 200 35752
[02/Feb/2023 11:18:34] "GET /lifelog/log/ HTTP/1.1" 200 4127
[02/Feb/2023 11:18:41] "POST /lifelog/log/ HTTP/1.1" 200 9
[02/Feb/2023 11:18:42] "GET /lifelog/log/ HTTP/1.1" 200 4127
[02/Feb/2023 11:18:46] "POST /lifelog/log/ HTTP/1.1" 302 0
[02/Feb/2023 11:18:46] "GET /lifelog/ HTTP/1.1" 200 35726
[02/Feb/2023 11:41:54] "GET /lifelog/log/ HTTP/1.1" 200 4127
Internal Server Error: /lifelog/edit/7026662103608070147/
Traceback (most recent call last):
  File "/usr/local/lib/python3.8/dist-packages/django/utils/connection.py", line 58, in __getitem__
    return getattr(self._connections, alias)
  File "/usr/local/lib/python3.8/dist-packages/asgiref/local.py", line 105, in __getattr__
    raise AttributeError(f"{self!r} object has no attribute {key!r}")
AttributeError: <asgiref.local.Local object at 0x7efefe5914f0> object has no attribute 'app01_lifelog'

During handling of the above exception, another exception occurred:

Traceback (most recent call last):
  File "/usr/local/lib/python3.8/dist-packages/django/core/handlers/exception.py", line 47, in inner
    response = get_response(request)
  File "/usr/local/lib/python3.8/dist-packages/django/core/handlers/base.py", line 181, in _get_response
    response = wrapped_callback(request, *callback_args, **callback_kwargs)
  File "/www/django_www/app01/views.py", line 26, in lifelog_edit
    one_row = App01Lifelog.objects.using('app01_lifelog').filter(global_id=global_id).first()
  File "/usr/local/lib/python3.8/dist-packages/django/db/models/query.py", line 674, in first
    for obj in (self if self.ordered else self.order_by('pk'))[:1]:
  File "/usr/local/lib/python3.8/dist-packages/django/db/models/query.py", line 280, in __iter__
    self._fetch_all()
  File "/usr/local/lib/python3.8/dist-packages/django/db/models/query.py", line 1324, in _fetch_all
    self._result_cache = list(self._iterable_class(self))
  File "/usr/local/lib/python3.8/dist-packages/django/db/models/query.py", line 48, in __iter__
    compiler = queryset.query.get_compiler(using=db)
  File "/usr/local/lib/python3.8/dist-packages/django/db/models/sql/query.py", line 292, in get_compiler
    connection = connections[using]
  File "/usr/local/lib/python3.8/dist-packages/django/utils/connection.py", line 61, in __getitem__
    raise self.exception_class(f"The connection '{alias}' doesn't exist.")
django.utils.connection.ConnectionDoesNotExist: The connection 'app01_lifelog' doesn't exist.
[02/Feb/2023 11:50:00] "GET /lifelog/edit/7026662103608070147/ HTTP/1.1" 500 89244
Internal Server Error: /lifelog/edit/7026662103608070149/
Traceback (most recent call last):
  File "/usr/local/lib/python3.8/dist-packages/django/utils/connection.py", line 58, in __getitem__
    return getattr(self._connections, alias)
  File "/usr/local/lib/python3.8/dist-packages/asgiref/local.py", line 105, in __getattr__
    raise AttributeError(f"{self!r} object has no attribute {key!r}")
AttributeError: <asgiref.local.Local object at 0x7efefe5914f0> object has no attribute 'app01_lifelog'

During handling of the above exception, another exception occurred:

Traceback (most recent call last):
  File "/usr/local/lib/python3.8/dist-packages/django/core/handlers/exception.py", line 47, in inner
    response = get_response(request)
  File "/usr/local/lib/python3.8/dist-packages/django/core/handlers/base.py", line 181, in _get_response
    response = wrapped_callback(request, *callback_args, **callback_kwargs)
  File "/www/django_www/app01/views.py", line 26, in lifelog_edit
    one_row = App01Lifelog.objects.using('app01_lifelog').filter(global_id=global_id).first()
  File "/usr/local/lib/python3.8/dist-packages/django/db/models/query.py", line 674, in first
    for obj in (self if self.ordered else self.order_by('pk'))[:1]:
  File "/usr/local/lib/python3.8/dist-packages/django/db/models/query.py", line 280, in __iter__
    self._fetch_all()
  File "/usr/local/lib/python3.8/dist-packages/django/db/models/query.py", line 1324, in _fetch_all
    self._result_cache = list(self._iterable_class(self))
  File "/usr/local/lib/python3.8/dist-packages/django/db/models/query.py", line 48, in __iter__
    compiler = queryset.query.get_compiler(using=db)
  File "/usr/local/lib/python3.8/dist-packages/django/db/models/sql/query.py", line 292, in get_compiler
    connection = connections[using]
  File "/usr/local/lib/python3.8/dist-packages/django/utils/connection.py", line 61, in __getitem__
    raise self.exception_class(f"The connection '{alias}' doesn't exist.")
django.utils.connection.ConnectionDoesNotExist: The connection 'app01_lifelog' doesn't exist.
[02/Feb/2023 11:50:02] "GET /lifelog/edit/7026662103608070149/ HTTP/1.1" 500 89244
[02/Feb/2023 11:50:38] "GET /lifelog/log/ HTTP/1.1" 200 4127
/www/django_www/app01/views.py changed, reloading.
Performing system checks...

System check identified no issues (0 silenced).
February 02, 2023 - 11:18:04
Django version 3.2, using settings 'django_www.settings'
Starting development server at http://0.0.0.0:80/
Quit the server with CONTROL-C.
form.errors +++++form.errors的错误+++++
form.errors +++++form.errors的错误+++++
Watching for file changes with StatReloader
/www/django_www/app01/views.py changed, reloading.
Performing system checks...

System check identified no issues (0 silenced).
February 02, 2023 - 12:11:58
Django version 3.2, using settings 'django_www.settings'
Starting development server at http://0.0.0.0:80/
Quit the server with CONTROL-C.
Watching for file changes with StatReloader
Internal Server Error: /lifelog/log/
Traceback (most recent call last):
  File "/usr/local/lib/python3.8/dist-packages/django/core/handlers/exception.py", line 47, in inner
    response = get_response(request)
  File "/usr/local/lib/python3.8/dist-packages/django/core/handlers/base.py", line 181, in _get_response
    response = wrapped_callback(request, *callback_args, **callback_kwargs)
  File "/www/django_www/app01/views.py", line 54, in lifelog_log
    form = LogModeForm()  # 创建LogModeForm的实例对象
  File "/www/django_www/app01/views.py", line 49, in __init__
    field[1][2].widget.attrs = {"class": "a111"}
TypeError: 'IntegerField' object is not subscriptable
[02/Feb/2023 12:12:04] "GET /lifelog/log/ HTTP/1.1" 500 60712
/www/django_www/app01/views.py changed, reloading.
Performing system checks...

System check identified no issues (0 silenced).
February 02, 2023 - 12:12:04
Django version 3.2, using settings 'django_www.settings'
Starting development server at http://0.0.0.0:80/
Quit the server with CONTROL-C.
Watching for file changes with StatReloader
[02/Feb/2023 12:12:11] "GET /lifelog/log/ HTTP/1.1" 200 4115
/www/django_www/app01/views.py changed, reloading.
Performing system checks...

System check identified no issues (0 silenced).
February 02, 2023 - 12:12:11
Django version 3.2, using settings 'django_www.settings'
Starting development server at http://0.0.0.0:80/
Quit the server with CONTROL-C.
Watching for file changes with StatReloader
[02/Feb/2023 12:14:06] "GET /lifelog/log/ HTTP/1.1" 200 4115
[02/Feb/2023 12:14:13] "GET /lifelog/log/ HTTP/1.1" 200 4115
[02/Feb/2023 12:14:17] "GET /static/bootstrap/css/bootstrap.min.css.map HTTP/1.1" 200 522639
[02/Feb/2023 12:14:17] "GET /static/bootstrap/js/bootstrap.min.js.map HTTP/1.1" 200 216913
/www/django_www/app01/views.py changed, reloading.
Performing system checks...

System check identified no issues (0 silenced).
February 02, 2023 - 12:14:06
Django version 3.2, using settings 'django_www.settings'
Starting development server at http://0.0.0.0:80/
Quit the server with CONTROL-C.
Watching for file changes with StatReloader
Internal Server Error: /lifelog/log/
Traceback (most recent call last):
  File "/usr/local/lib/python3.8/dist-packages/django/core/handlers/exception.py", line 47, in inner
    response = get_response(request)
  File "/usr/local/lib/python3.8/dist-packages/django/core/handlers/base.py", line 181, in _get_response
    response = wrapped_callback(request, *callback_args, **callback_kwargs)
  File "/www/django_www/app01/views.py", line 53, in lifelog_log
    form = LogModeForm()  # 创建LogModeForm的实例对象
  File "/www/django_www/app01/views.py", line 48, in __init__
    field[1][2].widget.attrs =  {"value": "2020"}
TypeError: 'IntegerField' object is not subscriptable
[02/Feb/2023 12:18:31] "GET /lifelog/log/ HTTP/1.1" 500 60712
/www/django_www/app01/views.py changed, reloading.
Performing system checks...

System check identified no issues (0 silenced).
February 02, 2023 - 12:18:31
Django version 3.2, using settings 'django_www.settings'
Starting development server at http://0.0.0.0:80/
Quit the server with CONTROL-C.
Watching for file changes with StatReloader
Internal Server Error: /lifelog/log/
Traceback (most recent call last):
  File "/usr/local/lib/python3.8/dist-packages/django/core/handlers/exception.py", line 47, in inner
    response = get_response(request)
  File "/usr/local/lib/python3.8/dist-packages/django/core/handlers/base.py", line 181, in _get_response
    response = wrapped_callback(request, *callback_args, **callback_kwargs)
  File "/www/django_www/app01/views.py", line 53, in lifelog_log
    form = LogModeForm()  # 创建LogModeForm的实例对象
  File "/www/django_www/app01/views.py", line 48, in __init__
    field[1][1].widget.attrs =  {"value": "2020"}
TypeError: 'IntegerField' object is not subscriptable
[02/Feb/2023 12:18:43] "GET /lifelog/log/ HTTP/1.1" 500 60712
/www/django_www/app01/views.py changed, reloading.
Performing system checks...

System check identified no issues (0 silenced).
February 02, 2023 - 12:18:42
Django version 3.2, using settings 'django_www.settings'
Starting development server at http://0.0.0.0:80/
Quit the server with CONTROL-C.
Watching for file changes with StatReloader
[02/Feb/2023 12:19:51] "GET /lifelog/log/ HTTP/1.1" 200 4115
/www/django_www/app01/views.py changed, reloading.
Performing system checks...

System check identified no issues (0 silenced).
February 02, 2023 - 12:19:51
Django version 3.2, using settings 'django_www.settings'
Starting development server at http://0.0.0.0:80/
Quit the server with CONTROL-C.
Watching for file changes with StatReloader
[02/Feb/2023 12:21:56] "GET /lifelog/log/ HTTP/1.1" 200 4115
/www/django_www/app01/views.py changed, reloading.
Performing system checks...

System check identified no issues (0 silenced).
February 02, 2023 - 12:21:56
Django version 3.2, using settings 'django_www.settings'
Starting development server at http://0.0.0.0:80/
Quit the server with CONTROL-C.
Watching for file changes with StatReloader
[02/Feb/2023 12:22:09] "GET /lifelog/log/ HTTP/1.1" 200 4115
/www/django_www/app01/views.py changed, reloading.
Performing system checks...

System check identified no issues (0 silenced).
February 02, 2023 - 12:22:09
Django version 3.2, using settings 'django_www.settings'
Starting development server at http://0.0.0.0:80/
Quit the server with CONTROL-C.
Watching for file changes with StatReloader
[02/Feb/2023 12:23:07] "GET /lifelog/log/ HTTP/1.1" 200 4271
/www/django_www/app01/views.py changed, reloading.
Performing system checks...

System check identified no issues (0 silenced).
February 02, 2023 - 12:23:07
Django version 3.2, using settings 'django_www.settings'
Starting development server at http://0.0.0.0:80/
Quit the server with CONTROL-C.
Watching for file changes with StatReloader
[02/Feb/2023 12:23:28] "GET /lifelog/log/ HTTP/1.1" 200 4271
/www/django_www/app01/views.py changed, reloading.
Performing system checks...

System check identified no issues (0 silenced).
February 02, 2023 - 12:23:28
Django version 3.2, using settings 'django_www.settings'
Starting development server at http://0.0.0.0:80/
Quit the server with CONTROL-C.
Watching for file changes with StatReloader
[02/Feb/2023 12:23:59] "GET /lifelog/log/ HTTP/1.1" 200 5267
/www/django_www/app01/views.py changed, reloading.
Performing system checks...

System check identified no issues (0 silenced).
February 02, 2023 - 12:23:59
Django version 3.2, using settings 'django_www.settings'
Starting development server at http://0.0.0.0:80/
Quit the server with CONTROL-C.
Watching for file changes with StatReloader
/www/django_www/app01/views.py changed, reloading.
Performing system checks...

System check identified no issues (0 silenced).
February 02, 2023 - 12:24:59
Django version 3.2, using settings 'django_www.settings'
Starting development server at http://0.0.0.0:80/
Quit the server with CONTROL-C.
Watching for file changes with StatReloader
Internal Server Error: /lifelog/log/
Traceback (most recent call last):
  File "/usr/local/lib/python3.8/dist-packages/django/core/handlers/exception.py", line 47, in inner
    response = get_response(request)
  File "/usr/local/lib/python3.8/dist-packages/django/core/handlers/base.py", line 181, in _get_response
    response = wrapped_callback(request, *callback_args, **callback_kwargs)
  File "/www/django_www/app01/views.py", line 55, in lifelog_log
    form = LogModeForm()  # 创建LogModeForm的实例对象
  File "/www/django_www/app01/views.py", line 48, in __init__
    ield[1].widget.attrs = {"value": "2020"}
NameError: name 'ield' is not defined
[02/Feb/2023 12:25:05] "GET /lifelog/log/ HTTP/1.1" 500 60687
/www/django_www/app01/views.py changed, reloading.
Performing system checks...

System check identified no issues (0 silenced).
February 02, 2023 - 12:25:03
Django version 3.2, using settings 'django_www.settings'
Starting development server at http://0.0.0.0:80/
Quit the server with CONTROL-C.
Watching for file changes with StatReloader
[02/Feb/2023 12:25:12] "GET /lifelog/log/ HTTP/1.1" 200 5267
/www/django_www/app01/views.py changed, reloading.
Performing system checks...

System check identified no issues (0 silenced).
February 02, 2023 - 12:25:11
Django version 3.2, using settings 'django_www.settings'
Starting development server at http://0.0.0.0:80/
Quit the server with CONTROL-C.
Watching for file changes with StatReloader
[02/Feb/2023 12:25:20] "GET /lifelog/log/ HTTP/1.1" 200 4115
/www/django_www/app01/views.py changed, reloading.
Performing system checks...

System check identified no issues (0 silenced).
February 02, 2023 - 12:25:20
Django version 3.2, using settings 'django_www.settings'
Starting development server at http://0.0.0.0:80/
Quit the server with CONTROL-C.
Watching for file changes with StatReloader
[02/Feb/2023 12:25:36] "GET /lifelog/log/ HTTP/1.1" 200 4115
/www/django_www/app01/views.py changed, reloading.
Performing system checks...

System check identified no issues (0 silenced).
February 02, 2023 - 12:25:36
Django version 3.2, using settings 'django_www.settings'
Starting development server at http://0.0.0.0:80/
Quit the server with CONTROL-C.
Watching for file changes with StatReloader
[02/Feb/2023 12:25:53] "GET /lifelog/log/ HTTP/1.1" 200 4115
/www/django_www/app01/views.py changed, reloading.
Performing system checks...

System check identified no issues (0 silenced).
February 02, 2023 - 12:25:52
Django version 3.2, using settings 'django_www.settings'
Starting development server at http://0.0.0.0:80/
Quit the server with CONTROL-C.
Watching for file changes with StatReloader
[02/Feb/2023 12:26:11] "GET /lifelog/log/ HTTP/1.1" 200 4141
/www/django_www/app01/views.py changed, reloading.
Performing system checks...

System check identified no issues (0 silenced).
February 02, 2023 - 12:26:11
Django version 3.2, using settings 'django_www.settings'
Starting development server at http://0.0.0.0:80/
Quit the server with CONTROL-C.
Watching for file changes with StatReloader
[02/Feb/2023 12:29:03] "GET /lifelog/log/ HTTP/1.1" 200 4197
[02/Feb/2023 12:29:21] "GET /lifelog/log/ HTTP/1.1" 200 4197
[02/Feb/2023 12:29:22] "GET /lifelog/log/ HTTP/1.1" 200 4197
[02/Feb/2023 12:29:22] "GET /lifelog/log/ HTTP/1.1" 200 4197
[02/Feb/2023 12:29:23] "GET /lifelog/log/ HTTP/1.1" 200 4197
[02/Feb/2023 12:29:23] "GET /lifelog/log/ HTTP/1.1" 200 4197
[02/Feb/2023 12:29:23] "GET /lifelog/log/ HTTP/1.1" 200 4197
[02/Feb/2023 12:29:24] "GET /lifelog/log/ HTTP/1.1" 200 4197
[02/Feb/2023 12:29:24] "GET /lifelog/log/ HTTP/1.1" 200 4197
[02/Feb/2023 12:29:24] "GET /lifelog/log/ HTTP/1.1" 200 4197
[02/Feb/2023 12:29:26] "GET /lifelog/log/ HTTP/1.1" 200 4197
[02/Feb/2023 12:29:28] "GET /lifelog/log/ HTTP/1.1" 200 4197
[02/Feb/2023 12:29:29] "GET /lifelog/log/ HTTP/1.1" 200 4197
[02/Feb/2023 12:29:29] "GET /lifelog/log/ HTTP/1.1" 200 4197
/www/django_www/app01/views.py changed, reloading.
Performing system checks...

System check identified no issues (0 silenced).
February 02, 2023 - 12:29:02
Django version 3.2, using settings 'django_www.settings'
Starting development server at http://0.0.0.0:80/
Quit the server with CONTROL-C.
Watching for file changes with StatReloader
[02/Feb/2023 12:29:46] "GET /lifelog/log/ HTTP/1.1" 200 4197
[02/Feb/2023 12:29:46] "GET /lifelog/log/ HTTP/1.1" 200 4197
/www/django_www/app01/views.py changed, reloading.
Performing system checks...

System check identified no issues (0 silenced).
February 02, 2023 - 12:29:45
Django version 3.2, using settings 'django_www.settings'
Starting development server at http://0.0.0.0:80/
Quit the server with CONTROL-C.
Watching for file changes with StatReloader
[02/Feb/2023 12:34:30] "GET /lifelog/log/ HTTP/1.1" 200 4159
/www/django_www/django_www/settings.py changed, reloading.
Performing system checks...

System check identified no issues (0 silenced).
February 02, 2023 - 12:34:30
Django version 3.2, using settings 'django_www.settings'
Starting development server at http://0.0.0.0:80/
Quit the server with CONTROL-C.
Watching for file changes with StatReloader
[02/Feb/2023 12:36:34] "GET /lifelog/log/ HTTP/1.1" 200 4159
/www/django_www/app01/views.py changed, reloading.
Performing system checks...

System check identified no issues (0 silenced).
February 02, 2023 - 12:36:34
Django version 3.2, using settings 'django_www.settings'
Starting development server at http://0.0.0.0:80/
Quit the server with CONTROL-C.
Watching for file changes with StatReloader
[02/Feb/2023 12:36:42] "GET /lifelog/log/ HTTP/1.1" 200 4185
[02/Feb/2023 12:36:42] "GET /lifelog/log/ HTTP/1.1" 200 4185
[02/Feb/2023 12:36:47] "GET /lifelog/log/ HTTP/1.1" 200 4185
[02/Feb/2023 12:36:48] "GET /lifelog/log/ HTTP/1.1" 200 4185
[02/Feb/2023 12:36:48] "GET /lifelog/log/ HTTP/1.1" 200 4185
[02/Feb/2023 12:36:48] "GET /lifelog/log/ HTTP/1.1" 200 4185
[02/Feb/2023 12:36:49] "GET /lifelog/log/ HTTP/1.1" 200 4185
[02/Feb/2023 12:36:49] "GET /lifelog/log/ HTTP/1.1" 200 4185
[02/Feb/2023 12:36:49] "GET /lifelog/log/ HTTP/1.1" 200 4185
[02/Feb/2023 12:36:49] "GET /lifelog/log/ HTTP/1.1" 200 4185
[02/Feb/2023 12:36:51] "GET /lifelog/log/ HTTP/1.1" 200 4185
[02/Feb/2023 12:36:54] "GET /lifelog/log/ HTTP/1.1" 200 4185
[02/Feb/2023 12:36:57] "GET /lifelog/log/ HTTP/1.1" 200 4185
/www/django_www/app01/views.py changed, reloading.
Performing system checks...

System check identified no issues (0 silenced).
February 02, 2023 - 12:36:41
Django version 3.2, using settings 'django_www.settings'
Starting development server at http://0.0.0.0:80/
Quit the server with CONTROL-C.
Watching for file changes with StatReloader
[02/Feb/2023 12:37:09] "GET /lifelog/log/ HTTP/1.1" 200 4185
[02/Feb/2023 12:37:10] "GET /lifelog/log/ HTTP/1.1" 200 4185
[02/Feb/2023 12:37:10] "GET /lifelog/log/ HTTP/1.1" 200 4185
[02/Feb/2023 12:37:11] "GET /lifelog/log/ HTTP/1.1" 200 4185
[02/Feb/2023 12:37:11] "GET /lifelog/log/ HTTP/1.1" 200 4185
[02/Feb/2023 12:37:12] "GET /lifelog/log/ HTTP/1.1" 200 4185
[02/Feb/2023 12:37:12] "GET /lifelog/log/ HTTP/1.1" 200 4185
[02/Feb/2023 12:37:12] "GET /lifelog/log/ HTTP/1.1" 200 4185
[02/Feb/2023 12:37:13] "GET /lifelog/log/ HTTP/1.1" 200 4185
[02/Feb/2023 12:37:13] "GET /lifelog/log/ HTTP/1.1" 200 4185
[02/Feb/2023 12:37:14] "GET /lifelog/log/ HTTP/1.1" 200 4185
[02/Feb/2023 12:37:14] "GET /lifelog/log/ HTTP/1.1" 200 4185
[02/Feb/2023 12:37:15] "GET /lifelog/log/ HTTP/1.1" 200 4185
[02/Feb/2023 12:37:15] "GET /lifelog/log/ HTTP/1.1" 200 4185
[02/Feb/2023 12:37:16] "GET /lifelog/log/ HTTP/1.1" 200 4185
[02/Feb/2023 12:37:16] "GET /lifelog/log/ HTTP/1.1" 200 4185
[02/Feb/2023 12:37:17] "GET /lifelog/log/ HTTP/1.1" 200 4185
[02/Feb/2023 12:37:17] "GET /lifelog/log/ HTTP/1.1" 200 4185
/www/django_www/app01/views.py changed, reloading.
Performing system checks...

System check identified no issues (0 silenced).
February 02, 2023 - 12:37:08
Django version 3.2, using settings 'django_www.settings'
Starting development server at http://0.0.0.0:80/
Quit the server with CONTROL-C.
Watching for file changes with StatReloader
Exception in thread django-main-thread:
Traceback (most recent call last):
  File "/usr/lib/python3.8/threading.py", line 932, in _bootstrap_inner
    self.run()
  File "/usr/lib/python3.8/threading.py", line 870, in run
    self._target(*self._args, **self._kwargs)
  File "/usr/local/lib/python3.8/dist-packages/django/utils/autoreload.py", line 64, in wrapper
    fn(*args, **kwargs)
  File "/usr/local/lib/python3.8/dist-packages/django/core/management/commands/runserver.py", line 118, in inner_run
    self.check(display_num_errors=True)
  File "/usr/local/lib/python3.8/dist-packages/django/core/management/base.py", line 419, in check
    all_issues = checks.run_checks(
  File "/usr/local/lib/python3.8/dist-packages/django/core/checks/registry.py", line 76, in run_checks
    new_errors = check(app_configs=app_configs, databases=databases)
  File "/usr/local/lib/python3.8/dist-packages/django/core/checks/urls.py", line 13, in check_url_config
    return check_resolver(resolver)
  File "/usr/local/lib/python3.8/dist-packages/django/core/checks/urls.py", line 23, in check_resolver
    return check_method()
  File "/usr/local/lib/python3.8/dist-packages/django/urls/resolvers.py", line 412, in check
    for pattern in self.url_patterns:
  File "/usr/local/lib/python3.8/dist-packages/django/utils/functional.py", line 48, in __get__
    res = instance.__dict__[self.name] = self.func(instance)
  File "/usr/local/lib/python3.8/dist-packages/django/urls/resolvers.py", line 598, in url_patterns
    patterns = getattr(self.urlconf_module, "urlpatterns", self.urlconf_module)
  File "/usr/local/lib/python3.8/dist-packages/django/utils/functional.py", line 48, in __get__
    res = instance.__dict__[self.name] = self.func(instance)
  File "/usr/local/lib/python3.8/dist-packages/django/urls/resolvers.py", line 591, in urlconf_module
    return import_module(self.urlconf_name)
  File "/usr/lib/python3.8/importlib/__init__.py", line 127, in import_module
    return _bootstrap._gcd_import(name[level:], package, level)
  File "<frozen importlib._bootstrap>", line 1014, in _gcd_import
  File "<frozen importlib._bootstrap>", line 991, in _find_and_load
  File "<frozen importlib._bootstrap>", line 975, in _find_and_load_unlocked
  File "<frozen importlib._bootstrap>", line 671, in _load_unlocked
  File "<frozen importlib._bootstrap_external>", line 848, in exec_module
  File "<frozen importlib._bootstrap>", line 219, in _call_with_frames_removed
  File "/www/django_www/django_www/urls.py", line 3, in <module>
    from app01 import views
  File "/www/django_www/app01/views.py", line 36, in <module>
    current_time = timezone.localtime()
  File "/usr/local/lib/python3.8/dist-packages/django/utils/timezone.py", line 176, in localtime
    raise ValueError("localtime() cannot be applied to a naive datetime")
ValueError: localtime() cannot be applied to a naive datetime
nohup: ignoring input
Watching for file changes with StatReloader
Exception in thread django-main-thread:
Traceback (most recent call last):
  File "/usr/lib/python3.8/threading.py", line 932, in _bootstrap_inner
    self.run()
  File "/usr/lib/python3.8/threading.py", line 870, in run
    self._target(*self._args, **self._kwargs)
  File "/usr/local/lib/python3.8/dist-packages/django/utils/autoreload.py", line 64, in wrapper
    fn(*args, **kwargs)
  File "/usr/local/lib/python3.8/dist-packages/django/core/management/commands/runserver.py", line 118, in inner_run
    self.check(display_num_errors=True)
  File "/usr/local/lib/python3.8/dist-packages/django/core/management/base.py", line 419, in check
    all_issues = checks.run_checks(
  File "/usr/local/lib/python3.8/dist-packages/django/core/checks/registry.py", line 76, in run_checks
    new_errors = check(app_configs=app_configs, databases=databases)
  File "/usr/local/lib/python3.8/dist-packages/django/core/checks/urls.py", line 13, in check_url_config
    return check_resolver(resolver)
  File "/usr/local/lib/python3.8/dist-packages/django/core/checks/urls.py", line 23, in check_resolver
    return check_method()
  File "/usr/local/lib/python3.8/dist-packages/django/urls/resolvers.py", line 412, in check
    for pattern in self.url_patterns:
  File "/usr/local/lib/python3.8/dist-packages/django/utils/functional.py", line 48, in __get__
    res = instance.__dict__[self.name] = self.func(instance)
  File "/usr/local/lib/python3.8/dist-packages/django/urls/resolvers.py", line 598, in url_patterns
    patterns = getattr(self.urlconf_module, "urlpatterns", self.urlconf_module)
  File "/usr/local/lib/python3.8/dist-packages/django/utils/functional.py", line 48, in __get__
    res = instance.__dict__[self.name] = self.func(instance)
  File "/usr/local/lib/python3.8/dist-packages/django/urls/resolvers.py", line 591, in urlconf_module
    return import_module(self.urlconf_name)
  File "/usr/lib/python3.8/importlib/__init__.py", line 127, in import_module
    return _bootstrap._gcd_import(name[level:], package, level)
  File "<frozen importlib._bootstrap>", line 1014, in _gcd_import
  File "<frozen importlib._bootstrap>", line 991, in _find_and_load
  File "<frozen importlib._bootstrap>", line 975, in _find_and_load_unlocked
  File "<frozen importlib._bootstrap>", line 671, in _load_unlocked
  File "<frozen importlib._bootstrap_external>", line 848, in exec_module
  File "<frozen importlib._bootstrap>", line 219, in _call_with_frames_removed
  File "/www/django_www/django_www/urls.py", line 3, in <module>
    from app01 import views
  File "/www/django_www/app01/views.py", line 54
    current_time = timezone.now().
                                 ^
SyntaxError: invalid syntax
/www/django_www/app01/views.py changed, reloading.
Performing system checks...

Watching for file changes with StatReloader
[02/Feb/2023 12:41:07] "GET /lifelog/ HTTP/1.1" 200 35727
[02/Feb/2023 12:41:09] "GET /lifelog/log/ HTTP/1.1" 200 4185
/www/django_www/app01/views.py changed, reloading.
Performing system checks...

System check identified no issues (0 silenced).
February 02, 2023 - 12:41:07
Django version 3.2, using settings 'django_www.settings'
Starting development server at http://0.0.0.0:80/
Quit the server with CONTROL-C.
Watching for file changes with StatReloader
Internal Server Error: /lifelog/log/
Traceback (most recent call last):
  File "/usr/local/lib/python3.8/dist-packages/django/core/handlers/exception.py", line 47, in inner
    response = get_response(request)
  File "/usr/local/lib/python3.8/dist-packages/django/core/handlers/base.py", line 181, in _get_response
    response = wrapped_callback(request, *callback_args, **callback_kwargs)
  File "/www/django_www/app01/views.py", line 62, in lifelog_log
    form = LogModeForm()  # 创建LogModeForm的实例对象
  File "/www/django_www/app01/views.py", line 54, in __init__
    current_time = timezone.now()[:current_time.index('.')]
UnboundLocalError: local variable 'current_time' referenced before assignment
[02/Feb/2023 12:46:26] "GET /lifelog/log/ HTTP/1.1" 500 60834
/www/django_www/app01/views.py changed, reloading.
Performing system checks...

System check identified no issues (0 silenced).
February 02, 2023 - 12:46:25
Django version 3.2, using settings 'django_www.settings'
Starting development server at http://0.0.0.0:80/
Quit the server with CONTROL-C.
Watching for file changes with StatReloader
[02/Feb/2023 12:46:45] "GET /lifelog/log/ HTTP/1.1" 200 4185
[02/Feb/2023 12:46:52] "POST /lifelog/log/ HTTP/1.1" 302 0
[02/Feb/2023 12:46:52] "GET /lifelog/ HTTP/1.1" 200 35671
[02/Feb/2023 12:46:57] "GET /lifelog/ HTTP/1.1" 200 35671
[02/Feb/2023 12:47:19] "POST /lifelog/log/ HTTP/1.1" 302 0
[02/Feb/2023 12:47:19] "GET /lifelog/ HTTP/1.1" 200 35604
[02/Feb/2023 12:47:30] "GET /lifelog/log/ HTTP/1.1" 200 4185
[02/Feb/2023 12:47:30] "GET /lifelog/log/ HTTP/1.1" 200 4185
[02/Feb/2023 12:47:30] "GET /lifelog/log/ HTTP/1.1" 200 4185
[02/Feb/2023 12:47:31] "GET /lifelog/log/ HTTP/1.1" 200 4185
[02/Feb/2023 12:47:31] "GET /lifelog/log/ HTTP/1.1" 200 4185
[02/Feb/2023 12:47:31] "GET /lifelog/log/ HTTP/1.1" 200 4185
[02/Feb/2023 12:47:31] "GET /lifelog/log/ HTTP/1.1" 200 4185
[02/Feb/2023 12:47:32] "GET /lifelog/log/ HTTP/1.1" 200 4185
[02/Feb/2023 12:47:32] "GET /lifelog/log/ HTTP/1.1" 200 4185
[02/Feb/2023 12:47:32] "GET /lifelog/log/ HTTP/1.1" 200 4185
[02/Feb/2023 12:47:32] "GET /lifelog/log/ HTTP/1.1" 200 4185
[02/Feb/2023 12:47:32] "GET /lifelog/log/ HTTP/1.1" 200 4185
[02/Feb/2023 12:47:33] "GET /lifelog/log/ HTTP/1.1" 200 4185
[02/Feb/2023 12:47:33] "GET /lifelog/log/ HTTP/1.1" 200 4185
/www/django_www/app01/views.py changed, reloading.
Performing system checks...

System check identified no issues (0 silenced).
February 02, 2023 - 12:46:45
Django version 3.2, using settings 'django_www.settings'
Starting development server at http://0.0.0.0:80/
Quit the server with CONTROL-C.
Watching for file changes with StatReloader
[02/Feb/2023 12:53:36] "GET /lifelog/log/ HTTP/1.1" 200 4335
[02/Feb/2023 12:53:38] "GET /lifelog/log/ HTTP/1.1" 200 4335
[02/Feb/2023 12:53:38] "GET /lifelog/log/ HTTP/1.1" 200 4335
[02/Feb/2023 12:53:39] "GET /lifelog/log/ HTTP/1.1" 200 4335
/www/django_www/django_www/settings.py changed, reloading.
Performing system checks...

System check identified no issues (0 silenced).
February 02, 2023 - 12:53:36
Django version 3.2, using settings 'django_www.settings'
Starting development server at http://0.0.0.0:80/
Quit the server with CONTROL-C.
Traceback (most recent call last):
  File "/www/django_www/manage.py", line 22, in <module>
    main()
  File "/www/django_www/manage.py", line 18, in main
    execute_from_command_line(sys.argv)
  File "/usr/local/lib/python3.8/dist-packages/django/core/management/__init__.py", line 419, in execute_from_command_line
    utility.execute()
  File "/usr/local/lib/python3.8/dist-packages/django/core/management/__init__.py", line 363, in execute
    settings.INSTALLED_APPS
  File "/usr/local/lib/python3.8/dist-packages/django/conf/__init__.py", line 82, in __getattr__
    self._setup(name)
  File "/usr/local/lib/python3.8/dist-packages/django/conf/__init__.py", line 69, in _setup
    self._wrapped = Settings(settings_module)
  File "/usr/local/lib/python3.8/dist-packages/django/conf/__init__.py", line 170, in __init__
    mod = importlib.import_module(self.SETTINGS_MODULE)
  File "/usr/lib/python3.8/importlib/__init__.py", line 127, in import_module
    return _bootstrap._gcd_import(name[level:], package, level)
  File "<frozen importlib._bootstrap>", line 1014, in _gcd_import
  File "<frozen importlib._bootstrap>", line 991, in _find_and_load
  File "<frozen importlib._bootstrap>", line 975, in _find_and_load_unlocked
  File "<frozen importlib._bootstrap>", line 671, in _load_unlocked
  File "<frozen importlib._bootstrap_external>", line 848, in exec_module
  File "<frozen importlib._bootstrap>", line 219, in _call_with_frames_removed
  File "/www/django_www/django_www/settings.py", line 153, in <module>
    sys.path.append = [ BASE_DIR / "crawler" ]
AttributeError: 'list' object attribute 'append' is read-only
nohup: ignoring input
Traceback (most recent call last):
  File "/www/django_www/manage.py", line 22, in <module>
    main()
  File "/www/django_www/manage.py", line 18, in main
    execute_from_command_line(sys.argv)
  File "/usr/local/lib/python3.8/dist-packages/django/core/management/__init__.py", line 419, in execute_from_command_line
    utility.execute()
  File "/usr/local/lib/python3.8/dist-packages/django/core/management/__init__.py", line 363, in execute
    settings.INSTALLED_APPS
  File "/usr/local/lib/python3.8/dist-packages/django/conf/__init__.py", line 82, in __getattr__
    self._setup(name)
  File "/usr/local/lib/python3.8/dist-packages/django/conf/__init__.py", line 69, in _setup
    self._wrapped = Settings(settings_module)
  File "/usr/local/lib/python3.8/dist-packages/django/conf/__init__.py", line 170, in __init__
    mod = importlib.import_module(self.SETTINGS_MODULE)
  File "/usr/lib/python3.8/importlib/__init__.py", line 127, in import_module
    return _bootstrap._gcd_import(name[level:], package, level)
  File "<frozen importlib._bootstrap>", line 1014, in _gcd_import
  File "<frozen importlib._bootstrap>", line 991, in _find_and_load
  File "<frozen importlib._bootstrap>", line 975, in _find_and_load_unlocked
  File "<frozen importlib._bootstrap>", line 671, in _load_unlocked
  File "<frozen importlib._bootstrap_external>", line 848, in exec_module
  File "<frozen importlib._bootstrap>", line 219, in _call_with_frames_removed
  File "/www/django_www/django_www/settings.py", line 153, in <module>
    sys.path.append = [ BASE_DIR / "crawler" ]
AttributeError: 'list' object attribute 'append' is read-only
nohup: ignoring input
Traceback (most recent call last):
  File "/www/django_www/manage.py", line 22, in <module>
    main()
  File "/www/django_www/manage.py", line 18, in main
    execute_from_command_line(sys.argv)
  File "/usr/local/lib/python3.8/dist-packages/django/core/management/__init__.py", line 419, in execute_from_command_line
    utility.execute()
  File "/usr/local/lib/python3.8/dist-packages/django/core/management/__init__.py", line 363, in execute
    settings.INSTALLED_APPS
  File "/usr/local/lib/python3.8/dist-packages/django/conf/__init__.py", line 82, in __getattr__
    self._setup(name)
  File "/usr/local/lib/python3.8/dist-packages/django/conf/__init__.py", line 69, in _setup
    self._wrapped = Settings(settings_module)
  File "/usr/local/lib/python3.8/dist-packages/django/conf/__init__.py", line 170, in __init__
    mod = importlib.import_module(self.SETTINGS_MODULE)
  File "/usr/lib/python3.8/importlib/__init__.py", line 127, in import_module
    return _bootstrap._gcd_import(name[level:], package, level)
  File "<frozen importlib._bootstrap>", line 1014, in _gcd_import
  File "<frozen importlib._bootstrap>", line 991, in _find_and_load
  File "<frozen importlib._bootstrap>", line 975, in _find_and_load_unlocked
  File "<frozen importlib._bootstrap>", line 671, in _load_unlocked
  File "<frozen importlib._bootstrap_external>", line 848, in exec_module
  File "<frozen importlib._bootstrap>", line 219, in _call_with_frames_removed
  File "/www/django_www/django_www/settings.py", line 153, in <module>
    sys.path.append = [ BASE_DIR / "crawler" ]
AttributeError: 'list' object attribute 'append' is read-only
nohup: ignoring input
Traceback (most recent call last):
  File "/www/django_www/manage.py", line 22, in <module>
    main()
  File "/www/django_www/manage.py", line 18, in main
    execute_from_command_line(sys.argv)
  File "/usr/local/lib/python3.8/dist-packages/django/core/management/__init__.py", line 419, in execute_from_command_line
    utility.execute()
  File "/usr/local/lib/python3.8/dist-packages/django/core/management/__init__.py", line 363, in execute
    settings.INSTALLED_APPS
  File "/usr/local/lib/python3.8/dist-packages/django/conf/__init__.py", line 82, in __getattr__
    self._setup(name)
  File "/usr/local/lib/python3.8/dist-packages/django/conf/__init__.py", line 69, in _setup
    self._wrapped = Settings(settings_module)
  File "/usr/local/lib/python3.8/dist-packages/django/conf/__init__.py", line 170, in __init__
    mod = importlib.import_module(self.SETTINGS_MODULE)
  File "/usr/lib/python3.8/importlib/__init__.py", line 127, in import_module
    return _bootstrap._gcd_import(name[level:], package, level)
  File "<frozen importlib._bootstrap>", line 1014, in _gcd_import
  File "<frozen importlib._bootstrap>", line 991, in _find_and_load
  File "<frozen importlib._bootstrap>", line 975, in _find_and_load_unlocked
  File "<frozen importlib._bootstrap>", line 671, in _load_unlocked
  File "<frozen importlib._bootstrap_external>", line 848, in exec_module
  File "<frozen importlib._bootstrap>", line 219, in _call_with_frames_removed
  File "/www/django_www/django_www/settings.py", line 153, in <module>
    sys.path.append = [ BASE_DIR / "crawler" ]
AttributeError: 'list' object attribute 'append' is read-only
nohup: ignoring input
Traceback (most recent call last):
  File "/www/django_www/manage.py", line 22, in <module>
    main()
  File "/www/django_www/manage.py", line 18, in main
    execute_from_command_line(sys.argv)
  File "/usr/local/lib/python3.8/dist-packages/django/core/management/__init__.py", line 419, in execute_from_command_line
    utility.execute()
  File "/usr/local/lib/python3.8/dist-packages/django/core/management/__init__.py", line 363, in execute
    settings.INSTALLED_APPS
  File "/usr/local/lib/python3.8/dist-packages/django/conf/__init__.py", line 82, in __getattr__
    self._setup(name)
  File "/usr/local/lib/python3.8/dist-packages/django/conf/__init__.py", line 69, in _setup
    self._wrapped = Settings(settings_module)
  File "/usr/local/lib/python3.8/dist-packages/django/conf/__init__.py", line 170, in __init__
    mod = importlib.import_module(self.SETTINGS_MODULE)
  File "/usr/lib/python3.8/importlib/__init__.py", line 127, in import_module
    return _bootstrap._gcd_import(name[level:], package, level)
  File "<frozen importlib._bootstrap>", line 1014, in _gcd_import
  File "<frozen importlib._bootstrap>", line 991, in _find_and_load
  File "<frozen importlib._bootstrap>", line 975, in _find_and_load_unlocked
  File "<frozen importlib._bootstrap>", line 671, in _load_unlocked
  File "<frozen importlib._bootstrap_external>", line 848, in exec_module
  File "<frozen importlib._bootstrap>", line 219, in _call_with_frames_removed
  File "/www/django_www/django_www/settings.py", line 153, in <module>
    sys.path.append = [ BASE_DIR / "crawler" ]
AttributeError: 'list' object attribute 'append' is read-only
nohup: ignoring input
Traceback (most recent call last):
  File "/www/django_www/manage.py", line 22, in <module>
    main()
  File "/www/django_www/manage.py", line 18, in main
    execute_from_command_line(sys.argv)
  File "/usr/local/lib/python3.8/dist-packages/django/core/management/__init__.py", line 419, in execute_from_command_line
    utility.execute()
  File "/usr/local/lib/python3.8/dist-packages/django/core/management/__init__.py", line 363, in execute
    settings.INSTALLED_APPS
  File "/usr/local/lib/python3.8/dist-packages/django/conf/__init__.py", line 82, in __getattr__
    self._setup(name)
  File "/usr/local/lib/python3.8/dist-packages/django/conf/__init__.py", line 69, in _setup
    self._wrapped = Settings(settings_module)
  File "/usr/local/lib/python3.8/dist-packages/django/conf/__init__.py", line 170, in __init__
    mod = importlib.import_module(self.SETTINGS_MODULE)
  File "/usr/lib/python3.8/importlib/__init__.py", line 127, in import_module
    return _bootstrap._gcd_import(name[level:], package, level)
  File "<frozen importlib._bootstrap>", line 1014, in _gcd_import
  File "<frozen importlib._bootstrap>", line 991, in _find_and_load
  File "<frozen importlib._bootstrap>", line 975, in _find_and_load_unlocked
  File "<frozen importlib._bootstrap>", line 671, in _load_unlocked
  File "<frozen importlib._bootstrap_external>", line 848, in exec_module
  File "<frozen importlib._bootstrap>", line 219, in _call_with_frames_removed
  File "/www/django_www/django_www/settings.py", line 153, in <module>
    sys.path.append = [ BASE_DIR / "crawler" ]
AttributeError: 'list' object attribute 'append' is read-only
nohup: ignoring input
Traceback (most recent call last):
  File "/www/django_www/manage.py", line 22, in <module>
    main()
  File "/www/django_www/manage.py", line 18, in main
    execute_from_command_line(sys.argv)
  File "/usr/local/lib/python3.8/dist-packages/django/core/management/__init__.py", line 419, in execute_from_command_line
    utility.execute()
  File "/usr/local/lib/python3.8/dist-packages/django/core/management/__init__.py", line 363, in execute
    settings.INSTALLED_APPS
  File "/usr/local/lib/python3.8/dist-packages/django/conf/__init__.py", line 82, in __getattr__
    self._setup(name)
  File "/usr/local/lib/python3.8/dist-packages/django/conf/__init__.py", line 69, in _setup
    self._wrapped = Settings(settings_module)
  File "/usr/local/lib/python3.8/dist-packages/django/conf/__init__.py", line 170, in __init__
    mod = importlib.import_module(self.SETTINGS_MODULE)
  File "/usr/lib/python3.8/importlib/__init__.py", line 127, in import_module
    return _bootstrap._gcd_import(name[level:], package, level)
  File "<frozen importlib._bootstrap>", line 1014, in _gcd_import
  File "<frozen importlib._bootstrap>", line 991, in _find_and_load
  File "<frozen importlib._bootstrap>", line 975, in _find_and_load_unlocked
  File "<frozen importlib._bootstrap>", line 671, in _load_unlocked
  File "<frozen importlib._bootstrap_external>", line 848, in exec_module
  File "<frozen importlib._bootstrap>", line 219, in _call_with_frames_removed
  File "/www/django_www/django_www/settings.py", line 153, in <module>
    sys.path.append = [ BASE_DIR / "crawler" ]
AttributeError: 'list' object attribute 'append' is read-only
nohup: ignoring input
Traceback (most recent call last):
  File "/www/django_www/manage.py", line 22, in <module>
    main()
  File "/www/django_www/manage.py", line 18, in main
    execute_from_command_line(sys.argv)
  File "/usr/local/lib/python3.8/dist-packages/django/core/management/__init__.py", line 419, in execute_from_command_line
    utility.execute()
  File "/usr/local/lib/python3.8/dist-packages/django/core/management/__init__.py", line 363, in execute
    settings.INSTALLED_APPS
  File "/usr/local/lib/python3.8/dist-packages/django/conf/__init__.py", line 82, in __getattr__
    self._setup(name)
  File "/usr/local/lib/python3.8/dist-packages/django/conf/__init__.py", line 69, in _setup
    self._wrapped = Settings(settings_module)
  File "/usr/local/lib/python3.8/dist-packages/django/conf/__init__.py", line 170, in __init__
    mod = importlib.import_module(self.SETTINGS_MODULE)
  File "/usr/lib/python3.8/importlib/__init__.py", line 127, in import_module
    return _bootstrap._gcd_import(name[level:], package, level)
  File "<frozen importlib._bootstrap>", line 1014, in _gcd_import
  File "<frozen importlib._bootstrap>", line 991, in _find_and_load
  File "<frozen importlib._bootstrap>", line 975, in _find_and_load_unlocked
  File "<frozen importlib._bootstrap>", line 671, in _load_unlocked
  File "<frozen importlib._bootstrap_external>", line 848, in exec_module
  File "<frozen importlib._bootstrap>", line 219, in _call_with_frames_removed
  File "/www/django_www/django_www/settings.py", line 153, in <module>
    sys.path.append = [ BASE_DIR / "crawler" ]
AttributeError: 'list' object attribute 'append' is read-only
nohup: ignoring input
Watching for file changes with StatReloader
[02/Feb/2023 12:58:03] "GET /lifelog/log/ HTTP/1.1" 200 4335
/www/django_www/django_www/settings.py changed, reloading.
Performing system checks...

System check identified no issues (0 silenced).
February 02, 2023 - 12:58:02
Django version 3.2, using settings 'django_www.settings'
Starting development server at http://0.0.0.0:80/
Quit the server with CONTROL-C.
Watching for file changes with StatReloader
/www/django_www/app01/views.py changed, reloading.
Performing system checks...

System check identified no issues (0 silenced).
February 02, 2023 - 12:58:15
Django version 3.2, using settings 'django_www.settings'
Starting development server at http://0.0.0.0:80/
Quit the server with CONTROL-C.
Watching for file changes with StatReloader
Exception in thread django-main-thread:
Traceback (most recent call last):
  File "/usr/lib/python3.8/threading.py", line 932, in _bootstrap_inner
    self.run()
  File "/usr/lib/python3.8/threading.py", line 870, in run
    self._target(*self._args, **self._kwargs)
  File "/usr/local/lib/python3.8/dist-packages/django/utils/autoreload.py", line 64, in wrapper
    fn(*args, **kwargs)
  File "/usr/local/lib/python3.8/dist-packages/django/core/management/commands/runserver.py", line 118, in inner_run
    self.check(display_num_errors=True)
  File "/usr/local/lib/python3.8/dist-packages/django/core/management/base.py", line 419, in check
    all_issues = checks.run_checks(
  File "/usr/local/lib/python3.8/dist-packages/django/core/checks/registry.py", line 76, in run_checks
    new_errors = check(app_configs=app_configs, databases=databases)
  File "/usr/local/lib/python3.8/dist-packages/django/core/checks/urls.py", line 13, in check_url_config
    return check_resolver(resolver)
  File "/usr/local/lib/python3.8/dist-packages/django/core/checks/urls.py", line 23, in check_resolver
    return check_method()
  File "/usr/local/lib/python3.8/dist-packages/django/urls/resolvers.py", line 412, in check
    for pattern in self.url_patterns:
  File "/usr/local/lib/python3.8/dist-packages/django/utils/functional.py", line 48, in __get__
    res = instance.__dict__[self.name] = self.func(instance)
  File "/usr/local/lib/python3.8/dist-packages/django/urls/resolvers.py", line 598, in url_patterns
    patterns = getattr(self.urlconf_module, "urlpatterns", self.urlconf_module)
  File "/usr/local/lib/python3.8/dist-packages/django/utils/functional.py", line 48, in __get__
    res = instance.__dict__[self.name] = self.func(instance)
  File "/usr/local/lib/python3.8/dist-packages/django/urls/resolvers.py", line 591, in urlconf_module
    return import_module(self.urlconf_name)
  File "/usr/lib/python3.8/importlib/__init__.py", line 127, in import_module
    return _bootstrap._gcd_import(name[level:], package, level)
  File "<frozen importlib._bootstrap>", line 1014, in _gcd_import
  File "<frozen importlib._bootstrap>", line 991, in _find_and_load
  File "<frozen importlib._bootstrap>", line 975, in _find_and_load_unlocked
  File "<frozen importlib._bootstrap>", line 671, in _load_unlocked
  File "<frozen importlib._bootstrap_external>", line 848, in exec_module
  File "<frozen importlib._bootstrap>", line 219, in _call_with_frames_removed
  File "/www/django_www/django_www/urls.py", line 3, in <module>
    from app01 import views
  File "/www/django_www/app01/views.py", line 38, in <module>
    import module_snowflake
ModuleNotFoundError: No module named 'module_snowflake'
/www/django_www/app01/views.py changed, reloading.
Performing system checks...

Watching for file changes with StatReloader
Exception in thread django-main-thread:
Traceback (most recent call last):
  File "/usr/lib/python3.8/threading.py", line 932, in _bootstrap_inner
    self.run()
  File "/usr/lib/python3.8/threading.py", line 870, in run
    self._target(*self._args, **self._kwargs)
  File "/usr/local/lib/python3.8/dist-packages/django/utils/autoreload.py", line 64, in wrapper
    fn(*args, **kwargs)
  File "/usr/local/lib/python3.8/dist-packages/django/core/management/commands/runserver.py", line 118, in inner_run
    self.check(display_num_errors=True)
  File "/usr/local/lib/python3.8/dist-packages/django/core/management/base.py", line 419, in check
    all_issues = checks.run_checks(
  File "/usr/local/lib/python3.8/dist-packages/django/core/checks/registry.py", line 76, in run_checks
    new_errors = check(app_configs=app_configs, databases=databases)
  File "/usr/local/lib/python3.8/dist-packages/django/core/checks/urls.py", line 13, in check_url_config
    return check_resolver(resolver)
  File "/usr/local/lib/python3.8/dist-packages/django/core/checks/urls.py", line 23, in check_resolver
    return check_method()
  File "/usr/local/lib/python3.8/dist-packages/django/urls/resolvers.py", line 412, in check
    for pattern in self.url_patterns:
  File "/usr/local/lib/python3.8/dist-packages/django/utils/functional.py", line 48, in __get__
    res = instance.__dict__[self.name] = self.func(instance)
  File "/usr/local/lib/python3.8/dist-packages/django/urls/resolvers.py", line 598, in url_patterns
    patterns = getattr(self.urlconf_module, "urlpatterns", self.urlconf_module)
  File "/usr/local/lib/python3.8/dist-packages/django/utils/functional.py", line 48, in __get__
    res = instance.__dict__[self.name] = self.func(instance)
  File "/usr/local/lib/python3.8/dist-packages/django/urls/resolvers.py", line 591, in urlconf_module
    return import_module(self.urlconf_name)
  File "/usr/lib/python3.8/importlib/__init__.py", line 127, in import_module
    return _bootstrap._gcd_import(name[level:], package, level)
  File "<frozen importlib._bootstrap>", line 1014, in _gcd_import
  File "<frozen importlib._bootstrap>", line 991, in _find_and_load
  File "<frozen importlib._bootstrap>", line 975, in _find_and_load_unlocked
  File "<frozen importlib._bootstrap>", line 671, in _load_unlocked
  File "<frozen importlib._bootstrap_external>", line 848, in exec_module
  File "<frozen importlib._bootstrap>", line 219, in _call_with_frames_removed
  File "/www/django_www/django_www/urls.py", line 3, in <module>
    from app01 import views
  File "/www/django_www/app01/views.py", line 38, in <module>
    import module_snowflake
ModuleNotFoundError: No module named 'module_snowflake'
/www/django_www/django_www/settings.py changed, reloading.
Performing system checks...

Watching for file changes with StatReloader
Exception in thread django-main-thread:
Traceback (most recent call last):
  File "/usr/lib/python3.8/threading.py", line 932, in _bootstrap_inner
    self.run()
  File "/usr/lib/python3.8/threading.py", line 870, in run
    self._target(*self._args, **self._kwargs)
  File "/usr/local/lib/python3.8/dist-packages/django/utils/autoreload.py", line 64, in wrapper
    fn(*args, **kwargs)
  File "/usr/local/lib/python3.8/dist-packages/django/core/management/commands/runserver.py", line 118, in inner_run
    self.check(display_num_errors=True)
  File "/usr/local/lib/python3.8/dist-packages/django/core/management/base.py", line 419, in check
    all_issues = checks.run_checks(
  File "/usr/local/lib/python3.8/dist-packages/django/core/checks/registry.py", line 76, in run_checks
    new_errors = check(app_configs=app_configs, databases=databases)
  File "/usr/local/lib/python3.8/dist-packages/django/core/checks/urls.py", line 13, in check_url_config
    return check_resolver(resolver)
  File "/usr/local/lib/python3.8/dist-packages/django/core/checks/urls.py", line 23, in check_resolver
    return check_method()
  File "/usr/local/lib/python3.8/dist-packages/django/urls/resolvers.py", line 412, in check
    for pattern in self.url_patterns:
  File "/usr/local/lib/python3.8/dist-packages/django/utils/functional.py", line 48, in __get__
    res = instance.__dict__[self.name] = self.func(instance)
  File "/usr/local/lib/python3.8/dist-packages/django/urls/resolvers.py", line 598, in url_patterns
    patterns = getattr(self.urlconf_module, "urlpatterns", self.urlconf_module)
  File "/usr/local/lib/python3.8/dist-packages/django/utils/functional.py", line 48, in __get__
    res = instance.__dict__[self.name] = self.func(instance)
  File "/usr/local/lib/python3.8/dist-packages/django/urls/resolvers.py", line 591, in urlconf_module
    return import_module(self.urlconf_name)
  File "/usr/lib/python3.8/importlib/__init__.py", line 127, in import_module
    return _bootstrap._gcd_import(name[level:], package, level)
  File "<frozen importlib._bootstrap>", line 1014, in _gcd_import
  File "<frozen importlib._bootstrap>", line 991, in _find_and_load
  File "<frozen importlib._bootstrap>", line 975, in _find_and_load_unlocked
  File "<frozen importlib._bootstrap>", line 671, in _load_unlocked
  File "<frozen importlib._bootstrap_external>", line 848, in exec_module
  File "<frozen importlib._bootstrap>", line 219, in _call_with_frames_removed
  File "/www/django_www/django_www/urls.py", line 3, in <module>
    from app01 import views
  File "/www/django_www/app01/views.py", line 38, in <module>
    import module_snowflake
ModuleNotFoundError: No module named 'module_snowflake'
/www/django_www/django_www/settings.py changed, reloading.
Performing system checks...

Watching for file changes with StatReloader
Exception in thread django-main-thread:
Traceback (most recent call last):
  File "/usr/lib/python3.8/threading.py", line 932, in _bootstrap_inner
    self.run()
  File "/usr/lib/python3.8/threading.py", line 870, in run
    self._target(*self._args, **self._kwargs)
  File "/usr/local/lib/python3.8/dist-packages/django/utils/autoreload.py", line 64, in wrapper
    fn(*args, **kwargs)
  File "/usr/local/lib/python3.8/dist-packages/django/core/management/commands/runserver.py", line 118, in inner_run
    self.check(display_num_errors=True)
  File "/usr/local/lib/python3.8/dist-packages/django/core/management/base.py", line 419, in check
    all_issues = checks.run_checks(
  File "/usr/local/lib/python3.8/dist-packages/django/core/checks/registry.py", line 76, in run_checks
    new_errors = check(app_configs=app_configs, databases=databases)
  File "/usr/local/lib/python3.8/dist-packages/django/core/checks/urls.py", line 13, in check_url_config
    return check_resolver(resolver)
  File "/usr/local/lib/python3.8/dist-packages/django/core/checks/urls.py", line 23, in check_resolver
    return check_method()
  File "/usr/local/lib/python3.8/dist-packages/django/urls/resolvers.py", line 412, in check
    for pattern in self.url_patterns:
  File "/usr/local/lib/python3.8/dist-packages/django/utils/functional.py", line 48, in __get__
    res = instance.__dict__[self.name] = self.func(instance)
  File "/usr/local/lib/python3.8/dist-packages/django/urls/resolvers.py", line 598, in url_patterns
    patterns = getattr(self.urlconf_module, "urlpatterns", self.urlconf_module)
  File "/usr/local/lib/python3.8/dist-packages/django/utils/functional.py", line 48, in __get__
    res = instance.__dict__[self.name] = self.func(instance)
  File "/usr/local/lib/python3.8/dist-packages/django/urls/resolvers.py", line 591, in urlconf_module
    return import_module(self.urlconf_name)
  File "/usr/lib/python3.8/importlib/__init__.py", line 127, in import_module
    return _bootstrap._gcd_import(name[level:], package, level)
  File "<frozen importlib._bootstrap>", line 1014, in _gcd_import
  File "<frozen importlib._bootstrap>", line 991, in _find_and_load
  File "<frozen importlib._bootstrap>", line 975, in _find_and_load_unlocked
  File "<frozen importlib._bootstrap>", line 671, in _load_unlocked
  File "<frozen importlib._bootstrap_external>", line 848, in exec_module
  File "<frozen importlib._bootstrap>", line 219, in _call_with_frames_removed
  File "/www/django_www/django_www/urls.py", line 3, in <module>
    from app01 import views
  File "/www/django_www/app01/views.py", line 38, in <module>
    import module_snowflake
ModuleNotFoundError: No module named 'module_snowflake'
/www/django_www/app01/views.py changed, reloading.
Performing system checks...

Watching for file changes with StatReloader
[02/Feb/2023 13:07:02] "GET /lifelog/log/ HTTP/1.1" 200 4347
/www/django_www/app01/views.py changed, reloading.
Performing system checks...

System check identified no issues (0 silenced).
February 02, 2023 - 13:07:02
Django version 3.2, using settings 'django_www.settings'
Starting development server at http://0.0.0.0:80/
Quit the server with CONTROL-C.
Watching for file changes with StatReloader
[02/Feb/2023 13:07:23] "GET /lifelog/log/ HTTP/1.1" 200 4347
[02/Feb/2023 13:07:38] "GET /static/bootstrap/js/bootstrap.min.js.map HTTP/1.1" 200 216913
[02/Feb/2023 13:07:38] "GET /static/bootstrap/css/bootstrap.min.css.map HTTP/1.1" 200 522639
/www/django_www/app01/views.py changed, reloading.
Performing system checks...

System check identified no issues (0 silenced).
February 02, 2023 - 13:07:23
Django version 3.2, using settings 'django_www.settings'
Starting development server at http://0.0.0.0:80/
Quit the server with CONTROL-C.
Watching for file changes with StatReloader
[02/Feb/2023 13:09:05] "GET /lifelog/log/ HTTP/1.1" 200 4241
[02/Feb/2023 13:09:05] "GET /static/bootstrap/js/bootstrap.min.js HTTP/1.1" 200 60404
[02/Feb/2023 13:09:05] "GET /static/bootstrap/css/bootstrap.min.css HTTP/1.1" 200 194901
[02/Feb/2023 13:09:05] "GET /static/bootstrap/js/bootstrap.min.js.map HTTP/1.1" 200 216913
[02/Feb/2023 13:09:05] "GET /static/bootstrap/css/bootstrap.min.css.map HTTP/1.1" 200 522639
[02/Feb/2023 13:09:07] "GET /lifelog/log/ HTTP/1.1" 200 4241
[02/Feb/2023 13:09:07] "GET /static/bootstrap/css/bootstrap.min.css HTTP/1.1" 200 194901
[02/Feb/2023 13:09:07] "GET /static/bootstrap/js/bootstrap.min.js HTTP/1.1" 200 60404
[02/Feb/2023 13:09:07] "GET /static/bootstrap/css/bootstrap.min.css.map HTTP/1.1" 200 522639
[02/Feb/2023 13:09:07] "GET /static/bootstrap/js/bootstrap.min.js.map HTTP/1.1" 200 216913
[02/Feb/2023 13:09:07] "GET /lifelog/log/ HTTP/1.1" 200 4241
[02/Feb/2023 13:09:07] "GET /static/bootstrap/js/bootstrap.min.js HTTP/1.1" 200 60404
[02/Feb/2023 13:09:07] "GET /static/bootstrap/css/bootstrap.min.css HTTP/1.1" 200 194901
[02/Feb/2023 13:09:07] "GET /static/bootstrap/js/bootstrap.min.js.map HTTP/1.1" 200 216913
[02/Feb/2023 13:09:07] "GET /static/bootstrap/css/bootstrap.min.css.map HTTP/1.1" 200 522639
[02/Feb/2023 13:09:08] "GET /lifelog/log/ HTTP/1.1" 200 4241
[02/Feb/2023 13:09:08] "GET /static/bootstrap/css/bootstrap.min.css HTTP/1.1" 200 194901
[02/Feb/2023 13:09:08] "GET /static/bootstrap/js/bootstrap.min.js HTTP/1.1" 200 60404
[02/Feb/2023 13:09:08] "GET /static/bootstrap/css/bootstrap.min.css.map HTTP/1.1" 200 522639
[02/Feb/2023 13:09:08] "GET /static/bootstrap/js/bootstrap.min.js.map HTTP/1.1" 200 216913
[02/Feb/2023 13:09:09] "GET /lifelog/log/ HTTP/1.1" 200 4241
[02/Feb/2023 13:09:09] "GET /static/bootstrap/js/bootstrap.min.js HTTP/1.1" 200 60404
[02/Feb/2023 13:09:09] "GET /static/bootstrap/css/bootstrap.min.css HTTP/1.1" 200 194901
[02/Feb/2023 13:09:09] "GET /static/bootstrap/css/bootstrap.min.css.map HTTP/1.1" 200 522639
[02/Feb/2023 13:09:09] "GET /static/bootstrap/js/bootstrap.min.js.map HTTP/1.1" 200 216913
[02/Feb/2023 13:09:09] "GET /lifelog/log/ HTTP/1.1" 200 4241
[02/Feb/2023 13:09:09] "GET /static/bootstrap/js/bootstrap.min.js HTTP/1.1" 200 60404
[02/Feb/2023 13:09:09] "GET /static/bootstrap/css/bootstrap.min.css HTTP/1.1" 200 194901
[02/Feb/2023 13:09:09] "GET /static/bootstrap/js/bootstrap.min.js.map HTTP/1.1" 200 216913
[02/Feb/2023 13:09:09] "GET /static/bootstrap/css/bootstrap.min.css.map HTTP/1.1" 200 522639
[02/Feb/2023 13:09:09] "GET /lifelog/log/ HTTP/1.1" 200 4241
[02/Feb/2023 13:09:09] "GET /static/bootstrap/js/bootstrap.min.js HTTP/1.1" 200 60404
[02/Feb/2023 13:09:09] "GET /static/bootstrap/css/bootstrap.min.css HTTP/1.1" 200 194901
[02/Feb/2023 13:09:10] "GET /static/bootstrap/css/bootstrap.min.css.map HTTP/1.1" 200 522639
[02/Feb/2023 13:09:10] "GET /static/bootstrap/js/bootstrap.min.js.map HTTP/1.1" 200 216913
[02/Feb/2023 13:09:10] "GET /lifelog/log/ HTTP/1.1" 200 4241
[02/Feb/2023 13:09:10] "GET /static/bootstrap/js/bootstrap.min.js HTTP/1.1" 200 60404
[02/Feb/2023 13:09:10] "GET /static/bootstrap/css/bootstrap.min.css HTTP/1.1" 200 194901
[02/Feb/2023 13:09:10] "GET /static/bootstrap/js/bootstrap.min.js.map HTTP/1.1" 200 216913
[02/Feb/2023 13:09:10] "GET /static/bootstrap/css/bootstrap.min.css.map HTTP/1.1" 200 522639
[02/Feb/2023 13:09:10] "GET /lifelog/log/ HTTP/1.1" 200 4241
[02/Feb/2023 13:09:10] "GET /static/bootstrap/js/bootstrap.min.js HTTP/1.1" 200 60404
[02/Feb/2023 13:09:10] "GET /static/bootstrap/css/bootstrap.min.css HTTP/1.1" 200 194901
[02/Feb/2023 13:09:10] "GET /static/bootstrap/js/bootstrap.min.js.map HTTP/1.1" 200 216913
[02/Feb/2023 13:09:10] "GET /static/bootstrap/css/bootstrap.min.css.map HTTP/1.1" 200 522639
[02/Feb/2023 13:09:10] "GET /lifelog/log/ HTTP/1.1" 200 4241
[02/Feb/2023 13:09:10] "GET /static/bootstrap/css/bootstrap.min.css HTTP/1.1" 200 194901
[02/Feb/2023 13:09:10] "GET /static/bootstrap/js/bootstrap.min.js HTTP/1.1" 200 60404
[02/Feb/2023 13:09:11] "GET /static/bootstrap/js/bootstrap.min.js.map HTTP/1.1" 200 216913
[02/Feb/2023 13:09:11] "GET /static/bootstrap/css/bootstrap.min.css.map HTTP/1.1" 200 522639
[02/Feb/2023 13:09:11] "GET /lifelog/log/ HTTP/1.1" 200 4241
[02/Feb/2023 13:09:11] "GET /static/bootstrap/js/bootstrap.min.js HTTP/1.1" 200 60404
[02/Feb/2023 13:09:11] "GET /static/bootstrap/css/bootstrap.min.css HTTP/1.1" 200 194901
[02/Feb/2023 13:09:11] "GET /static/bootstrap/js/bootstrap.min.js.map HTTP/1.1" 200 216913
[02/Feb/2023 13:09:11] "GET /static/bootstrap/css/bootstrap.min.css.map HTTP/1.1" 200 522639
[02/Feb/2023 13:09:11] "GET /lifelog/log/ HTTP/1.1" 200 4241
[02/Feb/2023 13:09:11] "GET /static/bootstrap/js/bootstrap.min.js HTTP/1.1" 200 60404
[02/Feb/2023 13:09:11] "GET /static/bootstrap/css/bootstrap.min.css HTTP/1.1" 200 194901
[02/Feb/2023 13:09:11] "GET /static/bootstrap/js/bootstrap.min.js.map HTTP/1.1" 200 216913
[02/Feb/2023 13:09:11] "GET /static/bootstrap/css/bootstrap.min.css.map HTTP/1.1" 200 522639
[02/Feb/2023 13:11:23] "GET /lifelog/log/ HTTP/1.1" 200 4241
[02/Feb/2023 13:11:23] "GET /static/bootstrap/css/bootstrap.min.css HTTP/1.1" 200 194901
[02/Feb/2023 13:11:23] "GET /static/bootstrap/js/bootstrap.min.js HTTP/1.1" 200 60404
[02/Feb/2023 13:11:23] "GET /static/bootstrap/js/bootstrap.min.js.map HTTP/1.1" 200 216913
[02/Feb/2023 13:11:23] "GET /static/bootstrap/css/bootstrap.min.css.map HTTP/1.1" 200 522639
[02/Feb/2023 13:11:24] "GET /lifelog/log/ HTTP/1.1" 200 4241
[02/Feb/2023 13:11:24] "GET /static/bootstrap/js/bootstrap.min.js HTTP/1.1" 200 60404
[02/Feb/2023 13:11:24] "GET /static/bootstrap/css/bootstrap.min.css HTTP/1.1" 200 194901
[02/Feb/2023 13:11:24] "GET /static/bootstrap/js/bootstrap.min.js.map HTTP/1.1" 200 216913
[02/Feb/2023 13:11:24] "GET /static/bootstrap/css/bootstrap.min.css.map HTTP/1.1" 200 522639
[02/Feb/2023 13:11:24] "GET /lifelog/log/ HTTP/1.1" 200 4241
[02/Feb/2023 13:11:24] "GET /static/bootstrap/css/bootstrap.min.css HTTP/1.1" 200 194901
[02/Feb/2023 13:11:24] "GET /static/bootstrap/js/bootstrap.min.js HTTP/1.1" 200 60404
[02/Feb/2023 13:11:24] "GET /static/bootstrap/css/bootstrap.min.css.map HTTP/1.1" 200 522639
[02/Feb/2023 13:11:24] "GET /static/bootstrap/js/bootstrap.min.js.map HTTP/1.1" 200 216913
[02/Feb/2023 13:11:25] "GET /lifelog/log/ HTTP/1.1" 200 4241
[02/Feb/2023 13:11:25] "GET /static/bootstrap/css/bootstrap.min.css HTTP/1.1" 200 194901
[02/Feb/2023 13:11:25] "GET /static/bootstrap/js/bootstrap.min.js HTTP/1.1" 200 60404
[02/Feb/2023 13:11:25] "GET /static/bootstrap/js/bootstrap.min.js.map HTTP/1.1" 200 216913
[02/Feb/2023 13:11:25] "GET /static/bootstrap/css/bootstrap.min.css.map HTTP/1.1" 200 522639
[02/Feb/2023 13:12:38] "POST /lifelog/log/ HTTP/1.1" 302 0
[02/Feb/2023 13:12:38] "GET /lifelog/ HTTP/1.1" 200 35650
[02/Feb/2023 13:12:38] "GET /static/bootstrap/js/bootstrap.min.js HTTP/1.1" 200 60404
[02/Feb/2023 13:12:38] "GET /static/bootstrap/css/bootstrap.min.css HTTP/1.1" 200 194901
[02/Feb/2023 13:12:38] "GET /static/bootstrap/js/bootstrap.min.js.map HTTP/1.1" 200 216913
[02/Feb/2023 13:12:38] "GET /static/bootstrap/css/bootstrap.min.css.map HTTP/1.1" 200 522639
[02/Feb/2023 13:13:02] "GET /lifelog/ HTTP/1.1" 200 35817
[02/Feb/2023 13:13:02] "GET /static/bootstrap/css/bootstrap.min.css HTTP/1.1" 200 194901
[02/Feb/2023 13:13:02] "GET /static/bootstrap/js/bootstrap.min.js HTTP/1.1" 200 60404
[02/Feb/2023 13:13:02] "GET /static/bootstrap/css/bootstrap.min.css.map HTTP/1.1" 200 522639
[02/Feb/2023 13:13:02] "GET /static/bootstrap/js/bootstrap.min.js.map HTTP/1.1" 200 216913
[02/Feb/2023 13:13:55] "GET /lifelog/ HTTP/1.1" 200 36845
[02/Feb/2023 13:13:55] "GET /static/bootstrap/js/bootstrap.min.js HTTP/1.1" 200 60404
[02/Feb/2023 13:13:55] "GET /static/bootstrap/css/bootstrap.min.css HTTP/1.1" 200 194901
[02/Feb/2023 13:13:55] "GET /static/bootstrap/js/bootstrap.min.js.map HTTP/1.1" 200 216913
[02/Feb/2023 13:13:55] "GET /static/bootstrap/css/bootstrap.min.css.map HTTP/1.1" 200 522639
[02/Feb/2023 13:15:14] "GET /lifelog/log/ HTTP/1.1" 200 4241
[02/Feb/2023 13:15:14] "GET /static/bootstrap/js/bootstrap.min.js HTTP/1.1" 200 60404
[02/Feb/2023 13:15:14] "GET /static/bootstrap/css/bootstrap.min.css HTTP/1.1" 200 194901
[02/Feb/2023 13:15:14] "GET /static/bootstrap/js/bootstrap.min.js.map HTTP/1.1" 200 216913
[02/Feb/2023 13:15:14] "GET /static/bootstrap/css/bootstrap.min.css.map HTTP/1.1" 200 522639
[02/Feb/2023 13:16:12] "POST /lifelog/log/ HTTP/1.1" 302 0
[02/Feb/2023 13:16:12] "GET /lifelog/ HTTP/1.1" 200 36862
[02/Feb/2023 13:16:12] "GET /static/bootstrap/css/bootstrap.min.css HTTP/1.1" 200 194901
[02/Feb/2023 13:16:12] "GET /static/bootstrap/js/bootstrap.min.js HTTP/1.1" 200 60404
[02/Feb/2023 13:16:12] "GET /static/bootstrap/js/bootstrap.min.js.map HTTP/1.1" 200 216913
[02/Feb/2023 13:16:12] "GET /static/bootstrap/css/bootstrap.min.css.map HTTP/1.1" 200 522639
[02/Feb/2023 13:16:15] "GET /lifelog/ HTTP/1.1" 200 36862
[02/Feb/2023 13:16:15] "GET /static/bootstrap/js/bootstrap.min.js HTTP/1.1" 200 60404
[02/Feb/2023 13:16:15] "GET /static/bootstrap/css/bootstrap.min.css HTTP/1.1" 200 194901
[02/Feb/2023 13:16:15] "GET /static/bootstrap/css/bootstrap.min.css.map HTTP/1.1" 200 522639
[02/Feb/2023 13:16:15] "GET /static/bootstrap/js/bootstrap.min.js.map HTTP/1.1" 200 216913
/www/django_www/app01/models.py changed, reloading.
Performing system checks...

System check identified no issues (0 silenced).
February 02, 2023 - 13:09:05
Django version 3.2, using settings 'django_www.settings'
Starting development server at http://0.0.0.0:80/
Quit the server with CONTROL-C.
Watching for file changes with StatReloader
[02/Feb/2023 13:16:39] "GET /static/bootstrap/js/bootstrap.min.js.map HTTP/1.1" 200 216913
[02/Feb/2023 13:16:39] "GET /static/bootstrap/css/bootstrap.min.css.map HTTP/1.1" 200 522639
[02/Feb/2023 13:16:47] "GET /lifelog/log/ HTTP/1.1" 200 4241
[02/Feb/2023 13:16:47] "GET /static/bootstrap/js/bootstrap.min.js HTTP/1.1" 200 60404
[02/Feb/2023 13:16:47] "GET /static/bootstrap/css/bootstrap.min.css HTTP/1.1" 200 194901
[02/Feb/2023 13:16:47] "GET /static/bootstrap/css/bootstrap.min.css.map HTTP/1.1" 200 522639
[02/Feb/2023 13:16:47] "GET /static/bootstrap/js/bootstrap.min.js.map HTTP/1.1" 200 216913
[02/Feb/2023 13:16:52] "POST /lifelog/log/ HTTP/1.1" 302 0
[02/Feb/2023 13:16:52] "GET /lifelog/ HTTP/1.1" 200 35836
[02/Feb/2023 13:16:52] "GET /static/bootstrap/js/bootstrap.min.js HTTP/1.1" 200 60404
[02/Feb/2023 13:16:52] "GET /static/bootstrap/css/bootstrap.min.css HTTP/1.1" 200 194901
[02/Feb/2023 13:16:52] "GET /static/bootstrap/css/bootstrap.min.css.map HTTP/1.1" 200 522639
[02/Feb/2023 13:16:52] "GET /static/bootstrap/js/bootstrap.min.js.map HTTP/1.1" 200 216913
[02/Feb/2023 13:17:35] "GET /lifelog/log/ HTTP/1.1" 200 4241
[02/Feb/2023 13:17:35] "GET /static/bootstrap/css/bootstrap.min.css HTTP/1.1" 200 194901
[02/Feb/2023 13:17:35] "GET /static/bootstrap/js/bootstrap.min.js HTTP/1.1" 200 60404
[02/Feb/2023 13:17:35] "GET /static/bootstrap/js/bootstrap.min.js.map HTTP/1.1" 200 216913
[02/Feb/2023 13:17:35] "GET /static/bootstrap/css/bootstrap.min.css.map HTTP/1.1" 200 522639
[02/Feb/2023 13:18:12] "POST /lifelog/log/ HTTP/1.1" 302 0
[02/Feb/2023 13:18:12] "GET /lifelog/ HTTP/1.1" 200 35918
[02/Feb/2023 13:18:12] "GET /static/bootstrap/js/bootstrap.min.js HTTP/1.1" 200 60404
[02/Feb/2023 13:18:12] "GET /static/bootstrap/css/bootstrap.min.css HTTP/1.1" 200 194901
[02/Feb/2023 13:18:12] "GET /static/bootstrap/js/bootstrap.min.js.map HTTP/1.1" 200 216913
[02/Feb/2023 13:18:12] "GET /static/bootstrap/css/bootstrap.min.css.map HTTP/1.1" 200 522639
[02/Feb/2023 13:18:14] "GET /lifelog/ HTTP/1.1" 200 35918
[02/Feb/2023 13:18:14] "GET /static/bootstrap/js/bootstrap.min.js HTTP/1.1" 200 60404
[02/Feb/2023 13:18:14] "GET /static/bootstrap/css/bootstrap.min.css HTTP/1.1" 200 194901
[02/Feb/2023 13:18:14] "GET /static/bootstrap/js/bootstrap.min.js.map HTTP/1.1" 200 216913
[02/Feb/2023 13:18:14] "GET /static/bootstrap/css/bootstrap.min.css.map HTTP/1.1" 200 522639
[02/Feb/2023 15:22:25] "GET /lifelog/log/ HTTP/1.1" 200 4241
[02/Feb/2023 15:22:25] "GET /static/bootstrap/js/bootstrap.min.js HTTP/1.1" 200 60404
[02/Feb/2023 15:22:25] "GET /static/bootstrap/css/bootstrap.min.css HTTP/1.1" 200 194901
[02/Feb/2023 15:22:25] "GET /static/bootstrap/css/bootstrap.min.css.map HTTP/1.1" 200 522639
[02/Feb/2023 15:22:25] "GET /static/bootstrap/js/bootstrap.min.js.map HTTP/1.1" 200 216913
[02/Feb/2023 15:25:20] "POST /lifelog/log/ HTTP/1.1" 302 0
[02/Feb/2023 15:25:20] "GET /lifelog/ HTTP/1.1" 200 35928
[02/Feb/2023 15:25:20] "GET /static/bootstrap/js/bootstrap.min.js HTTP/1.1" 200 60404
[02/Feb/2023 15:25:20] "GET /static/bootstrap/css/bootstrap.min.css HTTP/1.1" 200 194901
[02/Feb/2023 15:25:20] "GET /static/bootstrap/js/bootstrap.min.js.map HTTP/1.1" 200 216913
[02/Feb/2023 15:25:20] "GET /static/bootstrap/css/bootstrap.min.css.map HTTP/1.1" 200 522639
Internal Server Error: /lifelog/edit/7026727238418698240/
Traceback (most recent call last):
  File "/usr/local/lib/python3.8/dist-packages/django/utils/connection.py", line 58, in __getitem__
    return getattr(self._connections, alias)
  File "/usr/local/lib/python3.8/dist-packages/asgiref/local.py", line 105, in __getattr__
    raise AttributeError(f"{self!r} object has no attribute {key!r}")
AttributeError: <asgiref.local.Local object at 0x7fc0fb02a4f0> object has no attribute 'app01_lifelog'

During handling of the above exception, another exception occurred:

Traceback (most recent call last):
  File "/usr/local/lib/python3.8/dist-packages/django/core/handlers/exception.py", line 47, in inner
    response = get_response(request)
  File "/usr/local/lib/python3.8/dist-packages/django/core/handlers/base.py", line 181, in _get_response
    response = wrapped_callback(request, *callback_args, **callback_kwargs)
  File "/www/django_www/app01/views.py", line 26, in lifelog_edit
    one_row = App01Lifelog.objects.using('app01_lifelog').filter(global_id=global_id).first()
  File "/usr/local/lib/python3.8/dist-packages/django/db/models/query.py", line 674, in first
    for obj in (self if self.ordered else self.order_by('pk'))[:1]:
  File "/usr/local/lib/python3.8/dist-packages/django/db/models/query.py", line 280, in __iter__
    self._fetch_all()
  File "/usr/local/lib/python3.8/dist-packages/django/db/models/query.py", line 1324, in _fetch_all
    self._result_cache = list(self._iterable_class(self))
  File "/usr/local/lib/python3.8/dist-packages/django/db/models/query.py", line 48, in __iter__
    compiler = queryset.query.get_compiler(using=db)
  File "/usr/local/lib/python3.8/dist-packages/django/db/models/sql/query.py", line 292, in get_compiler
    connection = connections[using]
  File "/usr/local/lib/python3.8/dist-packages/django/utils/connection.py", line 61, in __getitem__
    raise self.exception_class(f"The connection '{alias}' doesn't exist.")
django.utils.connection.ConnectionDoesNotExist: The connection 'app01_lifelog' doesn't exist.
[02/Feb/2023 15:25:41] "GET /lifelog/edit/7026727238418698240/ HTTP/1.1" 500 89510
[02/Feb/2023 15:25:42] "GET /static/bootstrap/js/bootstrap.min.js.map HTTP/1.1" 200 216913
[02/Feb/2023 15:25:42] "GET /static/bootstrap/css/bootstrap.min.css.map HTTP/1.1" 200 522639
/www/django_www/app01/views.py changed, reloading.
Performing system checks...

System check identified no issues (0 silenced).
February 02, 2023 - 13:16:38
Django version 3.2, using settings 'django_www.settings'
Starting development server at http://0.0.0.0:80/
Quit the server with CONTROL-C.
Watching for file changes with StatReloader
[02/Feb/2023 15:29:08] "GET /lifelog/log/ HTTP/1.1" 200 4241
[02/Feb/2023 15:29:08] "GET /static/bootstrap/js/bootstrap.min.js HTTP/1.1" 200 60404
[02/Feb/2023 15:29:08] "GET /static/bootstrap/css/bootstrap.min.css HTTP/1.1" 200 194901
[02/Feb/2023 15:29:08] "GET /static/bootstrap/css/bootstrap.min.css.map HTTP/1.1" 200 522639
[02/Feb/2023 15:29:08] "GET /static/bootstrap/js/bootstrap.min.js.map HTTP/1.1" 200 216913
[02/Feb/2023 15:29:47] "GET /lifelog/log/ HTTP/1.1" 200 4241
[02/Feb/2023 15:29:47] "GET /static/bootstrap/css/bootstrap.min.css HTTP/1.1" 200 194901
[02/Feb/2023 15:29:47] "GET /static/bootstrap/js/bootstrap.min.js HTTP/1.1" 200 60404
[02/Feb/2023 15:29:47] "GET /static/bootstrap/js/bootstrap.min.js.map HTTP/1.1" 200 216913
[02/Feb/2023 15:29:47] "GET /static/bootstrap/css/bootstrap.min.css.map HTTP/1.1" 200 522639
[02/Feb/2023 15:29:48] "GET /lifelog/log/ HTTP/1.1" 200 4241
[02/Feb/2023 15:29:48] "GET /static/bootstrap/js/bootstrap.min.js HTTP/1.1" 200 60404
[02/Feb/2023 15:29:48] "GET /static/bootstrap/css/bootstrap.min.css HTTP/1.1" 200 194901
[02/Feb/2023 15:29:48] "GET /static/bootstrap/js/bootstrap.min.js.map HTTP/1.1" 200 216913
[02/Feb/2023 15:29:48] "GET /static/bootstrap/css/bootstrap.min.css.map HTTP/1.1" 200 522639
[02/Feb/2023 15:29:49] "GET /lifelog/log/ HTTP/1.1" 200 4241
[02/Feb/2023 15:29:49] "GET /static/bootstrap/js/bootstrap.min.js HTTP/1.1" 200 60404
[02/Feb/2023 15:29:49] "GET /static/bootstrap/css/bootstrap.min.css HTTP/1.1" 200 194901
[02/Feb/2023 15:29:49] "GET /static/bootstrap/js/bootstrap.min.js.map HTTP/1.1" 200 216913
[02/Feb/2023 15:29:49] "GET /static/bootstrap/css/bootstrap.min.css.map HTTP/1.1" 200 522639
[02/Feb/2023 15:29:49] "GET /lifelog/log/ HTTP/1.1" 200 4241
[02/Feb/2023 15:29:49] "GET /static/bootstrap/js/bootstrap.min.js HTTP/1.1" 200 60404
[02/Feb/2023 15:29:49] "GET /static/bootstrap/css/bootstrap.min.css HTTP/1.1" 200 194901
[02/Feb/2023 15:29:49] "GET /static/bootstrap/js/bootstrap.min.js.map HTTP/1.1" 200 216913
[02/Feb/2023 15:29:49] "GET /static/bootstrap/css/bootstrap.min.css.map HTTP/1.1" 200 522639
[02/Feb/2023 15:29:50] "GET /lifelog/log/ HTTP/1.1" 200 4241
[02/Feb/2023 15:29:50] "GET /static/bootstrap/js/bootstrap.min.js HTTP/1.1" 200 60404
[02/Feb/2023 15:29:50] "GET /static/bootstrap/css/bootstrap.min.css HTTP/1.1" 200 194901
[02/Feb/2023 15:29:50] "GET /static/bootstrap/js/bootstrap.min.js.map HTTP/1.1" 200 216913
[02/Feb/2023 15:29:50] "GET /static/bootstrap/css/bootstrap.min.css.map HTTP/1.1" 200 522639
[02/Feb/2023 15:29:50] "GET /lifelog/log/ HTTP/1.1" 200 4241
[02/Feb/2023 15:29:50] "GET /static/bootstrap/js/bootstrap.min.js HTTP/1.1" 200 60404
[02/Feb/2023 15:29:50] "GET /static/bootstrap/css/bootstrap.min.css HTTP/1.1" 200 194901
[02/Feb/2023 15:29:50] "GET /static/bootstrap/js/bootstrap.min.js.map HTTP/1.1" 200 216913
[02/Feb/2023 15:29:50] "GET /static/bootstrap/css/bootstrap.min.css.map HTTP/1.1" 200 522639
[02/Feb/2023 15:29:51] "GET /lifelog/log/ HTTP/1.1" 200 4241
[02/Feb/2023 15:29:51] "GET /static/bootstrap/js/bootstrap.min.js HTTP/1.1" 200 60404
[02/Feb/2023 15:29:51] "GET /static/bootstrap/css/bootstrap.min.css HTTP/1.1" 200 194901
[02/Feb/2023 15:29:51] "GET /static/bootstrap/js/bootstrap.min.js.map HTTP/1.1" 200 216913
[02/Feb/2023 15:29:51] "GET /static/bootstrap/css/bootstrap.min.css.map HTTP/1.1" 200 522639
[02/Feb/2023 15:29:51] "GET /lifelog/log/ HTTP/1.1" 200 4241
[02/Feb/2023 15:29:51] "GET /static/bootstrap/css/bootstrap.min.css HTTP/1.1" 200 194901
[02/Feb/2023 15:29:51] "GET /static/bootstrap/js/bootstrap.min.js HTTP/1.1" 200 60404
[02/Feb/2023 15:29:51] "GET /static/bootstrap/css/bootstrap.min.css.map HTTP/1.1" 200 522639
[02/Feb/2023 15:29:51] "GET /static/bootstrap/js/bootstrap.min.js.map HTTP/1.1" 200 216913
[02/Feb/2023 15:29:52] "GET /lifelog/log/ HTTP/1.1" 200 4241
[02/Feb/2023 15:29:52] "GET /static/bootstrap/js/bootstrap.min.js HTTP/1.1" 200 60404
[02/Feb/2023 15:29:52] "GET /static/bootstrap/css/bootstrap.min.css HTTP/1.1" 200 194901
[02/Feb/2023 15:29:52] "GET /static/bootstrap/js/bootstrap.min.js.map HTTP/1.1" 200 216913
[02/Feb/2023 15:29:52] "GET /static/bootstrap/css/bootstrap.min.css.map HTTP/1.1" 200 522639
[02/Feb/2023 15:29:52] "GET /lifelog/log/ HTTP/1.1" 200 4241
[02/Feb/2023 15:29:52] "GET /static/bootstrap/js/bootstrap.min.js HTTP/1.1" 200 60404
[02/Feb/2023 15:29:52] "GET /static/bootstrap/css/bootstrap.min.css HTTP/1.1" 200 194901
[02/Feb/2023 15:29:52] "GET /static/bootstrap/js/bootstrap.min.js.map HTTP/1.1" 200 216913
[02/Feb/2023 15:29:52] "GET /static/bootstrap/css/bootstrap.min.css.map HTTP/1.1" 200 522639
[02/Feb/2023 15:29:52] "GET /lifelog/log/ HTTP/1.1" 200 4241
[02/Feb/2023 15:29:53] "GET /static/bootstrap/js/bootstrap.min.js HTTP/1.1" 200 60404
[02/Feb/2023 15:29:53] "GET /static/bootstrap/css/bootstrap.min.css HTTP/1.1" 200 194901
[02/Feb/2023 15:29:53] "GET /static/bootstrap/js/bootstrap.min.js.map HTTP/1.1" 200 216913
[02/Feb/2023 15:29:53] "GET /static/bootstrap/css/bootstrap.min.css.map HTTP/1.1" 200 522639
[02/Feb/2023 15:29:53] "GET /lifelog/log/ HTTP/1.1" 200 4241
[02/Feb/2023 15:29:53] "GET /static/bootstrap/css/bootstrap.min.css HTTP/1.1" 200 194901
[02/Feb/2023 15:29:53] "GET /static/bootstrap/js/bootstrap.min.js HTTP/1.1" 200 60404
[02/Feb/2023 15:29:53] "GET /static/bootstrap/js/bootstrap.min.js.map HTTP/1.1" 200 216913
[02/Feb/2023 15:29:53] "GET /static/bootstrap/css/bootstrap.min.css.map HTTP/1.1" 200 522639
[02/Feb/2023 15:29:54] "GET /lifelog/log/ HTTP/1.1" 200 4241
[02/Feb/2023 15:29:54] "GET /static/bootstrap/js/bootstrap.min.js HTTP/1.1" 200 60404
[02/Feb/2023 15:29:54] "GET /static/bootstrap/css/bootstrap.min.css HTTP/1.1" 200 194901
[02/Feb/2023 15:29:54] "GET /static/bootstrap/js/bootstrap.min.js.map HTTP/1.1" 200 216913
[02/Feb/2023 15:29:54] "GET /static/bootstrap/css/bootstrap.min.css.map HTTP/1.1" 200 522639
[02/Feb/2023 15:29:54] "GET /lifelog/log/ HTTP/1.1" 200 4241
[02/Feb/2023 15:29:54] "GET /static/bootstrap/js/bootstrap.min.js HTTP/1.1" 200 60404
[02/Feb/2023 15:29:54] "GET /static/bootstrap/css/bootstrap.min.css HTTP/1.1" 200 194901
[02/Feb/2023 15:29:54] "GET /static/bootstrap/js/bootstrap.min.js.map HTTP/1.1" 200 216913
[02/Feb/2023 15:29:54] "GET /static/bootstrap/css/bootstrap.min.css.map HTTP/1.1" 200 522639
[02/Feb/2023 15:29:55] "GET /lifelog/log/ HTTP/1.1" 200 4241
[02/Feb/2023 15:29:55] "GET /static/bootstrap/js/bootstrap.min.js HTTP/1.1" 200 60404
[02/Feb/2023 15:29:55] "GET /static/bootstrap/css/bootstrap.min.css HTTP/1.1" 200 194901
[02/Feb/2023 15:29:55] "GET /static/bootstrap/js/bootstrap.min.js.map HTTP/1.1" 200 216913
[02/Feb/2023 15:29:55] "GET /static/bootstrap/css/bootstrap.min.css.map HTTP/1.1" 200 522639
[02/Feb/2023 15:29:55] "GET /lifelog/log/ HTTP/1.1" 200 4241
[02/Feb/2023 15:29:55] "GET /static/bootstrap/js/bootstrap.min.js HTTP/1.1" 200 60404
[02/Feb/2023 15:29:55] "GET /static/bootstrap/css/bootstrap.min.css HTTP/1.1" 200 194901
[02/Feb/2023 15:29:55] "GET /static/bootstrap/css/bootstrap.min.css.map HTTP/1.1" 200 522639
[02/Feb/2023 15:29:55] "GET /static/bootstrap/js/bootstrap.min.js.map HTTP/1.1" 200 216913
[02/Feb/2023 15:29:55] "GET /lifelog/log/ HTTP/1.1" 200 4241
[02/Feb/2023 15:29:55] "GET /static/bootstrap/js/bootstrap.min.js HTTP/1.1" 200 60404
[02/Feb/2023 15:29:55] "GET /static/bootstrap/css/bootstrap.min.css HTTP/1.1" 200 194901
[02/Feb/2023 15:29:55] "GET /static/bootstrap/js/bootstrap.min.js.map HTTP/1.1" 200 216913
[02/Feb/2023 15:29:55] "GET /static/bootstrap/css/bootstrap.min.css.map HTTP/1.1" 200 522639
[02/Feb/2023 15:29:56] "GET /lifelog/log/ HTTP/1.1" 200 4241
[02/Feb/2023 15:29:56] "GET /static/bootstrap/js/bootstrap.min.js HTTP/1.1" 200 60404
[02/Feb/2023 15:29:56] "GET /static/bootstrap/css/bootstrap.min.css HTTP/1.1" 200 194901
[02/Feb/2023 15:29:56] "GET /static/bootstrap/css/bootstrap.min.css.map HTTP/1.1" 200 522639
[02/Feb/2023 15:29:56] "GET /static/bootstrap/js/bootstrap.min.js.map HTTP/1.1" 200 216913
[02/Feb/2023 15:29:56] "GET /lifelog/log/ HTTP/1.1" 200 4241
[02/Feb/2023 15:29:56] "GET /static/bootstrap/js/bootstrap.min.js HTTP/1.1" 200 60404
[02/Feb/2023 15:29:56] "GET /static/bootstrap/css/bootstrap.min.css HTTP/1.1" 200 194901
[02/Feb/2023 15:29:56] "GET /static/bootstrap/css/bootstrap.min.css.map HTTP/1.1" 200 522639
[02/Feb/2023 15:29:56] "GET /static/bootstrap/js/bootstrap.min.js.map HTTP/1.1" 200 216913
[02/Feb/2023 15:29:56] "GET /lifelog/log/ HTTP/1.1" 200 4241
[02/Feb/2023 15:29:56] "GET /static/bootstrap/js/bootstrap.min.js HTTP/1.1" 200 60404
[02/Feb/2023 15:29:56] "GET /static/bootstrap/css/bootstrap.min.css HTTP/1.1" 200 194901
[02/Feb/2023 15:29:56] "GET /static/bootstrap/js/bootstrap.min.js.map HTTP/1.1" 200 216913
[02/Feb/2023 15:29:56] "GET /static/bootstrap/css/bootstrap.min.css.map HTTP/1.1" 200 522639
[02/Feb/2023 15:29:56] "GET /lifelog/log/ HTTP/1.1" 200 4241
[02/Feb/2023 15:29:56] "GET /static/bootstrap/js/bootstrap.min.js HTTP/1.1" 200 60404
[02/Feb/2023 15:29:56] "GET /static/bootstrap/css/bootstrap.min.css HTTP/1.1" 200 194901
[02/Feb/2023 15:29:56] "GET /static/bootstrap/css/bootstrap.min.css.map HTTP/1.1" 200 522639
[02/Feb/2023 15:29:56] "GET /static/bootstrap/js/bootstrap.min.js.map HTTP/1.1" 200 216913
[02/Feb/2023 15:29:57] "GET /lifelog/log/ HTTP/1.1" 200 4241
[02/Feb/2023 15:29:57] "GET /static/bootstrap/js/bootstrap.min.js HTTP/1.1" 200 60404
[02/Feb/2023 15:29:57] "GET /static/bootstrap/css/bootstrap.min.css HTTP/1.1" 200 194901
[02/Feb/2023 15:29:57] "GET /static/bootstrap/js/bootstrap.min.js.map HTTP/1.1" 200 216913
[02/Feb/2023 15:29:57] "GET /static/bootstrap/css/bootstrap.min.css.map HTTP/1.1" 200 522639
[02/Feb/2023 15:29:57] "GET /lifelog/log/ HTTP/1.1" 200 4241
[02/Feb/2023 15:29:57] "GET /static/bootstrap/js/bootstrap.min.js HTTP/1.1" 200 60404
[02/Feb/2023 15:29:57] "GET /static/bootstrap/css/bootstrap.min.css HTTP/1.1" 200 194901
[02/Feb/2023 15:29:57] "GET /static/bootstrap/js/bootstrap.min.js.map HTTP/1.1" 200 216913
[02/Feb/2023 15:29:57] "GET /static/bootstrap/css/bootstrap.min.css.map HTTP/1.1" 200 522639
[02/Feb/2023 15:29:57] "GET /static/bootstrap/js/bootstrap.min.js.map HTTP/1.1" 200 216913
[02/Feb/2023 15:29:57] "GET /static/bootstrap/css/bootstrap.min.css.map HTTP/1.1" 200 522639
[02/Feb/2023 16:24:39] "GET /lifelog/log/ HTTP/1.1" 200 4241
[02/Feb/2023 16:24:39] "GET /static/bootstrap/js/bootstrap.min.js HTTP/1.1" 200 60404
[02/Feb/2023 16:24:39] "GET /static/bootstrap/css/bootstrap.min.css HTTP/1.1" 200 194901
[02/Feb/2023 16:24:39] "GET /static/bootstrap/js/bootstrap.min.js.map HTTP/1.1" 200 216913
[02/Feb/2023 16:24:39] "GET /static/bootstrap/css/bootstrap.min.css.map HTTP/1.1" 200 522639
/www/django_www/app01/models.py changed, reloading.
Performing system checks...

System check identified no issues (0 silenced).
February 02, 2023 - 15:28:21
Django version 3.2, using settings 'django_www.settings'
Starting development server at http://0.0.0.0:80/
Quit the server with CONTROL-C.
Watching for file changes with StatReloader
[02/Feb/2023 16:25:10] "GET /lifelog/log/ HTTP/1.1" 200 4241
[02/Feb/2023 16:25:10] "GET /static/bootstrap/js/bootstrap.min.js HTTP/1.1" 200 60404
[02/Feb/2023 16:25:10] "GET /static/bootstrap/css/bootstrap.min.css HTTP/1.1" 200 194901
[02/Feb/2023 16:25:10] "GET /static/bootstrap/js/bootstrap.min.js.map HTTP/1.1" 200 216913
[02/Feb/2023 16:25:10] "GET /static/bootstrap/css/bootstrap.min.css.map HTTP/1.1" 200 522639
/www/django_www/app01/models.py changed, reloading.
Performing system checks...

System check identified no issues (0 silenced).
February 02, 2023 - 16:25:09
Django version 3.2, using settings 'django_www.settings'
Starting development server at http://0.0.0.0:80/
Quit the server with CONTROL-C.
Watching for file changes with StatReloader
/www/django_www/app01/views.py changed, reloading.
Performing system checks...

System check identified no issues (0 silenced).
February 02, 2023 - 16:25:25
Django version 3.2, using settings 'django_www.settings'
Starting development server at http://0.0.0.0:80/
Quit the server with CONTROL-C.
Watching for file changes with StatReloader
[02/Feb/2023 16:25:37] "GET /lifelog/log/ HTTP/1.1" 200 4241
[02/Feb/2023 16:25:37] "GET /static/bootstrap/js/bootstrap.min.js HTTP/1.1" 200 60404
[02/Feb/2023 16:25:37] "GET /static/bootstrap/css/bootstrap.min.css HTTP/1.1" 200 194901
[02/Feb/2023 16:25:37] "GET /static/bootstrap/css/bootstrap.min.css.map HTTP/1.1" 200 522639
[02/Feb/2023 16:25:37] "GET /static/bootstrap/js/bootstrap.min.js.map HTTP/1.1" 200 216913
[02/Feb/2023 16:29:27] "POST /lifelog/log/ HTTP/1.1" 200 7
[02/Feb/2023 16:29:29] "GET /lifelog/log/ HTTP/1.1" 200 4241
[02/Feb/2023 16:29:29] "GET /static/bootstrap/js/bootstrap.min.js HTTP/1.1" 200 60404
[02/Feb/2023 16:29:29] "GET /static/bootstrap/css/bootstrap.min.css HTTP/1.1" 200 194901
[02/Feb/2023 16:29:29] "GET /static/bootstrap/js/bootstrap.min.js.map HTTP/1.1" 200 216913
[02/Feb/2023 16:29:29] "GET /static/bootstrap/css/bootstrap.min.css.map HTTP/1.1" 200 522639
/www/django_www/app01/views.py changed, reloading.
Performing system checks...

System check identified no issues (0 silenced).
February 02, 2023 - 16:25:29
Django version 3.2, using settings 'django_www.settings'
Starting development server at http://0.0.0.0:80/
Quit the server with CONTROL-C.
form.errors +++++form.errors的错误+++++
Watching for file changes with StatReloader
[02/Feb/2023 16:38:50] "GET /lifelog/log/ HTTP/1.1" 200 4225
[02/Feb/2023 16:38:50] "GET /static/bootstrap/js/bootstrap.min.js HTTP/1.1" 200 60404
[02/Feb/2023 16:38:50] "GET /static/bootstrap/css/bootstrap.min.css HTTP/1.1" 200 194901
[02/Feb/2023 16:38:50] "GET /static/bootstrap/js/bootstrap.min.js.map HTTP/1.1" 200 216913
[02/Feb/2023 16:38:50] "GET /static/bootstrap/css/bootstrap.min.css.map HTTP/1.1" 200 522639
Internal Server Error: /lifelog/log/
Traceback (most recent call last):
  File "/usr/local/lib/python3.8/dist-packages/django/db/backends/mysql/base.py", line 73, in execute
    return self.cursor.execute(query, args)
  File "/usr/local/lib/python3.8/dist-packages/MySQLdb/cursors.py", line 206, in execute
    res = self._query(query)
  File "/usr/local/lib/python3.8/dist-packages/MySQLdb/cursors.py", line 319, in _query
    db.query(q)
  File "/usr/local/lib/python3.8/dist-packages/MySQLdb/connections.py", line 254, in query
    _mysql.connection.query(self, query)
MySQLdb.OperationalError: (1048, "Column 'weather' cannot be null")

During handling of the above exception, another exception occurred:

Traceback (most recent call last):
  File "/usr/local/lib/python3.8/dist-packages/django/core/handlers/exception.py", line 47, in inner
    response = get_response(request)
  File "/usr/local/lib/python3.8/dist-packages/django/core/handlers/base.py", line 181, in _get_response
    response = wrapped_callback(request, *callback_args, **callback_kwargs)
  File "/www/django_www/app01/views.py", line 74, in lifelog_log
    form.save()        # 如果数据是有效的，存入之前获取的表中
  File "/usr/local/lib/python3.8/dist-packages/django/forms/models.py", line 468, in save
    self.instance.save()
  File "/usr/local/lib/python3.8/dist-packages/django/db/models/base.py", line 726, in save
    self.save_base(using=using, force_insert=force_insert,
  File "/usr/local/lib/python3.8/dist-packages/django/db/models/base.py", line 763, in save_base
    updated = self._save_table(
  File "/usr/local/lib/python3.8/dist-packages/django/db/models/base.py", line 868, in _save_table
    results = self._do_insert(cls._base_manager, using, fields, returning_fields, raw)
  File "/usr/local/lib/python3.8/dist-packages/django/db/models/base.py", line 906, in _do_insert
    return manager._insert(
  File "/usr/local/lib/python3.8/dist-packages/django/db/models/manager.py", line 85, in manager_method
    return getattr(self.get_queryset(), name)(*args, **kwargs)
  File "/usr/local/lib/python3.8/dist-packages/django/db/models/query.py", line 1270, in _insert
    return query.get_compiler(using=using).execute_sql(returning_fields)
  File "/usr/local/lib/python3.8/dist-packages/django/db/models/sql/compiler.py", line 1410, in execute_sql
    cursor.execute(sql, params)
  File "/usr/local/lib/python3.8/dist-packages/django/db/backends/utils.py", line 98, in execute
    return super().execute(sql, params)
  File "/usr/local/lib/python3.8/dist-packages/django/db/backends/utils.py", line 66, in execute
    return self._execute_with_wrappers(sql, params, many=False, executor=self._execute)
  File "/usr/local/lib/python3.8/dist-packages/django/db/backends/utils.py", line 75, in _execute_with_wrappers
    return executor(sql, params, many, context)
  File "/usr/local/lib/python3.8/dist-packages/django/db/backends/utils.py", line 84, in _execute
    return self.cursor.execute(sql, params)
  File "/usr/local/lib/python3.8/dist-packages/django/db/backends/mysql/base.py", line 78, in execute
    raise IntegrityError(*tuple(e.args))
django.db.utils.IntegrityError: (1048, "Column 'weather' cannot be null")
[02/Feb/2023 16:38:54] "POST /lifelog/log/ HTTP/1.1" 500 143627
[02/Feb/2023 16:40:38] "GET /lifelog/log/ HTTP/1.1" 200 4225
[02/Feb/2023 16:40:38] "GET /static/bootstrap/js/bootstrap.min.js HTTP/1.1" 200 60404
[02/Feb/2023 16:40:38] "GET /static/bootstrap/css/bootstrap.min.css HTTP/1.1" 200 194901
[02/Feb/2023 16:40:38] "GET /static/bootstrap/css/bootstrap.min.css.map HTTP/1.1" 200 522639
[02/Feb/2023 16:40:38] "GET /static/bootstrap/js/bootstrap.min.js.map HTTP/1.1" 200 216913
[02/Feb/2023 16:44:33] "POST /lifelog/log/ HTTP/1.1" 302 0
[02/Feb/2023 16:44:33] "GET /lifelog/ HTTP/1.1" 200 35876
[02/Feb/2023 16:44:33] "GET /static/bootstrap/css/bootstrap.min.css HTTP/1.1" 200 194901
[02/Feb/2023 16:44:33] "GET /static/bootstrap/js/bootstrap.min.js HTTP/1.1" 200 60404
[02/Feb/2023 16:44:33] "GET /static/bootstrap/js/bootstrap.min.js.map HTTP/1.1" 200 216913
[02/Feb/2023 16:44:33] "GET /static/bootstrap/css/bootstrap.min.css.map HTTP/1.1" 200 522639
[02/Feb/2023 16:48:34] "GET /lifelog/log/ HTTP/1.1" 200 4225
[02/Feb/2023 16:48:34] "GET /static/bootstrap/css/bootstrap.min.css HTTP/1.1" 200 194901
[02/Feb/2023 16:48:34] "GET /static/bootstrap/js/bootstrap.min.js HTTP/1.1" 200 60404
[02/Feb/2023 16:48:35] "GET /static/bootstrap/js/bootstrap.min.js.map HTTP/1.1" 200 216913
[02/Feb/2023 16:48:35] "GET /static/bootstrap/css/bootstrap.min.css.map HTTP/1.1" 200 522639
/www/django_www/app01/views.py changed, reloading.
Performing system checks...

System check identified no issues (0 silenced).
February 02, 2023 - 16:38:49
Django version 3.2, using settings 'django_www.settings'
Starting development server at http://0.0.0.0:80/
Quit the server with CONTROL-C.
Watching for file changes with StatReloader
[02/Feb/2023 16:55:54] "GET /lifelog/ HTTP/1.1" 200 35928
[02/Feb/2023 16:55:54] "GET /static/bootstrap/js/bootstrap.min.js HTTP/1.1" 200 60404
[02/Feb/2023 16:55:54] "GET /static/bootstrap/css/bootstrap.min.css HTTP/1.1" 200 194901
[02/Feb/2023 16:55:54] "GET /static/bootstrap/js/bootstrap.min.js.map HTTP/1.1" 200 216913
[02/Feb/2023 16:55:54] "GET /static/bootstrap/css/bootstrap.min.css.map HTTP/1.1" 200 522639
[02/Feb/2023 16:56:06] "GET /index/ HTTP/1.1" 200 4146
[02/Feb/2023 16:56:08] "GET /lifelog/ HTTP/1.1" 200 35928
